Workbook

Sheet 8 formal
B1: COUNT DOWN : 8
B3: NO SEQ | C3: NO PROCESS | D3: MAIN JOB | E3: PROCESS NAME | F3: ZONE | G3: LANE | H3: ROUTE | I3: OFFSET 1 | J3: OFFSET 2 | K3: GROUP
J4: 8 | L4: 8 | M4: 7 | N4: 6 | O4: 5 | P4: 4 | Q4: 3 | R4: 2 | S4: 1 | T4: 8 | U4: 7 | V4: 6 | W4: 5 | X4: 4 | Y4: 3 | Z4: 2 | AA4: 1 | AB4: 8 | AC4: 7 | AD4: 6 | AE4: 5 | AF4: 4 | AG4: 3 | AH4: 2 | AI4: 1 | AJ4: 8 | AK4: 7 | AL4: 6 | AM4: 5 | AN4: 4 | AO4: 3 | AP4: 2 | AQ4: 1 | AR4: 8 | AS4: 7 | AT4: 6 | AU4: 5 | AV4: 4 | AW4: 3 | AX4: 2 | AY4: 1
B5: 0 | C5: 0 | D5: UNLOAD | E5: UNLOAD P LANE | I5: -4 | J5: 4 | L5: 4 | M5: 3 | N5: 2 | O5: 1 | P5: 8 | Q5: 7 | R5: 6 | S5: 5 | T5: 4 | U5: 3 | V5: 2 | W5: 1 | X5: 8 | Y5: 7 | Z5: 6 | AA5: 5 | AB5: 4 | AC5: 3 | AD5: 2 | AE5: 1 | AF5: 8 | AG5: 7 | AH5: 6 | AI5: 5 | AJ5: 4 | AK5: 3 | AL5: 2 | AM5: 1 | AN5: 8 | AO5: 7 | AP5: 6 | AQ5: 5 | AR5: 4 | AS5: 3 | AT5: 2 | AU5: 1 | AV5: 8 | AW5: 7 | AX5: 6 | AY5: 5
B6: 1 | C6: 1 | D6: UNLOAD | E6: UNLOAD SORTING | F6: EAST | G6: 1 | H6: A | I6: -4 | J6: =I6+$J$4 -> 4 | P6: 4 | Q6: 3 | X6: 4 | Y6: 3 | AF6: 4 | AG6: 3 | AN6: 4 | AO6: 3
B7: 1 | C7: 2 | D7: TRANSFER | E7: TRANSFER | F7: EAST | G7: =G6 -> 1 | H7: A | I7: -2 | J7: =I7+$J$4 -> 6 | R7: 2 | Z7: 2 | AH7: 2 | AP7: 2
B8: 1 | C8: 3 | D8: SUPPLY | E8: SUPPLY | F8: EAST | G8: 1 | H8: A | I8: 0 | J8: =I8+$J$4 -> 8 | T8: 8 | U8: 7 | V8: 6 | W8: 5 | X8: 4 | AB8: 8 | AC8: 7 | AD8: 6 | AE8: 5 | AF8: 4 | AJ8: 8 | AK8: 7 | AL8: 6 | AM8: 5 | AN8: 4
B9: =B8 -> 1 | C9: 4 | D9: SUPPLY | E9: EMPTY | F9: EAST | G9: =G8 -> 1 | H9: =H8 -> A | I9: -3 | J9: =I9+$J$4 -> 5 | Q9: 3 | R9: 2 | Y9: 3 | Z9: 2 | AG9: 3 | AH9: 2 | AO9: 3 | AP9: 2
B10: 1 | C10: 5 | D10: SUPPLY | E10: PREPARE B PASS | F10: EAST | G10: =G9 -> 1 | H10: A | I10: -1 | J10: =I10+$J$4 -> 7 | S10: 1 | AA10: 1 | AI10: 1 | AQ10: 1
B11: =B9 -> 1 | C11: 6 | E11: COUNTDOWN | F11: EAST | G11: =G10 -> 1 | H11: =H9 -> A | L11: 8 | M11: 7 | N11: 6 | O11: 5 | P11: 4 | Q11: 3 | R11: 2 | S11: 1 | T11: 8 | U11: 7 | V11: 6 | W11: 5 | X11: 4 | Y11: 3 | Z11: 2 | AA11: 1 | AB11: 8 | AC11: 7 | AD11: 6 | AE11: 5 | AF11: 4 | AG11: 3 | AH11: 2 | AI11: 1 | AJ11: 8 | AK11: 7 | AL11: 6 | AM11: 5 | AN11: 4 | AO11: 3 | AP11: 2 | AQ11: 1 | AR11: 8 | AS11: 7 | AT11: 6 | AU11: 5 | AV11: 4 | AW11: 3 | AX11: 2 | AY11: 1
B12: 2 | C12: 1 | D12: UNLOAD | E12: UNLOAD SORTING | F12: EAST | G12: =G11 -> 1 | H12: B | I12: -2 | J12: =I12+$J$4 -> 6 | R12: 4 | Z12: 4 | AH12: 4 | AP12: 4
B13: 2 | C13: 2 | D13: TRANSFER | E13: TRANSFER | F13: EAST | G13: =G12 -> 1 | H13: B | I13: -1 | J13: =I13+$J$4 -> 7 | S13: 3 | AA13: 3 | AI13: 3 | AQ13: 3
B14: 2 | C14: 3 | D14: SUPPLY | E14: SUPPLY | F14: EAST | G14: 1 | H14: B | I14: 2 | J14: =I14+$J$4 -> 10 | V14: 8 | W14: 7 | X14: 6 | Y14: 5 | Z14: 4 | AD14: 8 | AE14: 7 | AF14: 6 | AG14: 5 | AH14: 4 | AL14: 8 | AM14: 7 | AN14: 6 | AO14: 5 | AP14: 4
B15: =B14 -> 2 | C15: 4 | D15: SUPPLY | E15: EMPTY | F15: EAST | G15: =G14 -> 1 | H15: =H14 -> B | I15: -1 | J15: =I15+$J$4 -> 7 | S15: 3 | AA15: 3 | AI15: 3 | AQ15: 3
B16: 2 | C16: 5 | D16: SUPPLY | E16: PREPARE B PASS | F16: EAST | G16: =G15 -> 1 | H16: B | I16: 0 | J16: =I16+$J$4 -> 8 | T16: 2 | U16: 1 | AB16: 2 | AC16: 1 | AJ16: 2 | AK16: 1 | AR16: 2 | AS16: 1
B17: =B15 -> 2 | C17: 6 | E17: COUNTDOWN | F17: EAST | G17: =G16 -> 1 | H17: =H15 -> B | L17: 2 | M17: 1 | N17: 8 | O17: 7 | P17: 6 | Q17: 5 | R17: 4 | S17: 3 | T17: 2 | U17: 1 | V17: 8 | W17: 7 | X17: 6 | Y17: 5 | Z17: 4 | AA17: 3 | AB17: 2 | AC17: 1 | AD17: 8 | AE17: 7 | AF17: 6 | AG17: 5 | AH17: 4 | AI17: 3 | AJ17: 2 | AK17: 1 | AL17: 8 | AM17: 7 | AN17: 6 | AO17: 5 | AP17: 4 | AQ17: 3 | AR17: 2 | AS17: 1 | AT17: 8 | AU17: 7 | AV17: 6 | AW17: 5 | AX17: 4 | AY17: 3
B18: 3 | C18: 1 | D18: UNLOAD | E18: UNLOAD SORTING | F18: EAST | G18: =G17 -> 1 | H18: E | I18: 2 | J18: =I18+$J$4 -> 10 | V18: 3 | AD18: 3 | AL18: 3 | AT18: 3
B19: 3 | C19: 2 | D19: TRANSFER | E19: TRANSFER | F19: EAST | G19: =G18 -> 1 | H19: E | I19: 3 | J19: =I19+$J$4 -> 11 | W19: 2 | AE19: 2 | AM19: 2 | AU19: 2
B20: 3 | C20: 3 | D20: SUPPLY | E20: SUPPLY | F20: EAST | G20: 1 | H20: E | I20: 5 | J20: =I20+$J$4 -> 13 | Y20: 8 | Z20: 7 | AA20: 6 | AB20: 5 | AC20: 4 | AG20: 8 | AH20: 7 | AI20: 6 | AJ20: 5 | AK20: 4 | AO20: 8 | AP20: 7 | AQ20: 6 | AR20: 5 | AS20: 4
B21: =B20 -> 3 | C21: 4 | D21: SUPPLY | E21: EMPTY | F21: EAST | G21: =G20 -> 1 | H21: =H20 -> E | I21: 2 | J21: =I21+$J$4 -> 10 | V21: 3 | W21: 2 | AD21: 3 | AE21: 2 | AL21: 3 | AM21: 2 | AT21: 3 | AU21: 2
B22: 3 | C22: 5 | D22: SUPPLY | E22: PREPARE B PASS | F22: EAST | G22: =G21 -> 1 | H22: E | I22: 4 | J22: =I22+$J$4 -> 12 | X22: 1 | AF22: 1 | AN22: 1 | AV22: 1
B23: =B21 -> 3 | C23: 6 | E23: COUNTDOWN | F23: EAST | G23: =G22 -> 1 | H23: =H21 -> E | L23: 5 | M23: 4 | N23: 3 | O23: 2 | P23: 1 | Q23: 8 | R23: 7 | S23: 6 | T23: 5 | U23: 4 | V23: 3 | W23: 2 | X23: 1 | Y23: 8 | Z23: 7 | AA23: 6 | AB23: 5 | AC23: 4 | AD23: 3 | AE23: 2 | AF23: 1 | AG23: 8 | AH23: 7 | AI23: 6 | AJ23: 5 | AK23: 4 | AL23: 3 | AM23: 2 | AN23: 1 | AO23: 8 | AP23: 7 | AQ23: 6 | AR23: 5 | AS23: 4 | AT23: 3 | AU23: 2 | AV23: 1 | AW23: 8 | AX23: 7 | AY23: 6
B24: 4 | C24: 1 | D24: UNLOAD | E24: UNLOAD SORTING | F24: EAST | G24: =G23 -> 1 | H24: J | I24: 3 | J24: =I24+$J$4 -> 11 | W24: 4 | AE24: 4 | AM24: 4 | AU24: 4
B25: 4 | C25: 2 | D25: TRANSFER | E25: TRANSFER | F25: EAST | G25: =G24 -> 1 | H25: J | I25: 4 | J25: =I25+$J$4 -> 12 | X25: 3 | AF25: 3 | AN25: 3 | AV25: 3
B26: 4 | C26: 3 | D26: SUPPLY | E26: SUPPLY | F26: EAST | G26: 1 | H26: J | I26: 7 | J26: =I26+$J$4 -> 15 | AA26: 8 | AB26: 7 | AC26: 6 | AD26: 5 | AE26: 4 | AI26: 8 | AJ26: 7 | AK26: 6 | AL26: 5 | AM26: 4 | AQ26: 8 | AR26: 7 | AS26: 6 | AT26: 5 | AU26: 4
B27: =B26 -> 4 | C27: 4 | D27: SUPPLY | E27: EMPTY | F27: EAST | G27: =G26 -> 1 | H27: =H26 -> J | I27: 4 | J27: =I27+$J$4 -> 12 | X27: 3 | AF27: 3 | AN27: 3 | AV27: 3
B28: 4 | C28: 5 | D28: SUPPLY | E28: PREPARE B PASS | F28: EAST | G28: =G27 -> 1 | H28: J | I28: 5 | J28: =I28+$J$4 -> 13 | Y28: 2 | Z28: 1 | AG28: 2 | AH28: 1 | AO28: 2 | AP28: 1 | AW28: 2 | AX28: 1
B29: =B27 -> 4 | C29: 6 | E29: COUNTDOWN | F29: EAST | G29: =G28 -> 1 | H29: =H27 -> J | L29: 7 | M29: 6 | N29: 5 | O29: 4 | P29: 3 | Q29: 2 | R29: 1 | S29: 8 | T29: 7 | U29: 6 | V29: 5 | W29: 4 | X29: 3 | Y29: 2 | Z29: 1 | AA29: 8 | AB29: 7 | AC29: 6 | AD29: 5 | AE29: 4 | AF29: 3 | AG29: 2 | AH29: 1 | AI29: 8 | AJ29: 7 | AK29: 6 | AL29: 5 | AM29: 4 | AN29: 3 | AO29: 2 | AP29: 1 | AQ29: 8 | AR29: 7 | AS29: 6 | AT29: 5 | AU29: 4 | AV29: 3 | AW29: 2 | AX29: 1 | AY29: 8
B30: 5 | C30: 1 | D30: UNLOAD | E30: UNLOAD SORTING | F30: EAST | G30: =G29 -> 1 | H30: D1 | I30: 0 | J30: =I30+$J$4 -> 8 | K30: DIRECT | T30: 4 | U30: 3 | AB30: 4 | AC30: 3 | AJ30: 4 | AK30: 3 | AR30: 4 | AS30: 3
B31: 5 | C31: 2 | D31: TRANSFER | E31: TRANSFER | F31: EAST | G31: =G30 -> 1 | H31: D1 | I31: 2 | J31: =I31+$J$4 -> 10 | K31: DIRECT | V31: 2 | AD31: 2 | AL31: 2 | AT31: 2
B32: 5 | C32: 3 | D32: SUPPLY | E32: SUPPLY | F32: EAST | G32: 2 | H32: D1 | I32: 4 | J32: =I32+$J$4 -> 12 | K32: DIRECT | X32: 8 | Y32: 7 | Z32: 6 | AA32: 5 | AB32: 4 | AF32: 8 | AG32: 7 | AH32: 6 | AI32: 5 | AJ32: 4 | AN32: 8 | AO32: 7 | AP32: 6 | AQ32: 5 | AR32: 4
B33: =B32 -> 5 | C33: 4 | D33: SUPPLY | E33: EMPTY | F33: EAST | G33: =G32 -> 2 | H33: =H32 -> D1 | I33: 1 | J33: =I33+$J$4 -> 9 | K33: DIRECT | U33: 3 | V33: 2 | AC33: 3 | AD33: 2 | AK33: 3 | AL33: 2 | AS33: 3 | AT33: 2
B34: 5 | C34: 5 | D34: SUPPLY | E34: PREPARE B PASS | F34: EAST | G34: =G33 -> 2 | H34: D1 | I34: 3 | J34: =I34+$J$4 -> 11 | K34: DIRECT | W34: 1 | AE34: 1 | AM34: 1 | AU34: 1
B35: =B33 -> 5 | C35: 6 | E35: COUNTDOWN | F35: EAST | G35: =G34 -> 2 | H35: =H33 -> D1 | K35: DIRECT | L35: 4 | M35: 3 | N35: 2 | O35: 1 | P35: 8 | Q35: 7 | R35: 6 | S35: 5 | T35: 4 | U35: 3 | V35: 2 | W35: 1 | X35: 8 | Y35: 7 | Z35: 6 | AA35: 5 | AB35: 4 | AC35: 3 | AD35: 2 | AE35: 1 | AF35: 8 | AG35: 7 | AH35: 6 | AI35: 5 | AJ35: 4 | AK35: 3 | AL35: 2 | AM35: 1 | AN35: 8 | AO35: 7 | AP35: 6 | AQ35: 5 | AR35: 4 | AS35: 3 | AT35: 2 | AU35: 1 | AV35: 8 | AW35: 7 | AX35: 6 | AY35: 5
B36: 6 | C36: 1 | D36: UNLOAD | E36: UNLOAD SORTING | F36: EAST | G36: =G35 -> 2 | H36: C | I36: -1 | J36: =I36+$J$4 -> 7 | S36: 4 | AA36: 4 | AI36: 4 | AQ36: 4
B37: 6 | C37: 2 | D37: TRANSFER | E37: TRANSFER | F37: EAST | G37: =G36 -> 2 | H37: C | I37: 0 | J37: =I37+$J$4 -> 8 | T37: 3 | AB37: 3 | AJ37: 3 | AR37: 3
B38: 6 | C38: 3 | D38: SUPPLY | E38: SUPPLY | F38: EAST | G38: 2 | H38: C | I38: 3 | J38: =I38+$J$4 -> 11 | W38: 8 | X38: 7 | Y38: 6 | Z38: 5 | AA38: 4 | AE38: 8 | AF38: 7 | AG38: 6 | AH38: 5 | AI38: 4 | AM38: 8 | AN38: 7 | AO38: 6 | AP38: 5 | AQ38: 4
B39: =B38 -> 6 | C39: 4 | D39: SUPPLY | E39: EMPTY | F39: EAST | G39: =G38 -> 2 | H39: =H38 -> C | I39: 0 | J39: =I39+$J$4 -> 8 | T39: 3 | U39: 2 | AB39: 3 | AC39: 2 | AJ39: 3 | AK39: 2 | AR39: 3 | AS39: 2
B40: 6 | C40: 5 | D40: SUPPLY | E40: PREPARE B PASS | F40: EAST | G40: =G39 -> 2 | H40: C | I40: 2 | J40: =I40+$J$4 -> 10 | V40: 1 | AD40: 1 | AL40: 1 | AT40: 1
B41: =B39 -> 6 | C41: 6 | E41: COUNTDOWN | F41: EAST | G41: =G40 -> 2 | H41: =H39 -> C | L41: 3 | M41: 2 | N41: 1 | O41: 8 | P41: 7 | Q41: 6 | R41: 5 | S41: 4 | T41: 3 | U41: 2 | V41: 1 | W41: 8 | X41: 7 | Y41: 6 | Z41: 5 | AA41: 4 | AB41: 3 | AC41: 2 | AD41: 1 | AE41: 8 | AF41: 7 | AG41: 6 | AH41: 5 | AI41: 4 | AJ41: 3 | AK41: 2 | AL41: 1 | AM41: 8 | AN41: 7 | AO41: 6 | AP41: 5 | AQ41: 4 | AR41: 3 | AS41: 2 | AT41: 1 | AU41: 8 | AV41: 7 | AW41: 6 | AX41: 5 | AY41: 4
...

Sheet 7 formal 2
B1: COUNT DOWN : 7
B3: NO SEQ | C3: NO PROCESS | D3: MAIN JOB | E3: PROCESS NAME | F3: ZONE | G3: LANE | H3: ROUTE | I3: OFFSET 1 | J3: OFFSET 2 | K3: GROUP
J4: 7 | L4: 7 | M4: 6 | N4: 5 | O4: 4 | P4: 3 | Q4: 2 | R4: 1 | S4: 7 | T4: 6 | U4: 5 | V4: 4 | W4: 3 | X4: 2 | Y4: 1 | Z4: 7 | AA4: 6 | AB4: 5 | AC4: 4 | AD4: 3 | AE4: 2 | AF4: 1 | AG4: 7 | AH4: 6 | AI4: 5 | AJ4: 4 | AK4: 3 | AL4: 2 | AM4: 1 | AN4: 7 | AO4: 6 | AP4: 5 | AQ4: 4 | AR4: 3 | AS4: 2 | AT4: 1
B5: 0 | C5: 0 | D5: UNLOAD | E5: UNLOAD P LANE | I5: -3 | J5: 4 | L5: 4 | M5: 3 | N5: 2 | O5: 1 | P5: 7 | Q5: 6 | R5: 5 | S5: 4 | T5: 3 | U5: 2 | V5: 1 | W5: 7 | X5: 6 | Y5: 5 | Z5: 4 | AA5: 3 | AB5: 2 | AC5: 1 | AD5: 7 | AE5: 6 | AF5: 5 | AG5: 4 | AH5: 3 | AI5: 2 | AJ5: 1 | AK5: 7 | AL5: 6 | AM5: 5 | AN5: 4 | AO5: 3 | AP5: 2 | AQ5: 1 | AR5: 7 | AS5: 6 | AT5: 5
B6: 1 | C6: 1 | D6: UNLOAD | E6: UNLOAD SORTING | F6: EAST | G6: 1 | H6: A | I6: -3 | J6: =I6+$J$4 -> 4 | P6: 3 | W6: 3 | AD6: 3 | AK6: 3
B7: 1 | C7: 2 | D7: TRANSFER | E7: TRANSFER | F7: EAST | G7: =G6 -> 1 | H7: A | I7: -2 | J7: =I7+$J$4 -> 5 | Q7: 2 | X7: 2 | AE7: 2 | AL7: 2
B8: 1 | C8: 3 | D8: SUPPLY | E8: SUPPLY | F8: EAST | G8: 1 | H8: A | I8: 0 | J8: =I8+$J$4 -> 7 | S8: 7 | T8: 6 | U8: 5 | V8: 4 | Z8: 7 | AA8: 6 | AB8: 5 | AC8: 4 | AG8: 7 | AH8: 6 | AI8: 5 | AJ8: 4
B9: =B8 -> 1 | C9: 4 | D9: SUPPLY | E9: EMPTY | F9: EAST | G9: =G8 -> 1 | H9: =H8 -> A | I9: -3 | J9: =I9+$J$4 -> 4 | P9: 3 | Q9: 2 | W9: 3 | X9: 2 | AD9: 3 | AE9: 2 | AK9: 3 | AL9: 2
B10: 1 | C10: 5 | D10: SUPPLY | E10: PREPARE B PASS | F10: EAST | G10: =G9 -> 1 | H10: A | I10: -1 | J10: =I10+$J$4 -> 6 | R10: 1 | Y10: 1 | AF10: 1 | AM10: 1
B11: =B9 -> 1 | C11: 6 | E11: COUNTDOWN | F11: EAST | G11: =G10 -> 1 | H11: =H9 -> A | L11: 7 | M11: 6 | N11: 5 | O11: 4 | P11: 3 | Q11: 2 | R11: 1 | S11: 7 | T11: 6 | U11: 5 | V11: 4 | W11: 3 | X11: 2 | Y11: 1 | Z11: 7 | AA11: 6 | AB11: 5 | AC11: 4 | AD11: 3 | AE11: 2 | AF11: 1 | AG11: 7 | AH11: 6 | AI11: 5 | AJ11: 4 | AK11: 3 | AL11: 2 | AM11: 1 | AN11: 7 | AO11: 6 | AP11: 5 | AQ11: 4 | AR11: 3 | AS11: 2 | AT11: 1
B12: 2 | C12: 1 | D12: UNLOAD | E12: UNLOAD SORTING | F12: EAST | G12: =G11 -> 1 | H12: B | I12: -2 | J12: =I12+$J$4 -> 5 | Q12: 4 | X12: 4 | AE12: 4 | AL12: 4
B13: 2 | C13: 2 | D13: TRANSFER | E13: TRANSFER | F13: EAST | G13: =G12 -> 1 | H13: B | I13: -1 | J13: =I13+$J$4 -> 6 | R13: 3 | S13: 2 | Y13: 3 | Z13: 2 | AF13: 3 | AG13: 2 | AM13: 3 | AN13: 2
B14: 2 | C14: 3 | D14: SUPPLY | E14: SUPPLY | F14: EAST | G14: 1 | H14: B | I14: 2 | J14: =I14+$J$4 -> 9 | U14: 7 | V14: 6 | W14: 5 | X14: 4 | AB14: 7 | AC14: 6 | AD14: 5 | AE14: 4 | AI14: 7 | AJ14: 6 | AK14: 5 | AL14: 4
B15: =B14 -> 2 | C15: 4 | D15: SUPPLY | E15: EMPTY | F15: EAST | G15: =G14 -> 1 | H15: =H14 -> B | I15: -1 | J15: =I15+$J$4 -> 6 | R15: 3 | Y15: 3 | AF15: 3 | AM15: 3
B16: 2 | C16: 5 | D16: SUPPLY | E16: PREPARE B PASS | F16: EAST | G16: =G15 -> 1 | H16: B | I16: 0 | J16: =I16+$J$4 -> 7 | S16: 2 | T16: 1 | Z16: 2 | AA16: 1 | AG16: 2 | AH16: 1 | AN16: 2 | AO16: 1
B17: =B15 -> 2 | C17: 6 | E17: COUNTDOWN | F17: EAST | G17: =G16 -> 1 | H17: =H15 -> B | L17: 2 | M17: 1 | N17: 7 | O17: 6 | P17: 5 | Q17: 4 | R17: 3 | S17: 2 | T17: 1 | U17: 7 | V17: 6 | W17: 5 | X17: 4 | Y17: 3 | Z17: 2 | AA17: 1 | AB17: 7 | AC17: 6 | AD17: 5 | AE17: 4 | AF17: 3 | AG17: 2 | AH17: 1 | AI17: 7 | AJ17: 6 | AK17: 5 | AL17: 4 | AM17: 3 | AN17: 2 | AO17: 1 | AP17: 7 | AQ17: 6 | AR17: 5 | AS17: 4 | AT17: 3
B18: 3 | C18: 1 | D18: UNLOAD | E18: UNLOAD SORTING | F18: EAST | G18: =G17 -> 1 | H18: E | I18: 2 | J18: =I18+$J$4 -> 9 | U18: 3 | AB18: 3 | AI18: 3 | AP18: 3
B19: 3 | C19: 2 | D19: TRANSFER | E19: TRANSFER | F19: EAST | G19: =G18 -> 1 | H19: E | I19: 3 | J19: =I19+$J$4 -> 10 | V19: 2 | AC19: 2 | AJ19: 2 | AQ19: 2
B20: 3 | C20: 3 | D20: SUPPLY | E20: SUPPLY | F20: EAST | G20: 1 | H20: E | I20: 5 | J20: =I20+$J$4 -> 12 | X20: 7 | Y20: 6 | Z20: 5 | AA20: 4 | AE20: 7 | AF20: 6 | AG20: 5 | AH20: 4 | AL20: 7 | AM20: 6 | AN20: 5 | AO20: 4
B21: =B20 -> 3 | C21: 4 | D21: SUPPLY | E21: EMPTY | F21: EAST | G21: =G20 -> 1 | H21: =H20 -> E | I21: 2 | J21: =I21+$J$4 -> 9 | U21: 3 | V21: 2 | AB21: 3 | AC21: 2 | AI21: 3 | AJ21: 2 | AP21: 3 | AQ21: 2
B22: 3 | C22: 5 | D22: SUPPLY | E22: PREPARE B PASS | F22: EAST | G22: =G21 -> 1 | H22: E | I22: 4 | J22: =I22+$J$4 -> 11 | W22: 1 | AD22: 1 | AK22: 1 | AR22: 1
B23: =B21 -> 3 | C23: 6 | E23: COUNTDOWN | F23: EAST | G23: =G22 -> 1 | H23: =H21 -> E | L23: 5 | M23: 4 | N23: 3 | O23: 2 | P23: 1 | Q23: 7 | R23: 6 | S23: 5 | T23: 4 | U23: 3 | V23: 2 | W23: 1 | X23: 7 | Y23: 6 | Z23: 5 | AA23: 4 | AB23: 3 | AC23: 2 | AD23: 1 | AE23: 7 | AF23: 6 | AG23: 5 | AH23: 4 | AI23: 3 | AJ23: 2 | AK23: 1 | AL23: 7 | AM23: 6 | AN23: 5 | AO23: 4 | AP23: 3 | AQ23: 2 | AR23: 1 | AS23: 7 | AT23: 6
B24: 4 | C24: 1 | D24: UNLOAD | E24: UNLOAD SORTING | F24: EAST | G24: =G23 -> 1 | H24: J | I24: 3 | J24: =I24+$J$4 -> 10 | V24: 4 | AC24: 4 | AJ24: 4 | AQ24: 4
B25: 4 | C25: 2 | D25: TRANSFER | E25: TRANSFER | F25: EAST | G25: =G24 -> 1 | H25: J | I25: 4 | J25: =I25+$J$4 -> 11 | W25: 3 | AD25: 3 | AK25: 3 | AR25: 3
B26: 4 | C26: 3 | D26: SUPPLY | E26: SUPPLY | F26: EAST | G26: 1 | H26: J | I26: 7 | J26: =I26+$J$4 -> 14 | Z26: 7 | AA26: 6 | AB26: 5 | AC26: 4 | AG26: 7 | AH26: 6 | AI26: 5 | AJ26: 4 | AN26: 7 | AO26: 6 | AP26: 5 | AQ26: 4
B27: =B26 -> 4 | C27: 4 | D27: SUPPLY | E27: EMPTY | F27: EAST | G27: =G26 -> 1 | H27: =H26 -> J | I27: 4 | J27: =I27+$J$4 -> 11 | W27: 3 | AD27: 3 | AK27: 3 | AR27: 3
B28: 4 | C28: 5 | D28: SUPPLY | E28: PREPARE B PASS | F28: EAST | G28: =G27 -> 1 | H28: J | I28: 5 | J28: =I28+$J$4 -> 12 | X28: 2 | Y28: 1 | AE28: 2 | AF28: 1 | AL28: 2 | AM28: 1 | AS28: 2 | AT28: 1
B29: =B27 -> 4 | C29: 6 | E29: COUNTDOWN | F29: EAST | G29: =G28 -> 1 | H29: =H27 -> J | L29: 7 | M29: 6 | N29: 5 | O29: 4 | P29: 3 | Q29: 2 | R29: 1 | S29: 7 | T29: 6 | U29: 5 | V29: 4 | W29: 3 | X29: 2 | Y29: 1 | Z29: 7 | AA29: 6 | AB29: 5 | AC29: 4 | AD29: 3 | AE29: 2 | AF29: 1 | AG29: 7 | AH29: 6 | AI29: 5 | AJ29: 4 | AK29: 3 | AL29: 2 | AM29: 1 | AN29: 7 | AO29: 6 | AP29: 5 | AQ29: 4 | AR29: 3 | AS29: 2 | AT29: 1
B30: 5 | C30: 1 | D30: UNLOAD | E30: UNLOAD SORTING | F30: EAST | G30: =G29 -> 1 | H30: D1 | I30: 0 | J30: =I30+$J$4 -> 7 | K30: DIRECT | S30: 4 | T30: 3 | Z30: 4 | AA30: 3 | AG30: 4 | AH30: 3 | AN30: 4 | AO30: 3
B31: 5 | C31: 2 | D31: TRANSFER | E31: TRANSFER | F31: EAST | G31: =G30 -> 1 | H31: D1 | I31: 2 | J31: =I31+$J$4 -> 9 | K31: DIRECT | U31: 2 | AB31: 2 | AI31: 2 | AP31: 2
B32: 5 | C32: 3 | D32: SUPPLY | E32: SUPPLY | F32: EAST | G32: 2 | H32: D1 | I32: 4 | J32: =I32+$J$4 -> 11 | K32: DIRECT | W32: 7 | X32: 6 | Y32: 5 | Z32: 4 | AD32: 7 | AE32: 6 | AF32: 5 | AG32: 4 | AK32: 7 | AL32: 6 | AM32: 5 | AN32: 4
B33: =B32 -> 5 | C33: 4 | D33: SUPPLY | E33: EMPTY | F33: EAST | G33: =G32 -> 2 | H33: =H32 -> D1 | I33: 1 | J33: =I33+$J$4 -> 8 | K33: DIRECT | T33: 3 | U33: 2 | AA33: 3 | AB33: 2 | AH33: 3 | AI33: 2 | AO33: 3 | AP33: 2
B34: 5 | C34: 5 | D34: SUPPLY | E34: PREPARE B PASS | F34: EAST | G34: =G33 -> 2 | H34: D1 | I34: 3 | J34: =I34+$J$4 -> 10 | K34: DIRECT | V34: 1 | AC34: 1 | AJ34: 1 | AQ34: 1
B35: =B33 -> 5 | C35: 6 | E35: COUNTDOWN | F35: EAST | G35: =G34 -> 2 | H35: =H33 -> D1 | K35: DIRECT | L35: 4 | M35: 3 | N35: 2 | O35: 1 | P35: 7 | Q35: 6 | R35: 5 | S35: 4 | T35: 3 | U35: 2 | V35: 1 | W35: 7 | X35: 6 | Y35: 5 | Z35: 4 | AA35: 3 | AB35: 2 | AC35: 1 | AD35: 7 | AE35: 6 | AF35: 5 | AG35: 4 | AH35: 3 | AI35: 2 | AJ35: 1 | AK35: 7 | AL35: 6 | AM35: 5 | AN35: 4 | AO35: 3 | AP35: 2 | AQ35: 1 | AR35: 7 | AS35: 6 | AT35: 5
B36: 6 | C36: 1 | D36: UNLOAD | E36: UNLOAD SORTING | F36: EAST | G36: =G35 -> 2 | H36: C | I36: -1 | J36: =I36+$J$4 -> 6 | R36: 4 | Y36: 4 | AF36: 4 | AM36: 4
B37: 6 | C37: 2 | D37: TRANSFER | E37: TRANSFER | F37: EAST | G37: =G36 -> 2 | H37: C | I37: 0 | J37: =I37+$J$4 -> 7 | S37: 3 | Z37: 4 | AG37: 4 | AN37: 4
B38: 6 | C38: 3 | D38: SUPPLY | E38: SUPPLY | F38: EAST | G38: 2 | H38: C | I38: 3 | J38: =I38+$J$4 -> 10 | V38: 7 | W38: 6 | X38: 5 | Y38: 4 | AC38: 7 | AD38: 6 | AE38: 5 | AF38: 4 | AJ38: 7 | AK38: 6 | AL38: 5 | AM38: 4
B39: =B38 -> 6 | C39: 4 | D39: SUPPLY | E39: EMPTY | F39: EAST | G39: =G38 -> 2 | H39: =H38 -> C | I39: 0 | J39: =I39+$J$4 -> 7 | S39: 3 | T39: 2 | Z39: 3 | AA39: 2 | AG39: 3 | AH39: 2 | AN39: 3 | AO39: 2
B40: 6 | C40: 5 | D40: SUPPLY | E40: PREPARE B PASS | F40: EAST | G40: =G39 -> 2 | H40: C | I40: 2 | J40: =I40+$J$4 -> 9 | U40: 1 | AB40: 1 | AI40: 1 | AP40: 1
B41: =B39 -> 6 | C41: 6 | E41: COUNTDOWN | F41: EAST | G41: =G40 -> 2 | H41: =H39 -> C | L41: 3 | M41: 2 | N41: 1 | O41: 7 | P41: 6 | Q41: 5 | R41: 4 | S41: 3 | T41: 2 | U41: 1 | V41: 7 | W41: 6 | X41: 5 | Y41: 4 | Z41: 3 | AA41: 2 | AB41: 1 | AC41: 7 | AD41: 6 | AE41: 5 | AF41: 4 | AG41: 3 | AH41: 2 | AI41: 1 | AJ41: 7 | AK41: 6 | AL41: 5 | AM41: 4 | AN41: 3 | AO41: 2 | AP41: 1 | AQ41: 7 | AR41: 6 | AS41: 5 | AT41: 4
...

Sheet 14
B1: COUNT DOWN : | D1: 14 | E1: 4 Route Ketemu
AA2: PICS
B3: NO SEQ | C3: NO PROCESS | E3: MAIN JOB | F3: PROCESS NAME | G3: ZONE | H3: LANE | I3: LANE | J3: ROUTE | K3: OFFSET 1 | L3: OFFSET 2 | M3: GROUP | N3: 9 | AB3: 8
L4: 14 | N4: 14 | O4: 13 | P4: 12 | Q4: 11 | R4: 10 | S4: 9 | T4: 8 | U4: 7 | V4: 6 | W4: 5 | X4: 4 | Y4: 3 | Z4: 2 | AA4: 1 | AB4: 14 | AC4: 13 | AD4: 12 | AE4: 11 | AF4: 10 | AG4: 9 | AH4: 8 | AI4: 7 | AJ4: 6 | AK4: 5 | AL4: 4 | AM4: 3 | AN4: 2 | AO4: 1 | AP4: 14 | AQ4: 13 | AR4: 12 | AS4: 11 | AT4: 10 | AU4: 9 | AV4: 8 | AW4: 7 | AX4: 6 | AY4: 5 | AZ4: 4 | BA4: 3 | BB4: 2 | BC4: 1 | BD4: 14 | BE4: 13 | BF4: 12 | BG4: 11 | BH4: 10 | BI4: 9 | BJ4: 8 | BK4: 7 | BL4: 6 | BM4: 5 | BN4: 4 | BO4: 3 | BP4: 2 | BQ4: 1 | BR4: 14 | BS4: 13 | BT4: 12 | BU4: 11 | BV4: 10 | BW4: 9 | BX4: 8 | BY4: 7 | BZ4: 6 | CA4: 5 | CB4: 4 | CC4: 3 | CD4: 2 | CE4: 1
B5: 0 | C5: 0 | F5: UNLOAD P LANE | K5: -6 | L5: 6 | N5: 8 | O5: 7 | P5: 6 | Q5: 5 | R5: 4 | S5: 3 | T5: 2 | U5: 1 | V5: 14 | W5: 13 | X5: 12 | Y5: 11 | Z5: 10 | AA5: 9 | AB5: 8 | AC5: 7 | AD5: 6 | AE5: 5 | AF5: 4 | AG5: 3 | AH5: 2 | AI5: 1 | AJ5: 14 | AK5: 13 | AL5: 12 | AM5: 11 | AN5: 10 | AO5: 9 | AP5: 8 | AQ5: 7 | AR5: 6 | AS5: 5 | AT5: 4 | AU5: 3 | AV5: 2 | AW5: 1 | AX5: 14 | AY5: 13 | AZ5: 12 | BA5: 11 | BB5: 10 | BC5: 9 | BD5: 8 | BE5: 7 | BF5: 6 | BG5: 5 | BH5: 4 | BI5: 3 | BJ5: 2 | BK5: 1 | BL5: 14 | BM5: 13 | BN5: 12 | BO5: 11 | BP5: 10 | BQ5: 9 | BR5: 8 | BS5: 7 | BT5: 6 | BU5: 5 | BV5: 4 | BW5: 3 | BX5: 2 | BY5: 1 | BZ5: 14 | CA5: 13 | CB5: 12 | CC5: 11 | CD5: 10 | CE5: 9
B6: 1 | C6: 1 | D6: =F6&"_"&G6&"_"&J6&"_"&I6&"_"&$D$1 -> SORTING_EAST_UNP_1_14 | E6: UNLOAD | F6: SORTING | G6: EAST | H6: 1 | I6: 1 | J6: UNP | L6: =COUNT(V6:AO6) -> 0
B7: 1 | C7: 2 | D7: =F7&"_"&G7&"_"&J7&"_"&I7&"_"&$D$1 -> TRANSFER_EAST_UNP_1_14 | E7: TRANSFER | F7: TRANSFER | G7: EAST | H7: 1 | I7: 1 | J7: UNP | L7: =COUNT(V7:AO7) -> 1 | V7: 1
B8: 1 | C8: 3 | D8: =F8&"_"&G8&"_"&J8&"_"&I8&"_"&$D$1 -> SUPPLY_EAST_UNP_1_14 | E8: SUPPLY | F8: SUPPLY | G8: EAST | H8: 1 | I8: 1 | J8: UNP | L8: =COUNT(AB8:BC8) -> 0
B9: =B8 -> 1 | C9: 4 | D9: =F9&"_"&G9&"_"&J9&"_"&I9&"_"&$D$1 -> EMPTY_EAST_UNP_1_14 | E9: SUPPLY | F9: EMPTY | G9: EAST | H9: 1 | I9: 1 | J9: UNP | K9: -4 | L9: =COUNT(N9:AO9) -> 10 | N9: 1 | O9: =N9+1 -> 2 | P9: =O9+1 -> 3 | Q9: =P9+1 -> 4 | R9: =Q9+1 -> 5 | S9: =R9+1 -> 6 | T9: =S9+1 -> 7 | U9: =T9+1 -> 8 | V9: =U9+1 -> 9 | W9: =V9+1 -> 10
B10: 1 | C10: 5 | D10: =F10&"_"&G10&"_"&J10&"_"&I10&"_"&$D$1 -> PREPARE_EAST_UNP_1_14 | E10: SUPPLY | F10: PREPARE | G10: EAST | H10: 1 | I10: 1 | J10: UNP | L10: =COUNT(N10:AO10) -> 12 | N10: 1 | O10: =N10+1 -> 2 | P10: =O10+1 -> 3 | Q10: =P10+1 -> 4 | R10: =Q10+1 -> 5 | S10: =R10+1 -> 6 | T10: =S10+1 -> 7 | U10: =T10+1 -> 8 | V10: =U10+1 -> 9 | ... Y10: =X10+1 -> 12
B11: =B9 -> 1 | C11: 6 | D11: =F11&"_"&G11&"_"&J11&"_"&I11&"_"&$D$1 -> COUNTDOWN_EAST_UNP_1_14 | F11: COUNTDOWN | G11: EAST | H11: 1 | I11: 1 | J11: UNP | N11: 14 | O11: 13 | P11: 12 | Q11: 11 | R11: 10 | S11: 9 | T11: 8 | U11: 7 | V11: 6 | W11: 5 | X11: 4 | Y11: 3 | Z11: 2 | AA11: 1 | AB11: 14 | AC11: 13 | AD11: 12 | AE11: 11 | AF11: 10 | AG11: 9 | AH11: 8 | AI11: 7 | AJ11: 6 | AK11: 5 | AL11: 4 | AM11: 3 | AN11: 2 | AO11: 1 | AP11: 14 | AQ11: 13 | AR11: 12 | AS11: 11 | AT11: 10 | AU11: 9 | AV11: 8 | AW11: 7 | AX11: 6 | AY11: 5 | AZ11: 4 | BA11: 3 | BB11: 2 | BC11: 1 | BD11: 14 | BE11: 13 | BF11: 12 | BG11: 11 | BH11: 10 | BI11: 9 | BJ11: 8 | BK11: 7 | BL11: 6 | BM11: 5 | BN11: 4 | BO11: 3 | BP11: 2 | BQ11: 1 | BR11: 14 | BS11: 13 | BT11: 12 | BU11: 11 | BV11: 10 | BW11: 9 | BX11: 8 | BY11: 7 | BZ11: 6 | CA11: 5 | CB11: 4 | CC11: 3 | CD11: 2 | CE11: 1
B12: 2 | C12: 1 | D12: =F12&"_"&G12&"_"&J12&"_"&I12&"_"&$D$1 -> SORTING_EAST_A_2_14 | E12: UNLOAD | F12: SORTING | G12: EAST | H12: 2 | I12: 2 | J12: A | L12: =COUNT(V12:AO12) -> 1 | V12: 1
B13: 2 | C13: 2 | D13: =F13&"_"&G13&"_"&J13&"_"&I13&"_"&$D$1 -> TRANSFER_EAST_A_2_14 | E13: TRANSFER | F13: TRANSFER | G13: EAST | H13: 2 | I13: 2 | J13: A | L13: =COUNT(V13:AO13) -> 2 | V13: 1 | W13: =V13+1 -> 2
B14: 2 | C14: 3 | D14: =F14&"_"&G14&"_"&J14&"_"&I14&"_"&$D$1 -> SUPPLY_EAST_A_2_14 | E14: SUPPLY | F14: SUPPLY | G14: EAST | H14: 2 | I14: 2 | J14: A | L14: =COUNT(AB14:BC14) -> 1 | AB14: 1
B15: =B14 -> 2 | C15: 4 | D15: =F15&"_"&G15&"_"&J15&"_"&I15&"_"&$D$1 -> EMPTY_EAST_A_2_14 | E15: SUPPLY | F15: EMPTY | G15: EAST | H15: 2 | I15: 2 | J15: A | K15: -3 | L15: =COUNT(N15:AO15) -> 12 | N15: 1 | O15: =N15+1 -> 2 | P15: =O15+1 -> 3 | Q15: =P15+1 -> 4 | R15: =Q15+1 -> 5 | S15: =R15+1 -> 6 | T15: =S15+1 -> 7 | U15: =T15+1 -> 8 | V15: =U15+1 -> 9 | ... Y15: =X15+1 -> 12
B16: 2 | C16: 5 | D16: =F16&"_"&G16&"_"&J16&"_"&I16&"_"&$D$1 -> PREPARE_EAST_A_2_14 | E16: SUPPLY | F16: PREPARE | G16: EAST | H16: 2 | I16: 2 | J16: A | L16: =COUNT(N16:AO16) -> 13 | N16: 1 | O16: =N16+1 -> 2 | P16: =O16+1 -> 3 | Q16: =P16+1 -> 4 | R16: =Q16+1 -> 5 | S16: =R16+1 -> 6 | T16: =S16+1 -> 7 | U16: =T16+1 -> 8 | V16: =U16+1 -> 9 | ... Z16: =Y16+1 -> 13
B17: =B15 -> 2 | C17: 6 | D17: =F17&"_"&G17&"_"&J17&"_"&I17&"_"&$D$1 -> COUNTDOWN_EAST_A_2_14 | F17: COUNTDOWN | G17: EAST | H17: 2 | I17: 2 | J17: A | N17: 1 | O17: 14 | P17: 13 | Q17: 12 | R17: 11 | S17: 10 | T17: 9 | U17: 8 | V17: 7 | W17: 6 | X17: 5 | Y17: 4 | Z17: 3 | AA17: 2 | AB17: 1 | AC17: 14 | AD17: 13 | AE17: 12 | AF17: 11 | AG17: 10 | AH17: 9 | AI17: 8 | AJ17: 7 | AK17: 6 | AL17: 5 | AM17: 4 | AN17: 3 | AO17: 2 | AP17: 1 | AQ17: 14 | AR17: 13 | AS17: 12 | AT17: 11 | AU17: 10 | AV17: 9 | AW17: 8 | AX17: 7 | AY17: 6 | AZ17: 5 | BA17: 4 | BB17: 3 | BC17: 2 | BD17: 1 | BE17: 14 | BF17: 13 | BG17: 12 | BH17: 11 | BI17: 10 | BJ17: 9 | BK17: 8 | BL17: 7 | BM17: 6 | BN17: 5 | BO17: 4 | BP17: 3 | BQ17: 2 | BR17: 1 | BS17: 14 | BT17: 13 | BU17: 12 | BV17: 11 | BW17: 10 | BX17: 9 | BY17: 8 | BZ17: 7 | CA17: 6 | CB17: 5 | CC17: 4 | CD17: 3 | CE17: 2
C18: 1 | D18: =F18&"_"&G18&"_"&J18&"_"&I18&"_"&$D$1 -> SORTING_EAST_C/U_1_14 | E18: UNLOAD | F18: SORTING | G18: EAST | H18: 1 | I18: 1 | J18: C/U | L18: =COUNT(V18:AO18) -> 2 | V18: 1 | W18: =V18+1 -> 2
C19: 2 | D19: =F19&"_"&G19&"_"&J19&"_"&I19&"_"&$D$1 -> TRANSFER_EAST_C/U_1_14 | E19: TRANSFER | F19: TRANSFER | G19: EAST | H19: 1 | I19: 1 | J19: C/U | L19: =COUNT(V19:AO19) -> 3 | V19: 1 | W19: =V19+1 -> 2 | X19: =W19+1 -> 3
C20: 3 | D20: =F20&"_"&G20&"_"&J20&"_"&I20&"_"&$D$1 -> SUPPLY_EAST_C/U_1_14 | E20: SUPPLY | F20: SUPPLY | G20: EAST | H20: 1 | I20: 1 | J20: C/U | L20: =COUNT(AB20:BC20) -> 2 | AB20: 1 | AC20: =AB20+1 -> 2
C21: 4 | D21: =F21&"_"&G21&"_"&J21&"_"&I21&"_"&$D$1 -> EMPTY_EAST_C/U_1_14 | E21: SUPPLY | F21: EMPTY | G21: EAST | H21: 1 | I21: 1 | J21: C/U | L21: =COUNT(N21:AO21) -> 13 | N21: 1 | O21: =N21+1 -> 2 | P21: =O21+1 -> 3 | Q21: =P21+1 -> 4 | R21: =Q21+1 -> 5 | S21: =R21+1 -> 6 | T21: =S21+1 -> 7 | U21: =T21+1 -> 8 | V21: =U21+1 -> 9 | ... Z21: =Y21+1 -> 13
C22: 5 | D22: =F22&"_"&G22&"_"&J22&"_"&I22&"_"&$D$1 -> PREPARE_EAST_C/U_1_14 | E22: SUPPLY | F22: PREPARE | G22: EAST | H22: 1 | I22: 1 | J22: C/U | L22: =COUNT(N22:AO22) -> 14 | N22: 1 | O22: =N22+1 -> 2 | P22: =O22+1 -> 3 | Q22: =P22+1 -> 4 | R22: =Q22+1 -> 5 | S22: =R22+1 -> 6 | T22: =S22+1 -> 7 | U22: =T22+1 -> 8 | V22: =U22+1 -> 9 | ... AA22: =Z22+1 -> 14
C23: 6 | D23: =F23&"_"&G23&"_"&J23&"_"&I23&"_"&$D$1 -> COUNTDOWN_EAST_C/U_1_14 | F23: COUNTDOWN | G23: EAST | H23: 1 | I23: 1 | J23: C/U | N23: 1 | O23: 14 | P23: 13 | Q23: 12 | R23: 11 | S23: 10 | T23: 9 | U23: 8 | V23: 7 | W23: 6 | X23: 5 | Y23: 4 | Z23: 3 | AA23: 2 | AB23: 1 | AC23: 14 | AD23: 13 | AE23: 12 | AF23: 11 | AG23: 10 | AH23: 9 | AI23: 8 | AJ23: 7 | AK23: 6 | AL23: 5 | AM23: 4 | AN23: 3 | AO23: 2 | AP23: 1 | AQ23: 14 | AR23: 13 | AS23: 12 | AT23: 11 | AU23: 10 | AV23: 9 | AW23: 8 | AX23: 7 | AY23: 6 | AZ23: 5 | BA23: 4 | BB23: 3 | BC23: 2 | BD23: 1 | BE23: 14 | BF23: 13 | BG23: 12 | BH23: 11 | BI23: 10 | BJ23: 9 | BK23: 8 | BL23: 7 | BM23: 6 | BN23: 5 | BO23: 4 | BP23: 3 | BQ23: 2 | BR23: 1 | BS23: 14 | BT23: 13 | BU23: 12 | BV23: 11 | BW23: 10 | BX23: 9 | BY23: 8 | BZ23: 7 | CA23: 6 | CB23: 5 | CC23: 4 | CD23: 3 | CE23: 2
A24: E | B24: 5 | C24: 1 | D24: =F24&"_"&G24&"_"&J24&"_"&I24&"_"&$D$1 -> SORTING_EAST_C_2_14 | E24: UNLOAD | F24: SORTING | G24: EAST | H24: 2 | I24: 2 | J24: C | L24: =COUNT(V24:AO24) -> 3 | V24: 1 | W24: =V24+1 -> 2 | X24: =W24+1 -> 3
A25: E | B25: 5 | C25: 2 | D25: =F25&"_"&G25&"_"&J25&"_"&I25&"_"&$D$1 -> TRANSFER_EAST_C_2_14 | E25: TRANSFER | F25: TRANSFER | G25: EAST | H25: 2 | I25: 2 | J25: C | L25: =COUNT(V25:AO25) -> 4 | V25: 1 | W25: =V25+1 -> 2 | X25: =W25+1 -> 3 | Y25: =X25+1 -> 4
A26: E | B26: 5 | C26: 3 | D26: =F26&"_"&G26&"_"&J26&"_"&I26&"_"&$D$1 -> SUPPLY_EAST_C_2_14 | E26: SUPPLY | F26: SUPPLY | G26: EAST | H26: 2 | I26: 2 | J26: C | L26: =COUNT(AB26:BC26) -> 3 | AB26: 1 | AC26: =AB26+1 -> 2 | AD26: =AC26+1 -> 3
A27: E | B27: 5 | C27: 4 | D27: =F27&"_"&G27&"_"&J27&"_"&I27&"_"&$D$1 -> EMPTY_EAST_C_2_14 | E27: SUPPLY | F27: EMPTY | G27: EAST | H27: 2 | I27: 2 | J27: C | K27: -2 | L27: =COUNT(N27:AO27) -> 14 | N27: 1 | O27: =N27+1 -> 2 | P27: =O27+1 -> 3 | Q27: =P27+1 -> 4 | R27: =Q27+1 -> 5 | S27: =R27+1 -> 6 | T27: =S27+1 -> 7 | U27: =T27+1 -> 8 | V27: =U27+1 -> 9 | ... AA27: =Z27+1 -> 14
A28: E | B28: 5 | C28: 5 | D28: =F28&"_"&G28&"_"&J28&"_"&I28&"_"&$D$1 -> PREPARE_EAST_C_2_14 | E28: SUPPLY | F28: PREPARE | G28: EAST | H28: 2 | I28: 2 | J28: C | L28: =COUNT(N28:AO28) -> 15 | N28: 1 | O28: =N28+1 -> 2 | P28: =O28+1 -> 3 | Q28: =P28+1 -> 4 | R28: =Q28+1 -> 5 | S28: =R28+1 -> 6 | T28: =S28+1 -> 7 | U28: =T28+1 -> 8 | V28: =U28+1 -> 9 | ... AB28: =AA28+1 -> 15
A29: E | B29: =B27 -> 5 | C29: 6 | D29: =F29&"_"&G29&"_"&J29&"_"&I29&"_"&$D$1 -> COUNTDOWN_EAST_C_2_14 | F29: COUNTDOWN | G29: EAST | H29: 2 | I29: 2 | J29: C | N29: 2 | O29: 1 | P29: 14 | Q29: 13 | R29: 12 | S29: 11 | T29: 10 | U29: 9 | V29: 8 | W29: 7 | X29: 6 | Y29: 5 | Z29: 4 | AA29: 3 | AB29: 2 | AC29: 1 | AD29: 14 | AE29: 13 | AF29: 12 | AG29: 11 | AH29: 10 | AI29: 9 | AJ29: 8 | AK29: 7 | AL29: 6 | AM29: 5 | AN29: 4 | AO29: 3 | AP29: 2 | AQ29: 1 | AR29: 14 | AS29: 13 | AT29: 12 | AU29: 11 | AV29: 10 | AW29: 9 | AX29: 8 | AY29: 7 | AZ29: 6 | BA29: 5 | BB29: 4 | BC29: 3 | BD29: 2 | BE29: 1 | BF29: 14 | BG29: 13 | BH29: 12 | BI29: 11 | BJ29: 10 | BK29: 9 | BL29: 8 | BM29: 7 | BN29: 6 | BO29: 5 | BP29: 4 | BQ29: 3 | BR29: 2 | BS29: 1 | BT29: 14 | BU29: 13 | BV29: 12 | BW29: 11 | BX29: 10 | BY29: 9 | BZ29: 8 | CA29: 7 | CB29: 6 | CC29: 5 | CD29: 4 | CE29: 3
B30: 6 | C30: 6 | D30: =F30&"_"&G30&"_"&J30&"_"&I30&"_"&$D$1 -> SORTING_EAST_I_1_14 | E30: UNLOAD | F30: SORTING | G30: EAST | H30: 1 | I30: 1 | J30: I | L30: =COUNT(V30:AO30) -> 4 | V30: 1 | W30: =V30+1 -> 2 | X30: =W30+1 -> 3 | Y30: =X30+1 -> 4
B31: 6 | C31: 1 | D31: =F31&"_"&G31&"_"&J31&"_"&I31&"_"&$D$1 -> TRANSFER_EAST_I_1_14 | E31: TRANSFER | F31: TRANSFER | G31: EAST | H31: 1 | I31: 1 | J31: I | L31: =COUNT(V31:AO31) -> 5 | V31: 1 | W31: =V31+1 -> 2 | X31: =W31+1 -> 3 | Y31: =X31+1 -> 4 | Z31: =Y31+1 -> 5
B32: 6 | C32: 3 | D32: =F32&"_"&G32&"_"&J32&"_"&I32&"_"&$D$1 -> SUPPLY_EAST_I_1_14 | E32: SUPPLY | F32: SUPPLY | G32: EAST | H32: 1 | I32: 1 | J32: I | L32: =COUNT(AB32:BC32) -> 4 | AB32: 1 | AC32: =AB32+1 -> 2 | AD32: =AC32+1 -> 3 | AE32: =AD32+1 -> 4
B33: 6 | C33: 4 | D33: =F33&"_"&G33&"_"&J33&"_"&I33&"_"&$D$1 -> EMPTY_EAST_I_1_14 | E33: SUPPLY | F33: EMPTY | G33: EAST | H33: 1 | I33: 1 | J33: I | K33: -1 | L33: =COUNT(N33:AO33) -> 16 | N33: 1 | O33: =N33+1 -> 2 | P33: =O33+1 -> 3 | Q33: =P33+1 -> 4 | R33: =Q33+1 -> 5 | S33: =R33+1 -> 6 | T33: =S33+1 -> 7 | U33: =T33+1 -> 8 | V33: =U33+1 -> 9 | ... AC33: =AB33+1 -> 16
B34: 6 | C34: 2 | D34: =F34&"_"&G34&"_"&J34&"_"&I34&"_"&$D$1 -> PREPARE_EAST_I_1_14 | E34: SUPPLY | F34: PREPARE | G34: EAST | H34: 1 | I34: 1 | J34: I | L34: =COUNT(N34:AO34) -> 17 | N34: 1 | O34: =N34+1 -> 2 | P34: =O34+1 -> 3 | Q34: =P34+1 -> 4 | R34: =Q34+1 -> 5 | S34: =R34+1 -> 6 | T34: =S34+1 -> 7 | U34: =T34+1 -> 8 | V34: =U34+1 -> 9 | ... AD34: =AC34+1 -> 17
B35: =B33 -> 6 | C35: 6 | D35: =F35&"_"&G35&"_"&J35&"_"&I35&"_"&$D$1 -> COUNTDOWN_EAST_I_1_14 | F35: COUNTDOWN | G35: EAST | H35: 1 | I35: 1 | J35: I | N35: 3 | O35: 2 | P35: 1 | Q35: 14 | R35: 13 | S35: 12 | T35: 11 | U35: 10 | V35: 9 | W35: 8 | X35: 7 | Y35: 6 | Z35: 5 | AA35: 4 | AB35: 3 | AC35: 2 | AD35: 1 | AE35: 14 | AF35: 13 | AG35: 12 | AH35: 11 | AI35: 10 | AJ35: 9 | AK35: 8 | AL35: 7 | AM35: 6 | AN35: 5 | AO35: 4 | AP35: 3 | AQ35: 2 | AR35: 1 | AS35: 14 | AT35: 13 | AU35: 12 | AV35: 11 | AW35: 10 | AX35: 9 | AY35: 8 | AZ35: 7 | BA35: 6 | BB35: 5 | BC35: 4 | BD35: 3 | BE35: 2 | BF35: 1 | BG35: 14 | BH35: 13 | BI35: 12 | BJ35: 11 | BK35: 10 | BL35: 9 | BM35: 8 | BN35: 7 | BO35: 6 | BP35: 5 | BQ35: 4 | BR35: 3 | BS35: 2 | BT35: 1 | BU35: 14 | BV35: 13 | BW35: 12 | BX35: 11 | BY35: 10 | BZ35: 9 | CA35: 8 | CB35: 7 | CC35: 6 | CD35: 5 | CE35: 4
A36: N | B36: 4 | C36: 1 | D36: =F36&"_"&G36&"_"&J36&"_"&I36&"_"&$D$1 -> SORTING_EAST_G_2_14 | E36: UNLOAD | F36: SORTING | G36: EAST | H36: 2 | I36: 2 | J36: G | L36: =COUNT(V36:AO36) -> 5 | V36: 1 | W36: =V36+1 -> 2 | X36: =W36+1 -> 3 | Y36: =X36+1 -> 4 | Z36: =Y36+1 -> 5
A37: N | B37: 4 | C37: 2 | D37: =F37&"_"&G37&"_"&J37&"_"&I37&"_"&$D$1 -> TRANSFER_EAST_G_2_14 | E37: TRANSFER | F37: TRANSFER | G37: EAST | H37: 2 | I37: 2 | J37: G | L37: =COUNT(V37:AO37) -> 7 | V37: 1 | W37: =V37+1 -> 2 | X37: =W37+1 -> 3 | Y37: =X37+1 -> 4 | Z37: =Y37+1 -> 5 | AA37: =Z37+1 -> 6 | AB37: =AA37+1 -> 7
A38: N | B38: 4 | C38: 3 | D38: =F38&"_"&G38&"_"&J38&"_"&I38&"_"&$D$1 -> SUPPLY_EAST_G_2_14 | E38: SUPPLY | F38: SUPPLY | G38: EAST | H38: 2 | I38: 2 | J38: G | L38: =COUNT(AB38:BC38) -> 6 | AB38: 1 | AC38: =AB38+1 -> 2 | AD38: =AC38+1 -> 3 | AE38: =AD38+1 -> 4 | AF38: =AE38+1 -> 5 | AG38: =AF38+1 -> 6
A39: N | B39: 4 | C39: 4 | D39: =F39&"_"&G39&"_"&J39&"_"&I39&"_"&$D$1 -> EMPTY_EAST_G_2_14 | E39: SUPPLY | F39: EMPTY | G39: EAST | H39: 2 | I39: 2 | J39: G | K39: 1 | L39: =COUNT(N39:AO39) -> 18 | N39: 1 | O39: =N39+1 -> 2 | P39: =O39+1 -> 3 | Q39: =P39+1 -> 4 | R39: =Q39+1 -> 5 | S39: =R39+1 -> 6 | T39: =S39+1 -> 7 | U39: =T39+1 -> 8 | V39: =U39+1 -> 9 | ... AE39: =AD39+1 -> 18
A40: N | B40: 4 | C40: 5 | D40: =F40&"_"&G40&"_"&J40&"_"&I40&"_"&$D$1 -> PREPARE_EAST_G_2_14 | E40: SUPPLY | F40: PREPARE | G40: EAST | H40: 2 | I40: 2 | J40: G | L40: =COUNT(N40:AO40) -> 19 | N40: 1 | O40: =N40+1 -> 2 | P40: =O40+1 -> 3 | Q40: =P40+1 -> 4 | R40: =Q40+1 -> 5 | S40: =R40+1 -> 6 | T40: =S40+1 -> 7 | U40: =T40+1 -> 8 | V40: =U40+1 -> 9 | ... AF40: =AE40+1 -> 19
...

Sheet 15
B1: COUNT DOWN : 15 | D1: 15 | E1: 3 Route Ketemu
AB2: PICS
B3: NO SEQ | C3: NO PROCESS | E3: MAIN JOB | F3: PROCESS NAME | G3: ZONE | I3: LANE | J3: ROUTE | K3: OFFSET 1 | L3: OFFSET 2 | M3: GROUP | N3: 9 | AC3: 8
L4: 15 | N4: 15 | O4: 14 | P4: 13 | Q4: 12 | R4: 11 | S4: 10 | T4: 9 | U4: 8 | V4: 7 | W4: 6 | X4: 5 | Y4: 4 | Z4: 3 | AA4: 2 | AB4: 1 | AC4: 15 | AD4: 14 | AE4: 13 | AF4: 12 | AG4: 11 | AH4: 10 | AI4: 9 | AJ4: 8 | AK4: 7 | AL4: 6 | AM4: 5 | AN4: 4 | AO4: 3 | AP4: 2 | AQ4: 1 | AR4: 15 | AS4: 14 | AT4: 13 | AU4: 12 | AV4: 11 | AW4: 10 | AX4: 9 | AY4: 8 | AZ4: 7 | BA4: 6 | BB4: 5 | BC4: 4 | BD4: 3 | BE4: 2 | BF4: 1 | BG4: 15 | BH4: 14 | BI4: 13 | BJ4: 12 | BK4: 11 | BL4: 10 | BM4: 9 | BN4: 8 | BO4: 7 | BP4: 6 | BQ4: 5 | BR4: 4 | BS4: 3 | BT4: 2 | BU4: 1 | BV4: 15 | BW4: 14 | BX4: 13 | BY4: 12 | BZ4: 11 | CA4: 10 | CB4: 9 | CC4: 8 | CD4: 7 | CE4: 6 | CF4: 5 | CG4: 4 | CH4: 3 | CI4: 2 | CJ4: 1
B5: 0 | C5: 0 | F5: UNLOAD P LANE | K5: -6 | L5: 6 | N5: 9 | O5: 8 | P5: 7 | Q5: 6 | R5: 5 | S5: 4 | T5: 3 | U5: 2 | V5: 1 | W5: 15 | X5: 14 | Y5: 13 | Z5: 12 | AA5: 11 | AB5: 10 | AC5: 9 | AD5: 8 | AE5: 7 | AF5: 6 | AG5: 5 | AH5: 4 | AI5: 3 | AJ5: 2 | AK5: 1 | AL5: 15 | AM5: 14 | AN5: 13 | AO5: 12 | AP5: 11 | AQ5: 10 | AR5: 9 | AS5: 8 | AT5: 7 | AU5: 6 | AV5: 5 | AW5: 4 | AX5: 3 | AY5: 2 | AZ5: 1 | BA5: 15 | BB5: 14 | BC5: 13 | BD5: 12 | BE5: 11 | BF5: 10 | BG5: 9 | BH5: 8 | BI5: 7 | BJ5: 6 | BK5: 5 | BL5: 4 | BM5: 3 | BN5: 2 | BO5: 1 | BP5: 15 | BQ5: 14 | BR5: 13 | BS5: 12 | BT5: 11 | BU5: 10 | BV5: 9 | BW5: 8 | BX5: 7 | BY5: 6 | BZ5: 5 | CA5: 4 | CB5: 3 | CC5: 2 | CD5: 1 | CE5: 15 | CF5: 14 | CG5: 13 | CH5: 12 | CI5: 11 | CJ5: 10
B6: 1 | C6: 1 | D6: =F6&"_"&G6&"_"&J6&"_"&H6&"_"&$D$1 -> SORTING_EAST_UNP_1_15 | E6: UNLOAD | F6: SORTING | G6: EAST | H6: 1 | I6: 1 | J6: UNP | L6: =COUNT(W6:AQ6) -> 0 | M6: DIRECT
B7: 1 | C7: 2 | D7: =F7&"_"&G7&"_"&J7&"_"&H7&"_"&$D$1 -> TRANSFER_EAST_UNP_1_15 | E7: TRANSFER | F7: TRANSFER | G7: EAST | H7: 1 | I7: 1 | J7: UNP | L7: =COUNT(W7:AQ7) -> 1 | M7: DIRECT | W7: 1
B8: 1 | C8: 3 | D8: =F8&"_"&G8&"_"&J8&"_"&H8&"_"&$D$1 -> SUPPLY_EAST_UNP_1_15 | E8: SUPPLY | F8: SUPPLY | G8: EAST | H8: 1 | I8: 1 | J8: UNP | L8: =COUNT(AC8:BF8) -> 0 | M8: DIRECT
B9: =B8 -> 1 | C9: 4 | D9: =F9&"_"&G9&"_"&J9&"_"&H9&"_"&$D$1 -> EMPTY_EAST_UNP_1_15 | E9: SUPPLY | F9: EMPTY | G9: EAST | H9: 1 | I9: 1 | J9: UNP | L9: =COUNT(N9:AQ9) -> 11 | M9: DIRECT | N9: 1 | O9: =N9+1 -> 2 | P9: =O9+1 -> 3 | Q9: =P9+1 -> 4 | R9: =Q9+1 -> 5 | S9: =R9+1 -> 6 | T9: =S9+1 -> 7 | U9: =T9+1 -> 8 | V9: =U9+1 -> 9 | ... X9: =W9+1 -> 11
B10: 1 | C10: 5 | D10: =F10&"_"&G10&"_"&J10&"_"&H10&"_"&$D$1 -> PREPARE_EAST_UNP_1_15 | E10: SUPPLY | F10: PREPARE | G10: EAST | H10: 1 | I10: 1 | J10: UNP | L10: =COUNT(N10:AQ10) -> 13 | M10: DIRECT | N10: 1 | O10: =N10+1 -> 2 | P10: =O10+1 -> 3 | Q10: =P10+1 -> 4 | R10: =Q10+1 -> 5 | S10: =R10+1 -> 6 | T10: =S10+1 -> 7 | U10: =T10+1 -> 8 | V10: =U10+1 -> 9 | ... Z10: =Y10+1 -> 13
B11: =B9 -> 1 | C11: 6 | D11: =F11&"_"&G11&"_"&J11&"_"&H11&"_"&$D$1 -> COUNTDOWN_EAST_UNP_1_15 | F11: COUNTDOWN | G11: EAST | H11: 1 | I11: 1 | J11: UNP | M11: DIRECT | N11: 15 | O11: 14 | P11: 13 | Q11: 12 | R11: 11 | S11: 10 | T11: 9 | U11: 8 | V11: 7 | W11: 6 | X11: 5 | Y11: 4 | Z11: 3 | AA11: 2 | AB11: 1 | AC11: 15 | AD11: 14 | AE11: 13 | AF11: 12 | AG11: 11 | AH11: 10 | AI11: 9 | AJ11: 8 | AK11: 7 | AL11: 6 | AM11: 5 | AN11: 4 | AO11: 3 | AP11: 2 | AQ11: 1 | AR11: 15 | AS11: 14 | AT11: 13 | AU11: 12 | AV11: 11 | AW11: 10 | AX11: 9 | AY11: 8 | AZ11: 7 | BA11: 6 | BB11: 5 | BC11: 4 | BD11: 3 | BE11: 2 | BF11: 1 | BG11: 15 | BH11: 14 | BI11: 13 | BJ11: 12 | BK11: 11 | BL11: 10 | BM11: 9 | BN11: 8 | BO11: 7 | BP11: 6 | BQ11: 5 | BR11: 4 | BS11: 3 | BT11: 2 | BU11: 1 | BV11: 15 | BW11: 14 | BX11: 13 | BY11: 12 | BZ11: 11 | CA11: 10 | CB11: 9 | CC11: 8 | CD11: 7 | CE11: 6 | CF11: 5 | CG11: 4 | CH11: 3 | CI11: 2 | CJ11: 1
B12: 2 | C12: 1 | D12: =F12&"_"&G12&"_"&J12&"_"&H12&"_"&$D$1 -> SORTING_EAST_A_2_15 | E12: UNLOAD | F12: SORTING | G12: EAST | H12: 2 | I12: 2 | J12: A | L12: =COUNT(W12:AQ12) -> 1 | W12: 1
B13: 2 | C13: 2 | D13: =F13&"_"&G13&"_"&J13&"_"&H13&"_"&$D$1 -> TRANSFER_EAST_A_2_15 | E13: TRANSFER | F13: TRANSFER | G13: EAST | H13: 2 | I13: 2 | J13: A | L13: =COUNT(W13:AQ13) -> 2 | W13: 1 | X13: =W13+1 -> 2
B14: 2 | C14: 3 | D14: =F14&"_"&G14&"_"&J14&"_"&H14&"_"&$D$1 -> SUPPLY_EAST_A_2_15 | E14: SUPPLY | F14: SUPPLY | G14: EAST | H14: 2 | I14: 2 | J14: A | L14: =COUNT(AC14:BF14) -> 1 | AC14: 1
B15: =B14 -> 2 | C15: 4 | D15: =F15&"_"&G15&"_"&J15&"_"&H15&"_"&$D$1 -> EMPTY_EAST_A_2_15 | E15: SUPPLY | F15: EMPTY | G15: EAST | H15: 2 | I15: 2 | J15: A | L15: =COUNT(N15:AQ15) -> 12 | N15: 1 | O15: =N15+1 -> 2 | P15: =O15+1 -> 3 | Q15: =P15+1 -> 4 | R15: =Q15+1 -> 5 | S15: =R15+1 -> 6 | T15: =S15+1 -> 7 | U15: =T15+1 -> 8 | V15: =U15+1 -> 9 | ... Y15: =X15+1 -> 12
B16: 2 | C16: 5 | D16: =F16&"_"&G16&"_"&J16&"_"&H16&"_"&$D$1 -> PREPARE_EAST_A_2_15 | E16: SUPPLY | F16: PREPARE | G16: EAST | H16: 2 | I16: 2 | J16: A | L16: =COUNT(N16:AQ16) -> 14 | N16: 1 | O16: =N16+1 -> 2 | P16: =O16+1 -> 3 | Q16: =P16+1 -> 4 | R16: =Q16+1 -> 5 | S16: =R16+1 -> 6 | T16: =S16+1 -> 7 | U16: =T16+1 -> 8 | V16: =U16+1 -> 9 | ... AA16: =Z16+1 -> 14
B17: =B15 -> 2 | C17: 6 | D17: =F17&"_"&G17&"_"&J17&"_"&H17&"_"&$D$1 -> COUNTDOWN_EAST_A_2_15 | F17: COUNTDOWN | G17: EAST | H17: 2 | I17: 2 | J17: A | N17: 2 | O17: 1 | P17: 15 | Q17: 14 | R17: 13 | S17: 12 | T17: 11 | U17: 10 | V17: 9 | W17: 8 | X17: 7 | Y17: 6 | Z17: 5 | AA17: 4 | AB17: 3 | AC17: 2 | AD17: 1 | AE17: 15 | AF17: 14 | AG17: 13 | AH17: 12 | AI17: 11 | AJ17: 10 | AK17: 9 | AL17: 8 | AM17: 7 | AN17: 6 | AO17: 5 | AP17: 4 | AQ17: 3 | AR17: 2 | AS17: 1 | AT17: 15 | AU17: 14 | AV17: 13 | AW17: 12 | AX17: 11 | AY17: 10 | AZ17: 9 | BA17: 8 | BB17: 7 | BC17: 6 | BD17: 5 | BE17: 4 | BF17: 3 | BG17: 2 | BH17: 1 | BI17: 15 | BJ17: 14 | BK17: 13 | BL17: 12 | BM17: 11 | BN17: 10 | BO17: 9 | BP17: 8 | BQ17: 7 | BR17: 6 | BS17: 5 | BT17: 4 | BU17: 3 | BV17: 2 | BW17: 1 | BX17: 15 | BY17: 14 | BZ17: 13 | CA17: 12 | CB17: 11 | CC17: 10 | CD17: 9 | CE17: 8 | CF17: 7 | CG17: 6 | CH17: 5 | CI17: 4 | CJ17: 3
C18: 1 | D18: =F18&"_"&G18&"_"&J18&"_"&H18&"_"&$D$1 -> SORTING_EAST_C/U_1_15 | E18: UNLOAD | F18: SORTING | G18: EAST | H18: 1 | I18: 1 | J18: C/U | L18: =COUNT(W18:AQ18) -> 2 | W18: 1 | X18: =W18+1 -> 2
C19: 2 | D19: =F19&"_"&G19&"_"&J19&"_"&H19&"_"&$D$1 -> TRANSFER_EAST_C/U_1_15 | E19: TRANSFER | F19: TRANSFER | G19: EAST | H19: 1 | I19: 1 | J19: C/U | L19: =COUNT(W19:AQ19) -> 3 | W19: 1 | X19: =W19+1 -> 2 | Y19: =X19+1 -> 3
C20: 3 | D20: =F20&"_"&G20&"_"&J20&"_"&H20&"_"&$D$1 -> SUPPLY_EAST_C/U_1_15 | E20: SUPPLY | F20: SUPPLY | G20: EAST | H20: 1 | I20: 1 | J20: C/U | L20: =COUNT(AC20:BF20) -> 2 | AC20: 1 | AD20: =AC20+1 -> 2
C21: 4 | D21: =F21&"_"&G21&"_"&J21&"_"&H21&"_"&$D$1 -> EMPTY_EAST_C/U_1_15 | E21: SUPPLY | F21: EMPTY | G21: EAST | H21: 1 | I21: 1 | J21: C/U | L21: =COUNT(N21:AQ21) -> 13 | N21: 1 | O21: =N21+1 -> 2 | P21: =O21+1 -> 3 | Q21: =P21+1 -> 4 | R21: =Q21+1 -> 5 | S21: =R21+1 -> 6 | T21: =S21+1 -> 7 | U21: =T21+1 -> 8 | V21: =U21+1 -> 9 | ... Z21: =Y21+1 -> 13
C22: 5 | D22: =F22&"_"&G22&"_"&J22&"_"&H22&"_"&$D$1 -> PREPARE_EAST_C/U_1_15 | E22: SUPPLY | F22: PREPARE | G22: EAST | H22: 1 | I22: 1 | J22: C/U | L22: =COUNT(N22:AQ22) -> 14 | N22: 1 | O22: =N22+1 -> 2 | P22: =O22+1 -> 3 | Q22: =P22+1 -> 4 | R22: =Q22+1 -> 5 | S22: =R22+1 -> 6 | T22: =S22+1 -> 7 | U22: =T22+1 -> 8 | V22: =U22+1 -> 9 | ... AA22: =Z22+1 -> 14
C23: 6 | D23: =F23&"_"&G23&"_"&J23&"_"&H23&"_"&$D$1 -> COUNTDOWN_EAST_C/U_1_15 | F23: COUNTDOWN | G23: EAST | H23: 1 | I23: 1 | J23: C/U | N23: 2 | O23: 1 | P23: 15 | Q23: 14 | R23: 13 | S23: 12 | T23: 11 | U23: 10 | V23: 9 | W23: 8 | X23: 7 | Y23: 6 | Z23: 5 | AA23: 4 | AB23: 3 | AC23: 2 | AD23: 1 | AE23: 15 | AF23: 14 | AG23: 13 | AH23: 12 | AI23: 11 | AJ23: 10 | AK23: 9 | AL23: 8 | AM23: 7 | AN23: 6 | AO23: 5 | AP23: 4 | AQ23: 3 | AR23: 2 | AS23: 1 | AT23: 15 | AU23: 14 | AV23: 13 | AW23: 12 | AX23: 11 | AY23: 10 | AZ23: 9 | BA23: 8 | BB23: 7 | BC23: 6 | BD23: 5 | BE23: 4 | BF23: 3 | BG23: 2 | BH23: 1 | BI23: 15 | BJ23: 14 | BK23: 13 | BL23: 12 | BM23: 11 | BN23: 10 | BO23: 9 | BP23: 8 | BQ23: 7 | BR23: 6 | BS23: 5 | BT23: 4 | BU23: 3 | BV23: 2 | BW23: 1 | BX23: 15 | BY23: 14 | BZ23: 13 | CA23: 12 | CB23: 11 | CC23: 10 | CD23: 9 | CE23: 8 | CF23: 7 | CG23: 6 | CH23: 5 | CI23: 4 | CJ23: 3
A24: E | B24: 5 | C24: 1 | D24: =F24&"_"&G24&"_"&J24&"_"&H24&"_"&$D$1 -> SORTING_EAST_C_2_15 | E24: UNLOAD | F24: SORTING | G24: EAST | H24: 2 | I24: 2 | J24: C | L24: =COUNT(W24:AQ24) -> 3 | M24: DIRECT | W24: 1 | X24: =W24+1 -> 2 | Y24: =X24+1 -> 3
A25: E | B25: 5 | C25: 2 | D25: =F25&"_"&G25&"_"&J25&"_"&H25&"_"&$D$1 -> TRANSFER_EAST_C_2_15 | E25: TRANSFER | F25: TRANSFER | G25: EAST | H25: 2 | I25: 2 | J25: C | L25: =COUNT(W25:AQ25) -> 4 | M25: DIRECT | W25: 1 | X25: =W25+1 -> 2 | Y25: =X25+1 -> 3 | Z25: =Y25+1 -> 4
A26: E | B26: 5 | C26: 3 | D26: =F26&"_"&G26&"_"&J26&"_"&H26&"_"&$D$1 -> SUPPLY_EAST_C_2_15 | E26: SUPPLY | F26: SUPPLY | G26: EAST | H26: 2 | I26: 2 | J26: C | L26: =COUNT(AC26:BF26) -> 3 | M26: DIRECT | AC26: 1 | AD26: =AC26+1 -> 2 | AE26: =AD26+1 -> 3
A27: E | B27: 5 | C27: 4 | D27: =F27&"_"&G27&"_"&J27&"_"&H27&"_"&$D$1 -> EMPTY_EAST_C_2_15 | E27: SUPPLY | F27: EMPTY | G27: EAST | H27: 2 | I27: 2 | J27: C | L27: =COUNT(N27:AQ27) -> 14 | M27: DIRECT | N27: 1 | O27: =N27+1 -> 2 | P27: =O27+1 -> 3 | Q27: =P27+1 -> 4 | R27: =Q27+1 -> 5 | S27: =R27+1 -> 6 | T27: =S27+1 -> 7 | U27: =T27+1 -> 8 | V27: =U27+1 -> 9 | ... AA27: =Z27+1 -> 14
A28: E | B28: 5 | C28: 5 | D28: =F28&"_"&G28&"_"&J28&"_"&H28&"_"&$D$1 -> PREPARE_EAST_C_2_15 | E28: SUPPLY | F28: PREPARE | G28: EAST | H28: 2 | I28: 2 | J28: C | L28: =COUNT(N28:AQ28) -> 16 | M28: DIRECT | N28: 1 | O28: =N28+1 -> 2 | P28: =O28+1 -> 3 | Q28: =P28+1 -> 4 | R28: =Q28+1 -> 5 | S28: =R28+1 -> 6 | T28: =S28+1 -> 7 | U28: =T28+1 -> 8 | V28: =U28+1 -> 9 | ... AC28: =AB28+1 -> 16
A29: E | B29: =B27 -> 5 | C29: 6 | D29: =F29&"_"&G29&"_"&J29&"_"&H29&"_"&$D$1 -> COUNTDOWN_EAST_C_2_15 | F29: COUNTDOWN | G29: EAST | H29: 2 | I29: 2 | J29: C | M29: DIRECT | N29: 3 | O29: 2 | P29: 1 | Q29: 15 | R29: 14 | S29: 13 | T29: 12 | U29: 11 | V29: 10 | W29: 9 | X29: 8 | Y29: 7 | Z29: 6 | AA29: 5 | AB29: 4 | AC29: 3 | AD29: 2 | AE29: 1 | AF29: 15 | AG29: 14 | AH29: 13 | AI29: 12 | AJ29: 11 | AK29: 10 | AL29: 9 | AM29: 8 | AN29: 7 | AO29: 6 | AP29: 5 | AQ29: 4 | AR29: 3 | AS29: 2 | AT29: 1 | AU29: 15 | AV29: 14 | AW29: 13 | AX29: 12 | AY29: 11 | AZ29: 10 | BA29: 9 | BB29: 8 | BC29: 7 | BD29: 6 | BE29: 5 | BF29: 4 | BG29: 3 | BH29: 2 | BI29: 1 | BJ29: 15 | BK29: 14 | BL29: 13 | BM29: 12 | BN29: 11 | BO29: 10 | BP29: 9 | BQ29: 8 | BR29: 7 | BS29: 6 | BT29: 5 | BU29: 4 | BV29: 3 | BW29: 2 | BX29: 1 | BY29: 15 | BZ29: 14 | CA29: 13 | CB29: 12 | CC29: 11 | CD29: 10 | CE29: 9 | CF29: 8 | CG29: 7 | CH29: 6 | CI29: 5 | CJ29: 4
B30: 6 | C30: 6 | D30: =F30&"_"&G30&"_"&J30&"_"&H30&"_"&$D$1 -> SORTING_EAST_I_1_15 | E30: UNLOAD | F30: SORTING | G30: EAST | H30: 1 | I30: 1 | J30: I | L30: =COUNT(W30:AQ30) -> 4 | M30: DIRECT | W30: 1 | X30: =W30+1 -> 2 | Y30: =X30+1 -> 3 | Z30: =Y30+1 -> 4
B31: 6 | C31: 1 | D31: =F31&"_"&G31&"_"&J31&"_"&H31&"_"&$D$1 -> TRANSFER_EAST_I_1_15 | E31: TRANSFER | F31: TRANSFER | G31: EAST | H31: 1 | I31: 1 | J31: I | L31: =COUNT(W31:AQ31) -> 5 | M31: DIRECT | W31: 1 | X31: =W31+1 -> 2 | Y31: =X31+1 -> 3 | Z31: =Y31+1 -> 4 | AA31: =Z31+1 -> 5
B32: 6 | C32: 3 | D32: =F32&"_"&G32&"_"&J32&"_"&H32&"_"&$D$1 -> SUPPLY_EAST_I_1_15 | E32: SUPPLY | F32: SUPPLY | G32: EAST | H32: 1 | I32: 1 | J32: I | L32: =COUNT(AC32:BF32) -> 4 | M32: DIRECT | AC32: 1 | AD32: =AC32+1 -> 2 | AE32: =AD32+1 -> 3 | AF32: =AE32+1 -> 4
B33: 6 | C33: 4 | D33: =F33&"_"&G33&"_"&J33&"_"&H33&"_"&$D$1 -> EMPTY_EAST_I_1_15 | E33: SUPPLY | F33: EMPTY | G33: EAST | H33: 1 | I33: 1 | J33: I | L33: =COUNT(N33:AQ33) -> 16 | M33: DIRECT | N33: 1 | O33: =N33+1 -> 2 | P33: =O33+1 -> 3 | Q33: =P33+1 -> 4 | R33: =Q33+1 -> 5 | S33: =R33+1 -> 6 | T33: =S33+1 -> 7 | U33: =T33+1 -> 8 | V33: =U33+1 -> 9 | ... AC33: =AB33+1 -> 16
B34: 6 | C34: 2 | D34: =F34&"_"&G34&"_"&J34&"_"&H34&"_"&$D$1 -> PREPARE_EAST_I_1_15 | E34: SUPPLY | F34: PREPARE | G34: EAST | H34: 1 | I34: 1 | J34: I | L34: =COUNT(N34:AQ34) -> 18 | M34: DIRECT | N34: 1 | O34: =N34+1 -> 2 | P34: =O34+1 -> 3 | Q34: =P34+1 -> 4 | R34: =Q34+1 -> 5 | S34: =R34+1 -> 6 | T34: =S34+1 -> 7 | U34: =T34+1 -> 8 | V34: =U34+1 -> 9 | ... AE34: =AD34+1 -> 18
B35: =B33 -> 6 | C35: 6 | D35: =F35&"_"&G35&"_"&J35&"_"&H35&"_"&$D$1 -> COUNTDOWN_EAST_I_1_15 | F35: COUNTDOWN | G35: EAST | H35: 1 | I35: 1 | J35: I | M35: DIRECT | N35: 4 | O35: 3 | P35: 2 | Q35: 1 | R35: 15 | S35: 14 | T35: 13 | U35: 12 | V35: 11 | W35: 10 | X35: 9 | Y35: 8 | Z35: 7 | AA35: 6 | AB35: 5 | AC35: 4 | AD35: 3 | AE35: 2 | AF35: 1 | AG35: 15 | AH35: 14 | AI35: 13 | AJ35: 12 | AK35: 11 | AL35: 10 | AM35: 9 | AN35: 8 | AO35: 7 | AP35: 6 | AQ35: 5 | AR35: 4 | AS35: 3 | AT35: 2 | AU35: 1 | AV35: 15 | AW35: 14 | AX35: 13 | AY35: 12 | AZ35: 11 | BA35: 10 | BB35: 9 | BC35: 8 | BD35: 7 | BE35: 6 | BF35: 5 | BG35: 4 | BH35: 3 | BI35: 2 | BJ35: 1 | BK35: 15 | BL35: 14 | BM35: 13 | BN35: 12 | BO35: 11 | BP35: 10 | BQ35: 9 | BR35: 8 | BS35: 7 | BT35: 6 | BU35: 5 | BV35: 4 | BW35: 3 | BX35: 2 | BY35: 1 | BZ35: 15 | CA35: 14 | CB35: 13 | CC35: 12 | CD35: 11 | CE35: 10 | CF35: 9 | CG35: 8 | CH35: 7 | CI35: 6 | CJ35: 5
A36: N | B36: 4 | C36: 1 | D36: =F36&"_"&G36&"_"&J36&"_"&H36&"_"&$D$1 -> SORTING_EAST_G_2_15 | E36: UNLOAD | F36: SORTING | G36: EAST | H36: 2 | I36: 2 | J36: G | L36: =COUNT(W36:AQ36) -> 5 | W36: 1 | X36: =W36+1 -> 2 | Y36: =X36+1 -> 3 | Z36: =Y36+1 -> 4 | AA36: =Z36+1 -> 5
A37: N | B37: 4 | C37: 2 | D37: =F37&"_"&G37&"_"&J37&"_"&H37&"_"&$D$1 -> TRANSFER_EAST_G_2_15 | E37: TRANSFER | F37: TRANSFER | G37: EAST | H37: 2 | I37: 2 | J37: G | L37: =COUNT(W37:AQ37) -> 7 | W37: 1 | X37: =W37+1 -> 2 | Y37: =X37+1 -> 3 | Z37: =Y37+1 -> 4 | AA37: =Z37+1 -> 5 | AB37: =AA37+1 -> 6 | AC37: =AB37+1 -> 7
A38: N | B38: 4 | C38: 3 | D38: =F38&"_"&G38&"_"&J38&"_"&H38&"_"&$D$1 -> SUPPLY_EAST_G_2_15 | E38: SUPPLY | F38: SUPPLY | G38: EAST | H38: 2 | I38: 2 | J38: G | L38: =COUNT(AC38:BF38) -> 6 | AC38: 1 | AD38: =AC38+1 -> 2 | AE38: =AD38+1 -> 3 | AF38: =AE38+1 -> 4 | AG38: =AF38+1 -> 5 | AH38: =AG38+1 -> 6
A39: N | B39: 4 | C39: 4 | D39: =F39&"_"&G39&"_"&J39&"_"&H39&"_"&$D$1 -> EMPTY_EAST_G_2_15 | E39: SUPPLY | F39: EMPTY | G39: EAST | H39: 2 | I39: 2 | J39: G | L39: =COUNT(N39:AQ39) -> 18 | N39: 1 | O39: =N39+1 -> 2 | P39: =O39+1 -> 3 | Q39: =P39+1 -> 4 | R39: =Q39+1 -> 5 | S39: =R39+1 -> 6 | T39: =S39+1 -> 7 | U39: =T39+1 -> 8 | V39: =U39+1 -> 9 | ... AE39: =AD39+1 -> 18
A40: N | B40: 4 | C40: 5 | D40: =F40&"_"&G40&"_"&J40&"_"&H40&"_"&$D$1 -> PREPARE_EAST_G_2_15 | E40: SUPPLY | F40: PREPARE | G40: EAST | H40: 2 | I40: 2 | J40: G | L40: =COUNT(N40:AQ40) -> 20 | N40: 1 | O40: =N40+1 -> 2 | P40: =O40+1 -> 3 | Q40: =P40+1 -> 4 | R40: =Q40+1 -> 5 | S40: =R40+1 -> 6 | T40: =S40+1 -> 7 | U40: =T40+1 -> 8 | V40: =U40+1 -> 9 | ... AG40: =AF40+1 -> 20
...

Sheet 16
B1: COUNT DOWN : | D1: 16 | E1: 2 Route Ketemu
AB2: PICS
B3: NO SEQ | C3: NO PROCESS | E3: MAIN JOB | F3: PROCESS NAME | G3: ZONE | H3: LANE | I3: ROUTE | J3: OFFSET 1 | K3: OFFSET 2 | L3: GROUP | M3: 9 | AC3: 8
K4: 16 | M4: 16 | N4: 15 | O4: 14 | P4: 13 | Q4: 12 | R4: 11 | S4: 10 | T4: 9 | U4: 8 | V4: 7 | W4: 6 | X4: 5 | Y4: 4 | Z4: 3 | AA4: 2 | AB4: 1 | AC4: 16 | AD4: 15 | AE4: 14 | AF4: 13 | AG4: 12 | AH4: 11 | AI4: 10 | AJ4: 9 | AK4: 8 | AL4: 7 | AM4: 6 | AN4: 5 | AO4: 4 | AP4: 3 | AQ4: 2 | AR4: 1 | AS4: 16 | AT4: 15 | AU4: 14 | AV4: 13 | AW4: 12 | AX4: 11 | AY4: 10 | AZ4: 9 | BA4: 8 | BB4: 7 | BC4: 6 | BD4: 5 | BE4: 4 | BF4: 3 | BG4: 2 | BH4: 1 | BI4: 16 | BJ4: 15 | BK4: 14 | BL4: 13 | BM4: 12 | BN4: 11 | BO4: 10 | BP4: 9 | BQ4: 8 | BR4: 7 | BS4: 6 | BT4: 5 | BU4: 4 | BV4: 3 | BW4: 2 | BX4: 1 | BY4: 16 | BZ4: 15 | CA4: 14 | CB4: 13 | CC4: 12 | CD4: 11 | CE4: 10 | CF4: 9 | CG4: 8 | CH4: 7 | CI4: 6 | CJ4: 5 | CK4: 4 | CL4: 3 | CM4: 2 | CN4: 1
B5: 0 | C5: 0 | F5: UNLOAD P LANE | K5: 6 | M5: 10 | N5: 9 | O5: 8 | P5: 7 | Q5: 6 | R5: 5 | S5: 4 | T5: 3 | U5: 2 | V5: 1 | W5: 16 | X5: 15 | Y5: 14 | Z5: 13 | AA5: 12 | AB5: 11 | AC5: 10 | AD5: 9 | AE5: 8 | AF5: 7 | AG5: 6 | AH5: 5 | AI5: 4 | AJ5: 3 | AK5: 2 | AL5: 1 | AM5: 16 | AN5: 15 | AO5: 14 | AP5: 13 | AQ5: 12 | AR5: 11 | AS5: 10 | AT5: 9 | AU5: 8 | AV5: 7 | AW5: 6 | AX5: 5 | AY5: 4 | AZ5: 3 | BA5: 2 | BB5: 1 | BC5: 16 | BD5: 15 | BE5: 14 | BF5: 13 | BG5: 12 | BH5: 11 | BI5: 10 | BJ5: 9 | BK5: 8 | BL5: 7 | BM5: 6 | BN5: 5 | BO5: 4 | BP5: 3 | BQ5: 2 | BR5: 1 | BS5: 16 | BT5: 15 | BU5: 14 | BV5: 13 | BW5: 12 | BX5: 11 | BY5: 10 | BZ5: 9 | CA5: 8 | CB5: 7 | CC5: 6 | CD5: 5 | CE5: 4 | CF5: 3 | CG5: 2 | CH5: 1 | CI5: 16 | CJ5: 15 | CK5: 14 | CL5: 13 | CM5: 12 | CN5: 11
B6: 1 | C6: 1 | D6: =F6&"_"&G6&"_"&I6&"_"&H6&"_"&$D$1 -> SORTING_EAST_UNP_1_16 | E6: UNLOAD | F6: SORTING | G6: EAST | H6: 1 | I6: UNP | K6: =COUNT(W6:AR6) -> 0 | L6: DIRECT
B7: 1 | C7: 2 | D7: =F7&"_"&G7&"_"&I7&"_"&H7&"_"&$D$1 -> TRANSFER_EAST_UNP_1_16 | E7: TRANSFER | F7: TRANSFER | G7: EAST | H7: 1 | I7: UNP | K7: =COUNT(W7:AR7) -> 1 | L7: DIRECT | W7: 1
B8: 1 | C8: 3 | D8: =F8&"_"&G8&"_"&I8&"_"&H8&"_"&$D$1 -> SUPPLY_EAST_UNP_1_16 | E8: SUPPLY | F8: SUPPLY | G8: EAST | H8: 1 | I8: UNP | K8: =COUNT(AC8:BH8) -> 0 | L8: DIRECT
B9: =B8 -> 1 | C9: 4 | D9: =F9&"_"&G9&"_"&I9&"_"&H9&"_"&$D$1 -> EMPTY_EAST_UNP_1_16 | E9: SUPPLY | F9: EMPTY | G9: EAST | H9: 1 | I9: UNP | K9: =COUNT(M9:AR9) -> 12 | L9: DIRECT | M9: 1 | N9: =M9+1 -> 2 | O9: =N9+1 -> 3 | P9: =O9+1 -> 4 | Q9: =P9+1 -> 5 | R9: =Q9+1 -> 6 | S9: =R9+1 -> 7 | T9: =S9+1 -> 8 | U9: =T9+1 -> 9 | ... X9: =W9+1 -> 12
B10: 1 | C10: 5 | D10: =F10&"_"&G10&"_"&I10&"_"&H10&"_"&$D$1 -> PREPARE_EAST_UNP_1_16 | E10: SUPPLY | F10: PREPARE | G10: EAST | H10: 1 | I10: UNP | K10: =COUNT(M10:AR10) -> 14 | L10: DIRECT | M10: 1 | N10: =M10+1 -> 2 | O10: =N10+1 -> 3 | P10: =O10+1 -> 4 | Q10: =P10+1 -> 5 | R10: =Q10+1 -> 6 | S10: =R10+1 -> 7 | T10: =S10+1 -> 8 | U10: =T10+1 -> 9 | ... Z10: =Y10+1 -> 14
B11: =B9 -> 1 | C11: 6 | D11: =F11&"_"&G11&"_"&I11&"_"&H11&"_"&$D$1 -> COUNTDOWN_EAST_UNP_1_16 | F11: COUNTDOWN | G11: EAST | H11: 1 | I11: UNP | L11: DIRECT | M11: 16 | N11: 15 | O11: 14 | P11: 13 | Q11: 12 | R11: 11 | S11: 10 | T11: 9 | U11: 8 | V11: 7 | W11: 6 | X11: 5 | Y11: 4 | Z11: 3 | AA11: 2 | AB11: 1 | AC11: 16 | AD11: 15 | AE11: 14 | AF11: 13 | AG11: 12 | AH11: 11 | AI11: 10 | AJ11: 9 | AK11: 8 | AL11: 7 | AM11: 6 | AN11: 5 | AO11: 4 | AP11: 3 | AQ11: 2 | AR11: 1 | AS11: 16 | AT11: 15 | AU11: 14 | AV11: 13 | AW11: 12 | AX11: 11 | AY11: 10 | AZ11: 9 | BA11: 8 | BB11: 7 | BC11: 6 | BD11: 5 | BE11: 4 | BF11: 3 | BG11: 2 | BH11: 1 | BI11: 16 | BJ11: 15 | BK11: 14 | BL11: 13 | BM11: 12 | BN11: 11 | BO11: 10 | BP11: 9 | BQ11: 8 | BR11: 7 | BS11: 6 | BT11: 5 | BU11: 4 | BV11: 3 | BW11: 2 | BX11: 1 | BY11: 16 | BZ11: 15 | CA11: 14 | CB11: 13 | CC11: 12 | CD11: 11 | CE11: 10 | CF11: 9 | CG11: 8 | CH11: 7 | CI11: 6 | CJ11: 5 | CK11: 4 | CL11: 3 | CM11: 2 | CN11: 1
B12: 2 | C12: 1 | D12: =F12&"_"&G12&"_"&I12&"_"&H12&"_"&$D$1 -> SORTING_EAST_A_2_16 | E12: UNLOAD | F12: SORTING | G12: EAST | H12: 2 | I12: A | K12: =COUNT(W12:AR12) -> 1 | W12: 1
B13: 2 | C13: 2 | D13: =F13&"_"&G13&"_"&I13&"_"&H13&"_"&$D$1 -> TRANSFER_EAST_A_2_16 | E13: TRANSFER | F13: TRANSFER | G13: EAST | H13: 2 | I13: A | K13: =COUNT(W13:AR13) -> 3 | W13: 1 | X13: =W13+1 -> 2 | Y13: =X13+1 -> 3
B14: 2 | C14: 3 | D14: =F14&"_"&G14&"_"&I14&"_"&H14&"_"&$D$1 -> SUPPLY_EAST_A_2_16 | E14: SUPPLY | F14: SUPPLY | G14: EAST | H14: 2 | I14: A | K14: =COUNT(AC14:BH14) -> 1 | AC14: 1
B15: =B14 -> 2 | C15: 4 | D15: =F15&"_"&G15&"_"&I15&"_"&H15&"_"&$D$1 -> EMPTY_EAST_A_2_16 | E15: SUPPLY | F15: EMPTY | G15: EAST | H15: 2 | I15: A | K15: =COUNT(M15:AR15) -> 13 | M15: 1 | N15: =M15+1 -> 2 | O15: =N15+1 -> 3 | P15: =O15+1 -> 4 | Q15: =P15+1 -> 5 | R15: =Q15+1 -> 6 | S15: =R15+1 -> 7 | T15: =S15+1 -> 8 | U15: =T15+1 -> 9 | ... Y15: =X15+1 -> 13
B16: 2 | C16: 5 | D16: =F16&"_"&G16&"_"&I16&"_"&H16&"_"&$D$1 -> PREPARE_EAST_A_2_16 | E16: SUPPLY | F16: PREPARE | G16: EAST | H16: 2 | I16: A | K16: =COUNT(M16:AR16) -> 15 | M16: 1 | N16: =M16+1 -> 2 | O16: =N16+1 -> 3 | P16: =O16+1 -> 4 | Q16: =P16+1 -> 5 | R16: =Q16+1 -> 6 | S16: =R16+1 -> 7 | T16: =S16+1 -> 8 | U16: =T16+1 -> 9 | ... AA16: =Z16+1 -> 15
B17: =B15 -> 2 | C17: 6 | D17: =F17&"_"&G17&"_"&I17&"_"&H17&"_"&$D$1 -> COUNTDOWN_EAST_A_2_16 | F17: COUNTDOWN | G17: EAST | H17: 2 | I17: A | M17: 1 | N17: 16 | O17: 15 | P17: 14 | Q17: 13 | R17: 12 | S17: 11 | T17: 10 | U17: 9 | V17: 8 | W17: 7 | X17: 6 | Y17: 5 | Z17: 4 | AA17: 3 | AB17: 2 | AC17: 1 | AD17: 16 | AE17: 15 | AF17: 14 | AG17: 13 | AH17: 12 | AI17: 11 | AJ17: 10 | AK17: 9 | AL17: 8 | AM17: 7 | AN17: 6 | AO17: 5 | AP17: 4 | AQ17: 3 | AR17: 2 | AS17: 1 | AT17: 16 | AU17: 15 | AV17: 14 | AW17: 13 | AX17: 12 | AY17: 11 | AZ17: 10 | BA17: 9 | BB17: 8 | BC17: 7 | BD17: 6 | BE17: 5 | BF17: 4 | BG17: 3 | BH17: 2 | BI17: 1 | BJ17: 16 | BK17: 15 | BL17: 14 | BM17: 13 | BN17: 12 | BO17: 11 | BP17: 10 | BQ17: 9 | BR17: 8 | BS17: 7 | BT17: 6 | BU17: 5 | BV17: 4 | BW17: 3 | BX17: 2 | BY17: 1 | BZ17: 16 | CA17: 15 | CB17: 14 | CC17: 13 | CD17: 12 | CE17: 11 | CF17: 10 | CG17: 9 | CH17: 8 | CI17: 7 | CJ17: 6 | CK17: 5 | CL17: 4 | CM17: 3 | CN17: 2
C18: 1 | D18: =F18&"_"&G18&"_"&I18&"_"&H18&"_"&$D$1 -> SORTING_EAST_C/U_1_16 | E18: UNLOAD | F18: SORTING | G18: EAST | H18: 1 | I18: C/U | K18: =COUNT(W18:AR18) -> 3 | W18: 1 | X18: =W18+1 -> 2 | Y18: =X18+1 -> 3
C19: 2 | D19: =F19&"_"&G19&"_"&I19&"_"&H19&"_"&$D$1 -> TRANSFER_EAST_C/U_1_16 | E19: TRANSFER | F19: TRANSFER | G19: EAST | H19: 1 | I19: C/U | K19: =COUNT(W19:AR19) -> 4 | W19: 1 | X19: =W19+1 -> 2 | Y19: =X19+1 -> 3 | Z19: =Y19+1 -> 4
C20: 3 | D20: =F20&"_"&G20&"_"&I20&"_"&H20&"_"&$D$1 -> SUPPLY_EAST_C/U_1_16 | E20: SUPPLY | F20: SUPPLY | G20: EAST | H20: 1 | I20: C/U | K20: =COUNT(AC20:BH20) -> 2 | AC20: 1 | AD20: 2
C21: 4 | D21: =F21&"_"&G21&"_"&I21&"_"&H21&"_"&$D$1 -> EMPTY_EAST_C/U_1_16 | E21: SUPPLY | F21: EMPTY | G21: EAST | H21: 1 | I21: C/U | K21: =COUNT(M21:AR21) -> 14 | M21: 1 | N21: =M21+1 -> 2 | O21: =N21+1 -> 3 | P21: =O21+1 -> 4 | Q21: =P21+1 -> 5 | R21: =Q21+1 -> 6 | S21: =R21+1 -> 7 | T21: =S21+1 -> 8 | U21: =T21+1 -> 9 | ... Z21: =Y21+1 -> 14
C22: 5 | D22: =F22&"_"&G22&"_"&I22&"_"&H22&"_"&$D$1 -> PREPARE_EAST_C/U_1_16 | E22: SUPPLY | F22: PREPARE | G22: EAST | H22: 1 | I22: C/U | K22: =COUNT(M22:AR22) -> 16 | M22: 1 | N22: =M22+1 -> 2 | O22: =N22+1 -> 3 | P22: =O22+1 -> 4 | Q22: =P22+1 -> 5 | R22: =Q22+1 -> 6 | S22: =R22+1 -> 7 | T22: =S22+1 -> 8 | U22: =T22+1 -> 9 | ... AB22: =AA22+1 -> 16
C23: 6 | D23: =F23&"_"&G23&"_"&I23&"_"&H23&"_"&$D$1 -> COUNTDOWN_EAST_C/U_1_16 | F23: COUNTDOWN | G23: EAST | H23: 1 | I23: C/U | M23: 1 | N23: 16 | O23: 15 | P23: 14 | Q23: 13 | R23: 12 | S23: 11 | T23: 10 | U23: 9 | V23: 8 | W23: 7 | X23: 6 | Y23: 5 | Z23: 4 | AA23: 3 | AB23: 2 | AC23: 1 | AD23: 16 | AE23: 15 | AF23: 14 | AG23: 13 | AH23: 12 | AI23: 11 | AJ23: 10 | AK23: 9 | AL23: 8 | AM23: 7 | AN23: 6 | AO23: 5 | AP23: 4 | AQ23: 3 | AR23: 2 | AS23: 1 | AT23: 16 | AU23: 15 | AV23: 14 | AW23: 13 | AX23: 12 | AY23: 11 | AZ23: 10 | BA23: 9 | BB23: 8 | BC23: 7 | BD23: 6 | BE23: 5 | BF23: 4 | BG23: 3 | BH23: 2 | BI23: 1 | BJ23: 16 | BK23: 15 | BL23: 14 | BM23: 13 | BN23: 12 | BO23: 11 | BP23: 10 | BQ23: 9 | BR23: 8 | BS23: 7 | BT23: 6 | BU23: 5 | BV23: 4 | BW23: 3 | BX23: 2 | BY23: 1 | BZ23: 16 | CA23: 15 | CB23: 14 | CC23: 13 | CD23: 12 | CE23: 11 | CF23: 10 | CG23: 9 | CH23: 8 | CI23: 7 | CJ23: 6 | CK23: 5 | CL23: 4 | CM23: 3 | CN23: 2
A24: E | B24: 5 | C24: 1 | D24: =F24&"_"&G24&"_"&I24&"_"&H24&"_"&$D$1 -> SORTING_EAST_C_2_16 | E24: UNLOAD | F24: SORTING | G24: EAST | H24: 2 | I24: C | K24: =COUNT(W24:AR24) -> 4 | L24: DIRECT | W24: 1 | X24: =W24+1 -> 2 | Y24: =X24+1 -> 3 | Z24: =Y24+1 -> 4
A25: E | B25: 5 | C25: 2 | D25: =F25&"_"&G25&"_"&I25&"_"&H25&"_"&$D$1 -> TRANSFER_EAST_C_2_16 | E25: TRANSFER | F25: TRANSFER | G25: EAST | H25: 2 | I25: C | K25: =COUNT(W25:AR25) -> 5 | L25: DIRECT | W25: 1 | X25: =W25+1 -> 2 | Y25: =X25+1 -> 3 | Z25: =Y25+1 -> 4 | AA25: =Z25+1 -> 5
A26: E | B26: 5 | C26: 3 | D26: =F26&"_"&G26&"_"&I26&"_"&H26&"_"&$D$1 -> SUPPLY_EAST_C_2_16 | E26: SUPPLY | F26: SUPPLY | G26: EAST | H26: 2 | I26: C | K26: =COUNT(AC26:BH26) -> 3 | L26: DIRECT | AC26: 1 | AD26: =AC26+1 -> 2 | AE26: =AD26+1 -> 3
A27: E | B27: 5 | C27: 4 | D27: =F27&"_"&G27&"_"&I27&"_"&H27&"_"&$D$1 -> EMPTY_EAST_C_2_16 | E27: SUPPLY | F27: EMPTY | G27: EAST | H27: 2 | I27: C | K27: =COUNT(M27:AR27) -> 15 | L27: DIRECT | M27: 1 | N27: =M27+1 -> 2 | O27: =N27+1 -> 3 | P27: =O27+1 -> 4 | Q27: =P27+1 -> 5 | R27: =Q27+1 -> 6 | S27: =R27+1 -> 7 | T27: =S27+1 -> 8 | U27: =T27+1 -> 9 | ... AA27: =Z27+1 -> 15
A28: E | B28: 5 | C28: 5 | D28: =F28&"_"&G28&"_"&I28&"_"&H28&"_"&$D$1 -> PREPARE_EAST_C_2_16 | E28: SUPPLY | F28: PREPARE | G28: EAST | H28: 2 | I28: C | K28: =COUNT(M28:AR28) -> 17 | L28: DIRECT | M28: 1 | N28: =M28+1 -> 2 | O28: =N28+1 -> 3 | P28: =O28+1 -> 4 | Q28: =P28+1 -> 5 | R28: =Q28+1 -> 6 | S28: =R28+1 -> 7 | T28: =S28+1 -> 8 | U28: =T28+1 -> 9 | ... AC28: =AB28+1 -> 17
A29: E | B29: =B27 -> 5 | C29: 6 | D29: =F29&"_"&G29&"_"&I29&"_"&H29&"_"&$D$1 -> COUNTDOWN_EAST_C_2_16 | F29: COUNTDOWN | G29: EAST | H29: 2 | I29: C | L29: DIRECT | M29: 2 | N29: 1 | O29: 16 | P29: 15 | Q29: 14 | R29: 13 | S29: 12 | T29: 11 | U29: 10 | V29: 9 | W29: 8 | X29: 7 | Y29: 6 | Z29: 5 | AA29: 4 | AB29: 3 | AC29: 2 | AD29: 1 | AE29: 16 | AF29: 15 | AG29: 14 | AH29: 13 | AI29: 12 | AJ29: 11 | AK29: 10 | AL29: 9 | AM29: 8 | AN29: 7 | AO29: 6 | AP29: 5 | AQ29: 4 | AR29: 3 | AS29: 2 | AT29: 1 | AU29: 16 | AV29: 15 | AW29: 14 | AX29: 13 | AY29: 12 | AZ29: 11 | BA29: 10 | BB29: 9 | BC29: 8 | BD29: 7 | BE29: 6 | BF29: 5 | BG29: 4 | BH29: 3 | BI29: 2 | BJ29: 1 | BK29: 16 | BL29: 15 | BM29: 14 | BN29: 13 | BO29: 12 | BP29: 11 | BQ29: 10 | BR29: 9 | BS29: 8 | BT29: 7 | BU29: 6 | BV29: 5 | BW29: 4 | BX29: 3 | BY29: 2 | BZ29: 1 | CA29: 16 | CB29: 15 | CC29: 14 | CD29: 13 | CE29: 12 | CF29: 11 | CG29: 10 | CH29: 9 | CI29: 8 | CJ29: 7 | CK29: 6 | CL29: 5 | CM29: 4 | CN29: 3
B30: 6 | C30: 6 | D30: =F30&"_"&G30&"_"&I30&"_"&H30&"_"&$D$1 -> SORTING_EAST_I_1_16 | E30: UNLOAD | F30: SORTING | G30: EAST | H30: 1 | I30: I | K30: =COUNT(W30:AR30) -> 5 | L30: DIRECT | W30: 1 | X30: =W30+1 -> 2 | Y30: =X30+1 -> 3 | Z30: =Y30+1 -> 4 | AA30: =Z30+1 -> 5
B31: 6 | C31: 1 | D31: =F31&"_"&G31&"_"&I31&"_"&H31&"_"&$D$1 -> TRANSFER_EAST_I_1_16 | E31: TRANSFER | F31: TRANSFER | G31: EAST | H31: 1 | I31: I | K31: =COUNT(W31:AR31) -> 6 | L31: DIRECT | W31: 1 | X31: =W31+1 -> 2 | Y31: =X31+1 -> 3 | Z31: =Y31+1 -> 4 | AA31: =Z31+1 -> 5 | AB31: =AA31+1 -> 6
B32: 6 | C32: 3 | D32: =F32&"_"&G32&"_"&I32&"_"&H32&"_"&$D$1 -> SUPPLY_EAST_I_1_16 | E32: SUPPLY | F32: SUPPLY | G32: EAST | H32: 1 | I32: I | K32: =COUNT(AC32:BH32) -> 4 | L32: DIRECT | AC32: 1 | AD32: =AC32+1 -> 2 | AE32: =AD32+1 -> 3 | AF32: =AE32+1 -> 4
