Workbook

Sheet Pivot 1
B3: Values
A4: Gabungan | B4: Sum of Vol/Box Day | C4: Sum of Vol/m3 Day | E4: Vol Cycle Aug | F4: Vol Cycle Sep | G4: Order Freq Aug 26 | H4: Order Freq Sep 26 | I4: Check | J4: Remark
A5: 0003-1-43 | B5: 16 | C5: 2.046984 | E5: 0.6396825 | F5: =C5/H5 -> 0.511746 | G5: 4 | H5: 4
A6: 0003-1-FP1-43 | B6: 28 | C6: 0.99188475 | E6: 0.89340731 | F6: =C6/H6 -> 0.49594237 | G6: 2 | H6: 2
A7: 0003-1-OP1-43 | B7: 71 | C7: 2.816623 | E7: 0.53632327 | F7: =C7/H7 -> 0.70415576 | G7: 8 | H7: 4
A8: 0003-2-43 | B8: 16 | C8: 0.32 | E8: 0.52 | F8: =C8/H8 -> 0.32 | G8: 1 | H8: 1
A9: 0003-2-OP1-43 | B9: 36 | C9: 2.450994 | E9: 0.48144525 | F9: =C9/H9 -> 0.6127485 | G9: 8 | H9: 4
A10: 0003-3-IP1-43 | B10: 88 | C10: 5.5068808 | E10: 0.7062179 | F10: =C10/H10 -> 0.91781346 | G10: 8 | H10: 6
A11: 0003-3-LP1-43 | B11: 70 | C11: 4.5976388 | E11: 0.75530398 | F11: =C11/H11 -> 0.76627314 | G11: 4 | H11: 6
A12: 0003-3-MP1-43 | B12: 144 | C12: 13.480322 | E12: 0.82034162 | F12: =C12/H12 -> 0.56168009 | G12: 16 | H12: 24
A13: 0003-3-OP1-43 | B13: 349 | C13: 8.0651858 | E13: 0.7703518 | F13: =C13/H13 -> 0.67209882 | G13: 12 | H13: 12
A14: 0003-5-GP1-43 | B14: 223 | C14: 6.1410274 | E14: 0.84903656 | F14: =C14/H14 -> 0.76762842 | G14: 8 | H14: 8
A15: 0003-5-HP1-43 | B15: 52 | C15: 2.275923 | E15: 0.875355 | F15: =C15/H15 -> 0.56898075 | G15: 4 | H15: 4
A16: 0003-5-JP1-43 | B16: 159 | C16: 13.037403 | E16: 0.84930477 | F16: =C16/H16 -> 0.54322511 | G16: 24 | H16: 24
A17: 0003-5-LP1-43 | B17: 313 | C17: 10.503982 | E17: 0.90881467 | F17: =C17/H17 -> 0.87533185 | G17: 14 | H17: 12
A18: 0003-8-HP1-43 | B18: 4 | C18: 0.0462367 | E18: 0.0924734 | F18: =C18/H18 -> 0.0462367 | G18: 1 | H18: 1
A19: 0003-8-NP1-43 | B19: 211 | C19: 19.056478 | E19: 0.90478601 | F19: =C19/H19 -> 0.79401993 | G19: 24 | H19: 24 | I19: Set Part Uniq 683E & 684E ( 0.7 m3 )
A20: 0003-A-BP1-43 | B20: 38 | C20: 4.618385 | E20: 0.92172235 | F20: =C20/H20 -> 0.76973084 | G20: 8 | H20: 6
A21: 0003-A-FP1-43 | B21: 8 | C21: 0.5094144 | E21: 0.4457376 | F21: =C21/H21 -> 0.5094144 | G21: 2 | H21: 1
A22: 0003-A-GP1-43 | B22: 92 | C22: 5.3784316 | E22: 0.61794295 | F22: =C22/H22 -> 0.67230396 | G22: 12 | H22: 8
A23: 0003-A-HP1-43 | B23: 26 | C23: 1.1379615 | E23: 0.875355 | F23: =C23/H23 -> 0.56898075 | G23: 2 | H23: 2
A24: 0003-A-LP1-43 | B24: 302 | C24: 13.201499 | E24: 0.57624232 | F24: =C24/H24 -> 0.55006245 | G24: 24 | H24: 24
A25: 0003-A-MP1-43 | B25: 260 | C25: 15.944516 | E25: 0.71592166 | F25: =C25/H25 -> 0.66435483 | G25: 24 | H25: 24
A26: 0003-C-LP1-43 | B26: 119 | C26: 7.8173774 | E26: 0.71166688 | F26: =C26/H26 -> 0.97717218 | G26: 12 | H26: 8
A27: 0003-E-43 | B27: 261 | C27: 20.969335 | E27: 0.90323747 | F27: =C27/H27 -> 0.87372229 | G27: 24 | H27: 24
A28: 0003-E-FP1-43 | B28: 18 | C28: 0.7878195 | E28: 0.65651625 | F28: =C28/H28 -> 0.39390975 | G28: 2 | H28: 2
A29: 0003-F-FP1-43 | B29: 152 | C29: 19.465698 | E29: 0.78439077 | F29: =C29/H29 -> 0.81107073 | G29: 24 | H29: 24
A30: 0003-F-MP1-43 | B30: 152 | C30: 19.465698 | E30: 0.78439077 | F30: =C30/H30 -> 0.81107073 | G30: 24 | H30: 24
A31: 2536-1-43 | B31: 33 | C31: 0.901284 | E31: 0.459888 | F31: =C31/H31 -> 0.450642 | G31: 2 | H31: 2 | I31: Req Order Freq Vol 0.5 m3 ( Problem part assy )
A32: 5000-1-AP1-43 | B32: 37 | C32: 1.071861 | E32: 0.85633286 | F32: =C32/H32 -> 0.53593049 | G32: 2 | H32: 2 | I32: PART BERAT ( REQ 0.3 m3 ) TRIAL DOWN Juni 2025 0.5 m3
A33: 5000-1-BP1-43 | B33: 2 | C33: 0.0875355 | E33: 0.175071 | F33: =C33/H33 -> 0.0875355 | G33: 1 | H33: 1
A34: 5000-1-CP1-43 | B34: 9 | C34: 0.42768 | E34: 0.30888 | F34: =C34/H34 -> 0.42768 | G34: 2 | H34: 1 | I34: Req Order Freq Vol 0.3 m3 ( Problem part assy )
A35: 5000-1-DP1-43 | B35: 608 | C35: 39.955906 | E35: 1.5991124 | F35: =C35/H35 -> 1.6648294 | G35: 24 | H35: 24 | I35: Set Part
A36: 5000-1-EP1-43 | B36: 49 | C36: 2.8175778 | E36: 0.42257926 | F36: =C36/H36 -> 0.4695963 | G36: 8 | H36: 6 | I36: PART BERAT ( REQ 0.5 m3 )
A37: 5000-1-FP1-43 | B37: 5 | C37: 0.318384 | E37: 0.636768 | F37: =C37/H37 -> 0.318384 | G37: 1 | H37: 1
A38: 5000-1-GP1-43 | B38: 152 | C38: 8.3904 | E38: 0.6716 | F38: =C38/H38 -> 0.6992 | G38: 12 | H38: 12 | I38: Operation Req ( 0.5 m3 )
A39: 5000-1-JP1-43 | B39: 51 | C39: 1.8436507 | E39: 0.7238948 | F39: =C39/H39 -> 0.92182536 | G39: 4 | H39: 2
A40: 5000-1-KP1-43 | B40: 317 | C40: 17.434726 | E40: 0.78810852 | F40: =C40/H40 -> 0.72644691 | G40: 24 | H40: 24
A41: 5000-2-43 | B41: 75 | C41: 7.935 | E41: 1.0227333 | F41: =C41/H41 -> 0.991875 | G41: 12 | H41: 8
A42: 5002-1-43 | B42: 199 | C42: 4.4875695 | E42: 0.67034861 | F42: =C42/H42 -> 0.74792826 | G42: 8 | H42: 6
...

Sheet Pivot 2
E3: Values
A4: Gabungan | B4: Supplier / Exporter Name | C4: Shipping Dock | D4: CONVEYANCE | E4: Sum of Vol/Box Day | F4: Sum of Vol/m3 Day
A5: 0003-1-43 | B5: SUGITY CREATIVES | C5: (blank) | D5: D | E5: 16 | F5: 2.046984
A6: 0003-1-FP1-43 | B6: SUGITY CREATIVES | C6: FP1 | D6: N | E6: 28 | F6: 0.99188475
A7: 0003-1-OP1-43 | B7: SUGITY CREATIVES | C7: OP1 | D7: K | E7: 71 | F7: 2.816623
A8: 0003-2-43 | B8: SUGITY CREATIVES | C8: (blank) | D8: G | E8: 10 | F8: 0.2
A9: 0003-2-43 | B9: SUGITY CREATIVES | C9: (blank) | D9: O | E9: 6 | F9: 0.12
A10: 0003-2-OP1-43 | B10: SUGITY CREATIVES | C10: OP1 | D10: P | E10: 36 | F10: 2.450994
A11: 0003-3-IP1-43 | B11: SUGITY CREATIVES | C11: IP1 | D11: I | E11: 83 | F11: 5.4490849
A12: 0003-3-IP1-43 | B12: SUGITY CREATIVES | C12: IP1 | D12: O | E12: 5 | F12: 0.057795875
A13: 0003-3-LP1-43 | B13: SUGITY CREATIVES | C13: LP1 | D13: N | E13: 70 | F13: 4.5976388
A14: 0003-3-MP1-43 | B14: SUGITY CREATIVES | C14: MP1 | D14: M | E14: 144 | F14: 13.480322
A15: 0003-3-OP1-43 | B15: SUGITY CREATIVES | C15: OP1 | D15: P | E15: 349 | F15: 8.0651858
A16: 0003-5-GP1-43 | B16: SUGITY CREATIVES | C16: GP1 | D16: H | E16: 223 | F16: 6.1410274
... A411: 5942-1-OP1-43 | B411: SANKO GOSEI TECH | C411: OP1 | D411: O | E411: 6 | F411: 0.3839904
A412: Grand Total | E412: 31676 | F412: 1859.086

Sheet Data
A3: Dock Code | B3: Supplier Code / Exporter | C3: Supplier Plant Code | D3: Shipping Dock | E3: Gabungan | F3: Part No | G3: Part No 12 | H3: Kanban No | I3: Order Lot Size | J3: Supplier / Exporter Name | K3: Part Name | L3: Address | M3: August | N3: September | O3: 01 Sep | P3: 02 Sep | Q3: 03 Sep | R3: 04 Sep | S3: 05 Sep | T3: 06 Sep | U3: 07 Sep | V3: 08 Sep | W3: 09 Sep | X3: 10 Sep | Y3: 11 Sep | Z3: 12 Sep | AA3: 13 Sep | AB3: 14 Sep | AC3: 15 Sep | AD3: 16 Sep | AE3: 17 Sep | AF3: 18 Sep | AG3: 19 Sep | AH3: 20 Sep | AI3: 21 Sep | AJ3: 22 Sep | AK3: 23 Sep | AL3: 24 Sep | AM3: 25 Sep | AN3: 26 Sep | AO3: 27 Sep | AP3: 28 Sep | AQ3: 29 Sep | AR3: 30 Sep | AS3: 31 Sep | AT3: Max | AU3: Vol/Box Day | AV3: Vol Box | AW3: Vol/m3 Day | AX3: CONVEYANCE | AY3: Address | AZ3: Request S.Dock
A4: 43 | B4: 0003 | C4: 1 | E4: 0003-1-43 | F4: 75601YP030A1 | G4: 75601-YP030-A1 | H4: 212W | I4: 2 | J4: SUGITY CREATIVES | K4: MOULDING SUB-ASSY FR FENDER RH | L4: CH1RH- C49 | M4: 200 | N4: 173 | O4: 9 | P4: 8 | Q4: 8 | R4: 9 | S4: 0 | T4: 0 | U4: 8 | V4: 8 | W4: 8 | X4: 8 | Y4: 9 | Z4: 0 | AA4: 0 | AB4: 9 | AC4: 7 | AD4: 9 | AE4: 8 | AF4: 8 | AG4: 0 | AH4: 0 | AI4: 8 | AJ4: 8 | AK4: 9 | AL4: 8 | AM4: 8 | AN4: 0 | AO4: 0 | AP4: 8 | AQ4: 8 | AR4: 0 | AS4: 0 | AT4: =MAX(O4:AS4) -> 9 | AU4: 4 | AV4: 0.1279365 | AW4: 0.511746 | AX4: D | AY4: CH1RH- C49
A5: 43 | B5: 0003 | C5: 1 | E5: 0003-1-43 | F5: 75602YP030A1 | G5: 75602-YP030-A1 | H5: 213W | I5: 2 | J5: SUGITY CREATIVES | K5: MOULDING SUB-ASSY FR FENDER LH | L5: CH1LH- C13 | M5: 200 | N5: 173 | O5: 9 | P5: 8 | Q5: 8 | R5: 9 | S5: 0 | T5: 0 | U5: 8 | V5: 8 | W5: 8 | X5: 8 | Y5: 9 | Z5: 0 | AA5: 0 | AB5: 9 | AC5: 7 | AD5: 9 | AE5: 8 | AF5: 8 | AG5: 0 | AH5: 0 | AI5: 8 | AJ5: 8 | AK5: 9 | AL5: 8 | AM5: 8 | AN5: 0 | AO5: 0 | AP5: 8 | AQ5: 8 | AR5: 0 | AS5: 0 | AT5: =MAX(O5:AS5) -> 9 | AU5: 4 | AV5: 0.1279365 | AW5: 0.511746 | AX5: D | AY5: CH1LH- C13
A6: 43 | B6: 0003 | C6: 1 | E6: 0003-1-43 | F6: 75605YP030A1 | G6: 75605-YP030-A1 | H6: 214W | I6: 2 | J6: SUGITY CREATIVES | K6: MOULDING SUB-ASSY QUARTER OUTSIDE RH | L6: CH1RH- C49 | M6: 200 | N6: 173 | O6: 9 | P6: 8 | Q6: 8 | R6: 9 | S6: 0 | T6: 0 | U6: 8 | V6: 8 | W6: 8 | X6: 8 | Y6: 9 | Z6: 0 | AA6: 0 | AB6: 9 | AC6: 7 | AD6: 9 | AE6: 8 | AF6: 8 | AG6: 0 | AH6: 0 | AI6: 8 | AJ6: 8 | AK6: 9 | AL6: 8 | AM6: 8 | AN6: 0 | AO6: 0 | AP6: 8 | AQ6: 8 | AR6: 0 | AS6: 0 | AT6: =MAX(O6:AS6) -> 9 | AU6: 4 | AV6: 0.1279365 | AW6: 0.511746 | AX6: D | AY6: CH1RH- C49
A7: 43 | B7: 0003 | C7: 1 | E7: 0003-1-43 | F7: 75606YP030A1 | G7: 75606-YP030-A1 | H7: 215W | I7: 2 | J7: SUGITY CREATIVES | K7: MOULDING SUB-ASSY QUARTER OUTSIDE LH | L7: CH1LH- C13 | M7: 200 | N7: 173 | O7: 9 | P7: 8 | Q7: 8 | R7: 9 | S7: 0 | T7: 0 | U7: 8 | V7: 8 | W7: 8 | X7: 8 | Y7: 9 | Z7: 0 | AA7: 0 | AB7: 9 | AC7: 7 | AD7: 9 | AE7: 8 | AF7: 8 | AG7: 0 | AH7: 0 | AI7: 8 | AJ7: 8 | AK7: 9 | AL7: 8 | AM7: 8 | AN7: 0 | AO7: 0 | AP7: 8 | AQ7: 8 | AR7: 0 | AS7: 0 | AT7: =MAX(O7:AS7) -> 9 | AU7: 4 | AV7: 0.1279365 | AW7: 0.511746 | AX7: D | AY7: CH1LH- C13
A8: 43 | B8: 0003 | C8: 1 | D8: FP1 | E8: 0003-1-FP1-43 | F8: 55317KK010C0 | G8: 55317-KK010-C0 | H8: 398C | I8: 8 | J8: SUGITY CREATIVES | K8: PANEL INSTRUMENT SIDE RH | L8: SF2L -K145 | M8: 480 | N8: 289 | O8: 12 | P8: 12 | Q8: 13 | R8: 13 | S8: 0 | T8: 0 | U8: 13 | V8: 14 | W8: 13 | X8: 14 | Y8: 13 | Z8: 0 | AA8: 0 | AB8: 13 | AC8: 14 | AD8: 13 | AE8: 13 | AF8: 13 | AG8: 0 | AH8: 0 | AI8: 12 | AJ8: 14 | AK8: 13 | AL8: 14 | AM8: 14 | AN8: 0 | AO8: 0 | AP8: 13 | AQ8: 13 | AR8: 13 | AS8: 0 | AT8: =MAX(O8:AS8) -> 14 | AU8: 2 | AV8: 0.032989125 | AW8: 0.06597825 | AX8: N | AY8: SF2L -K145
A9: 43 | B9: 0003 | C9: 1 | D9: FP1 | E9: 0003-1-FP1-43 | F9: 55318KK080C0 | G9: 55318-KK080-C0 | H9: 401C | I9: 8 | J9: SUGITY CREATIVES | K9: PANEL INSTRUMENT SIDE LH | L9: SF2L -K145 | M9: 480 | N9: 289 | O9: 12 | P9: 12 | Q9: 13 | R9: 13 | S9: 0 | T9: 0 | U9: 13 | V9: 14 | W9: 13 | X9: 14 | Y9: 13 | Z9: 0 | AA9: 0 | AB9: 13 | AC9: 14 | AD9: 13 | AE9: 13 | AF9: 13 | AG9: 0 | AH9: 0 | AI9: 12 | AJ9: 14 | AK9: 13 | AL9: 14 | AM9: 14 | AN9: 0 | AO9: 0 | AP9: 13 | AQ9: 13 | AR9: 13 | AS9: 0 | AT9: =MAX(O9:AS9) -> 14 | AU9: 2 | AV9: 0.065651625 | AW9: 0.13130325 | AX9: N | AY9: SF2L -K145
A10: 43 | B10: 0003 | C10: 1 | D10: FP1 | E10: 0003-1-FP1-43 | F10: 55434KK020C0 | G10: 55434-KK020-C0 | H10: 413C | I10: 6 | J10: SUGITY CREATIVES | K10: PANEL INSTRUMENT PANEL FINISH LWR CTR | L10: FNL3 - K36 | M10: 480 | N10: 289 | O10: 12 | P10: 12 | Q10: 13 | R10: 13 | S10: 0 | T10: 0 | U10: 13 | V10: 14 | W10: 13 | X10: 14 | Y10: 13 | Z10: 0 | AA10: 0 | AB10: 13 | AC10: 14 | AD10: 13 | AE10: 13 | AF10: 13 | AG10: 0 | AH10: 0 | AI10: 12 | AJ10: 14 | AK10: 13 | AL10: 14 | AM10: 14 | AN10: 0 | AO10: 0 | AP10: 13 | AQ10: 13 | AR10: 13 | AS10: 0 | AT10: =MAX(O10:AS10) -> 14 | AU10: 3 | AV10: 0.04376775 | AW10: 0.13130325 | AX10: N | AY10: FNL3 - K36
A11: 43 | B11: 0003 | C11: 1 | D11: FP1 | E11: 0003-1-FP1-43 | F11: 55447KK010C0 | G11: 55447-KK010-C0 | H11: 387H | I11: 12 | J11: SUGITY CREATIVES | K11: BASE SWITCH HOLE NO.2 | L11: SPT2R- Y4 | M11: 139 | N11: 205 | O11: 6 | P11: 7 | Q11: 8 | R11: 5 | S11: 0 | T11: 0 | U11: 6 | V11: 9 | W11: 5 | X11: 8 | Y11: 5 | Z11: 0 | AA11: 0 | AB11: 10 | AC11: 6 | AD11: 13 | AE11: 5 | AF11: 8 | AG11: 0 | AH11: 0 | AI11: 6 | AJ11: 7 | AK11: 9 | AL11: 16 | AM11: 17 | AN11: 0 | AO11: 0 | AP11: 18 | AQ11: 17 | AR11: 14 | AS11: 0 | AT11: =MAX(O11:AS11) -> 18 | AU11: 1 | AV11: 0.021883875 | AW11: 0.021883875 | AX11: N | AY11: SPT2R- Y4
A12: 43 | B12: 0003 | C12: 1 | D12: FP1 | E12: 0003-1-FP1-43 | F12: 55447KK020C0 | G12: 55447-KK020-C0 | H12: 388H | I12: 12 | J12: SUGITY CREATIVES | K12: BASE SWITCH HOLE NO.2 | L12: SPT2R- Y4 | M12: 3264 | N12: 1913 | O12: 87 | P12: 84 | Q12: 84 | R12: 88 | S12: 0 | T12: 0 | U12: 95 | V12: 84 | W12: 89 | X12: 93 | Y12: 93 | Z12: 0 | AA12: 0 | AB12: 92 | AC12: 90 | AD12: 77 | AE12: 96 | AF12: 94 | AG12: 0 | AH12: 0 | AI12: 91 | AJ12: 93 | AK12: 78 | AL12: 88 | AM12: 80 | AN12: 0 | AO12: 0 | AP12: 77 | AQ12: 81 | AR12: 79 | AS12: 0 | AT12: =MAX(O12:AS12) -> 96 | AU12: 8 | AV12: 0.021883875 | AW12: 0.175071 | AX12: N | AY12: SPT2R- Y4
A13: 43 | B13: 0003 | C13: 1 | D13: FP1 | E13: 0003-1-FP1-43 | F13: 55447KK030C0 | G13: 55447-KK030-C0 | H13: 389H | I13: 12 | J13: SUGITY CREATIVES | K13: BASE SWITCH HOLE NO.2 | L13: SPT2R- Y4 | M13: 1246 | N13: 1033 | O13: 40 | P13: 45 | Q13: 46 | R13: 55 | S13: 0 | T13: 0 | U13: 44 | V13: 55 | W13: 44 | X13: 47 | Y13: 50 | Z13: 0 | AA13: 0 | AB13: 43 | AC13: 52 | AD13: 48 | AE13: 47 | AF13: 46 | AG13: 0 | AH13: 0 | AI13: 48 | AJ13: 48 | AK13: 51 | AL13: 44 | AM13: 52 | AN13: 0 | AO13: 0 | AP13: 42 | AQ13: 41 | AR13: 45 | AS13: 0 | AT13: =MAX(O13:AS13) -> 55 | AU13: 4 | AV13: 0.021883875 | AW13: 0.0875355 | AX13: N | AY13: SPT2R- Y4
A14: 43 | B14: 0003 | C14: 1 | D14: FP1 | E14: 0003-1-FP1-43 | F14: 55471010KBE0 | G14: 55471-010KB-E0 | H14: 952F | I14: 6 | J14: SUGITY CREATIVES | K14: ORNAMENT INSTR CLUSTER FINISH PANEL | L14: FNL2 -K113 | M14: 480 | N14: 289 | O14: 12 | P14: 12 | Q14: 13 | R14: 13 | S14: 0 | T14: 0 | U14: 13 | V14: 14 | W14: 13 | X14: 14 | Y14: 13 | Z14: 0 | AA14: 0 | AB14: 13 | AC14: 14 | AD14: 13 | AE14: 13 | AF14: 13 | AG14: 0 | AH14: 0 | AI14: 12 | AJ14: 14 | AK14: 13 | AL14: 14 | AM14: 14 | AN14: 0 | AO14: 0 | AP14: 13 | AQ14: 13 | AR14: 13 | AS14: 0 | AT14: =MAX(O14:AS14) -> 14 | AU14: 3 | AV14: 0.04376775 | AW14: 0.13130325 | AX14: N | AY14: FNL2 -K113
A15: 43 | B15: 0003 | C15: 1 | D15: FP1 | E15: 0003-1-FP1-43 | F15: 55474010KBE0 | G15: 55474-010KB-E0 | H15: 954F | I15: 5 | J15: SUGITY CREATIVES | K15: GARNISH INSTR CSTR FINISH PANEL NO.1 | L15: FNL2 -K111 | M15: 480 | N15: 289 | O15: 12 | P15: 12 | Q15: 13 | R15: 13 | S15: 0 | T15: 0 | U15: 13 | V15: 14 | W15: 13 | X15: 14 | Y15: 13 | Z15: 0 | AA15: 0 | AB15: 13 | AC15: 14 | AD15: 13 | AE15: 13 | AF15: 13 | AG15: 0 | AH15: 0 | AI15: 12 | AJ15: 14 | AK15: 13 | AL15: 14 | AM15: 14 | AN15: 0 | AO15: 0 | AP15: 13 | AQ15: 13 | AR15: 13 | AS15: 0 | AT15: =MAX(O15:AS15) -> 14 | AU15: 3 | AV15: 0.065651625 | AW15: 0.19695488 | AX15: N | AY15: FNL2 -K111
A16: 43 | B16: 0003 | C16: 1 | D16: FP1 | E16: 0003-1-FP1-43 | F16: 55475010KBE0 | G16: 55475-010KB-E0 | H16: 953F | I16: 9 | J16: SUGITY CREATIVES | K16: GARNISH INSTR CSTR FINISH PANEL NO.2 | L16: FNL2 -K111 | M16: 480 | N16: 289 | O16: 12 | P16: 12 | Q16: 13 | R16: 13 | S16: 0 | T16: 0 | U16: 13 | V16: 14 | W16: 13 | X16: 14 | Y16: 13 | Z16: 0 | AA16: 0 | AB16: 13 | AC16: 14 | AD16: 13 | AE16: 13 | AF16: 13 | AG16: 0 | AH16: 0 | AI16: 12 | AJ16: 14 | AK16: 13 | AL16: 14 | AM16: 14 | AN16: 0 | AO16: 0 | AP16: 13 | AQ16: 13 | AR16: 13 | AS16: 0 | AT16: =MAX(O16:AS16) -> 14 | AU16: 2 | AV16: 0.02527575 | AW16: 0.0505515 | AX16: N | AY16: FNL2 -K111
A17: 43 | B17: 0003 | C17: 1 | D17: OP1 | E17: 0003-1-OP1-43 | F17: 55407KK24000 | G17: 55407-KK240-00 | H17: 348W | I17: 4 | J17: SUGITY CREATIVES | K17: BASE SUB-ASSY SWITCH HOLE | L17: SIP1L- I84 | M17: 81 | N17: 165 | O17: 4 | P17: 6 | Q17: 6 | R17: 4 | S17: 0 | T17: 0 | U17: 4 | V17: 8 | W17: 3 | X17: 7 | Y17: 3 | Z17: 0 | AA17: 0 | AB17: 8 | AC17: 4 | AD17: 7 | AE17: 4 | AF17: 6 | AG17: 0 | AH17: 0 | AI17: 5 | AJ17: 6 | AK17: 7 | AL17: 14 | AM17: 16 | AN17: 0 | AO17: 0 | AP17: 13 | AQ17: 16 | AR17: 14 | AS17: 0 | AT17: =MAX(O17:AS17) -> 16 | AU17: 2 | AV17: 0.04376775 | AW17: 0.0875355 | AX17: K | AY17: SIP1L- I84
A18: 43 | B18: 0003 | C18: 1 | D18: OP1 | E18: 0003-1-OP1-43 | F18: 55407KK25000 | G18: 55407-KK250-00 | H18: 349W | I18: 4 | J18: SUGITY CREATIVES | K18: BASE SUB-ASSY SWITCH HOLE | L18: SIP1L- I84 | M18: 58 | N18: 40 | O18: 2 | P18: 1 | Q18: 2 | R18: 1 | S18: 0 | T18: 0 | U18: 2 | V18: 1 | W18: 2 | X18: 1 | Y18: 2 | Z18: 0 | AA18: 0 | AB18: 2 | AC18: 2 | AD18: 6 | AE18: 1 | AF18: 2 | AG18: 0 | AH18: 0 | AI18: 1 | AJ18: 1 | AK18: 2 | AL18: 2 | AM18: 1 | AN18: 0 | AO18: 0 | AP18: 5 | AQ18: 1 | AR18: 0 | AS18: 0 | AT18: =MAX(O18:AS18) -> 6 | AU18: 1 | AV18: 0.04376775 | AW18: 0.04376775 | AX18: K | AY18: SIP1L- I84
A19: 43 | B19: 0003 | C19: 1 | D19: OP1 | E19: 0003-1-OP1-43 | F19: 55407KK27000 | G19: 55407-KK270-00 | H19: 350W | I19: 4 | J19: SUGITY CREATIVES | K19: BASE SUB-ASSY SWITCH HOLE | L19: SIP1L- I84 | M19: 1020 | N19: 1551 | O19: 68 | P19: 68 | Q19: 70 | R19: 76 | S19: 0 | T19: 0 | U19: 75 | V19: 73 | W19: 72 | X19: 74 | Y19: 77 | Z19: 0 | AA19: 0 | AB19: 71 | AC19: 77 | AD19: 68 | AE19: 76 | AF19: 75 | AG19: 0 | AH19: 0 | AI19: 74 | AJ19: 75 | AK19: 68 | AL19: 66 | AM19: 66 | AN19: 0 | AO19: 0 | AP19: 61 | AQ19: 60 | AR19: 61 | AS19: 0 | AT19: =MAX(O19:AS19) -> 77 | AU19: 19 | AV19: 0.04376775 | AW19: 0.83158725 | AX19: K | AY19: SIP1L- I84
... A24: 43 | B24: 0003 | C24: 1 | D24: OP1 | E24: 0003-1-OP1-43 | F24: 757240K10100 | G24: 75724-0K101-00 | H24: 519W | I24: 10 | J24: SUGITY CREATIVES | K24: MOULDING RR DOOR BELT RR LH | L24: SPDR - D17 | M24: 3722 | N24: 2382 | O24: 103 | P24: 106 | Q24: 99 | R24: 110 | S24: 0 | T24: 0 | U24: 114 | V24: 105 | W24: 107 | X24: 115 | Y24: 110 | Z24: 0 | AA24: 0 | AB24: 113 | AC24: 111 | AD24: 93 | AE24: 116 | AF24: 114 | AG24: 0 | AH24: 0 | AI24: 112 | AJ24: 112 | AK24: 99 | AL24: 114 | AM24: 111 | AN24: 0 | AO24: 0 | AP24: 101 | AQ24: 108 | AR24: 109 | AS24: 0 | AT24: =MAX(O24:AS24) -> 116 | AU24: 12 | AV24: 0.034677525 | AW24: 0.4161303 | AX24: K | AY24: SPDR - D17
A25: 43 | B25: 0003 | C25: 2 | E25: 0003-2-43 | F25: 678730K07100 | G25: 67873-0K071-00 | H25: 450G | I25: 30 | J25: SUGITY CREATIVES | K25: WEATHERSTRIP CTR DOOR UPR NO.1 | L25: FNL4L- H25 | M25: 4649 | N25: 3151 | O25: 133 | P25: 136 | Q25: 138 | R25: 148 | S25: 0 | T25: 0 | U25: 145 | V25: 148 | W25: 138 | X25: 148 | Y25: 148 | Z25: 0 | AA25: 0 | AB25: 145 | AC25: 148 | AD25: 138 | AE25: 148 | AF25: 148 | AG25: 0 | AH25: 0 | AI25: 145 | AJ25: 148 | AK25: 138 | AL25: 148 | AM25: 149 | AN25: 0 | AO25: 0 | AP25: 137 | AQ25: 139 | AR25: 138 | AS25: 0 | AT25: =MAX(O25:AS25) -> 149 | AU25: 5 | AV25: 0.02 | AW25: 0.1 | AX25: G | AY25: FNL4L- H25
A26: 43 | B26: 0003 | C26: 2 | E26: 0003-2-43 | F26: 678740K07100 | G26: 67874-0K071-00 | H26: 451G | I26: 30 | J26: SUGITY CREATIVES | K26: WEATHERSTRIP CTR DOOR UPR NO.2 | L26: FNL4L- H25 | M26: 4649 | N26: 3151 | O26: 133 | P26: 136 | Q26: 138 | R26: 148 | S26: 0 | T26: 0 | U26: 145 | V26: 148 | W26: 138 | X26: 148 | Y26: 148 | Z26: 0 | AA26: 0 | AB26: 145 | AC26: 148 | AD26: 138 | AE26: 148 | AF26: 148 | AG26: 0 | AH26: 0 | AI26: 145 | AJ26: 148 | AK26: 138 | AL26: 148 | AM26: 149 | AN26: 0 | AO26: 0 | AP26: 137 | AQ26: 139 | AR26: 138 | AS26: 0 | AT26: =MAX(O26:AS26) -> 149 | AU26: 5 | AV26: 0.02 | AW26: 0.1 | AX26: G | AY26: FNL4L- H25
A27: 43 | B27: 0003 | C27: 2 | E27: 0003-2-43 | F27: 755510K21000 | G27: 75551-0K210-00 | H27: 221J | I27: 40 | J27: SUGITY CREATIVES | K27: MOULDING ROOF DRIP SIDE FINISH FR RH | L27: PLT - N41 | M27: 3792 | N27: 2012 | O27: 80 | P27: 86 | Q27: 88 | R27: 90 | S27: 0 | T27: 0 | U27: 91 | V27: 92 | W27: 85 | X27: 92 | Y27: 93 | Z27: 0 | AA27: 0 | AB27: 90 | AC27: 94 | AD27: 84 | AE27: 92 | AF27: 95 | AG27: 0 | AH27: 0 | AI27: 89 | AJ27: 92 | AK27: 88 | AL27: 100 | AM27: 102 | AN27: 0 | AO27: 0 | AP27: 93 | AQ27: 94 | AR27: 102 | AS27: 0 | AT27: =MAX(O27:AS27) -> 102 | AU27: 3 | AV27: 0.02 | AW27: 0.06 | AX27: O | AY27: PLT - N41
A28: 43 | B28: 0003 | C28: 2 | E28: 0003-2-43 | F28: 755520K21000 | G28: 75552-0K210-00 | H28: 223J | I28: 40 | J28: SUGITY CREATIVES | K28: MOULDING ROOF DRIP SIDE FINISH FR LH | L28: PLT - N41 | M28: 3792 | N28: 2012 | O28: 80 | P28: 86 | Q28: 88 | R28: 90 | S28: 0 | T28: 0 | U28: 91 | V28: 92 | W28: 85 | X28: 92 | Y28: 93 | Z28: 0 | AA28: 0 | AB28: 90 | AC28: 94 | AD28: 84 | AE28: 92 | AF28: 95 | AG28: 0 | AH28: 0 | AI28: 89 | AJ28: 92 | AK28: 88 | AL28: 100 | AM28: 102 | AN28: 0 | AO28: 0 | AP28: 93 | AQ28: 94 | AR28: 102 | AS28: 0 | AT28: =MAX(O28:AS28) -> 102 | AU28: 3 | AV28: 0.02 | AW28: 0.06 | AX28: O | AY28: PLT - N41
A29: 43 | B29: 0003 | C29: 2 | D29: OP1 | E29: 0003-2-OP1-43 | F29: 681600K10000 | G29: 68160-0K100-00 | H29: 510H | I29: 20 | J29: SUGITY CREATIVES | K29: WEATHERSTRIP ASSY FR DOOR GLASS OUT RH | L29: SPDR - D18 | M29: 927 | N29: 769 | O29: 30 | P29: 30 | Q29: 39 | R29: 38 | S29: 0 | T29: 0 | U29: 31 | V29: 43 | W29: 31 | X29: 33 | Y29: 38 | Z29: 0 | AA29: 0 | AB29: 32 | AC29: 37 | AD29: 45 | AE29: 32 | AF29: 34 | AG29: 0 | AH29: 0 | AI29: 33 | AJ29: 36 | AK29: 39 | AL29: 34 | AM29: 38 | AN29: 0 | AO29: 0 | AP29: 36 | AQ29: 31 | AR29: 29 | AS29: 0 | AT29: =MAX(O29:AS29) -> 45 | AU29: 2 | AV29: 0.065651625 | AW29: 0.13130325 | AX29: P | AY29: SPDR - D18
A30: 43 | B30: 0003 | C30: 2 | D30: OP1 | E30: 0003-2-OP1-43 | F30: 681600K12000 | G30: 68160-0K120-00 | H30: 511H | I30: 20 | J30: SUGITY CREATIVES | K30: WEATHERSTRIP ASSY FR DOOR GLASS OUT RH | L30: SPDR - D17 | M30: 3722 | N30: 2382 | O30: 103 | P30: 106 | Q30: 99 | R30: 110 | S30: 0 | T30: 0 | U30: 114 | V30: 105 | W30: 107 | X30: 115 | Y30: 110 | Z30: 0 | AA30: 0 | AB30: 113 | AC30: 111 | AD30: 93 | AE30: 116 | AF30: 114 | AG30: 0 | AH30: 0 | AI30: 112 | AJ30: 112 | AK30: 99 | AL30: 114 | AM30: 111 | AN30: 0 | AO30: 0 | AP30: 101 | AQ30: 108 | AR30: 109 | AS30: 0 | AT30: =MAX(O30:AS30) -> 116 | AU30: 6 | AV30: 0.065651625 | AW30: 0.39390975 | AX30: P | AY30: SPDR - D17
A31: 43 | B31: 0003 | C31: 2 | D31: OP1 | E31: 0003-2-OP1-43 | F31: 681800K10000 | G31: 68180-0K100-00 | H31: 512H | I31: 20 | J31: SUGITY CREATIVES | K31: WEATHERSTRIP ASSY RR DOOR GLASS OUT RH | L31: SPDR - D18 | M31: 927 | N31: 769 | O31: 30 | P31: 30 | Q31: 39 | R31: 38 | S31: 0 | T31: 0 | U31: 31 | V31: 43 | W31: 31 | X31: 33 | Y31: 38 | Z31: 0 | AA31: 0 | AB31: 32 | AC31: 37 | AD31: 45 | AE31: 32 | AF31: 34 | AG31: 0 | AH31: 0 | AI31: 33 | AJ31: 36 | AK31: 39 | AL31: 34 | AM31: 38 | AN31: 0 | AO31: 0 | AP31: 36 | AQ31: 31 | AR31: 29 | AS31: 0 | AT31: =MAX(O31:AS31) -> 45 | AU31: 2 | AV31: 0.065651625 | AW31: 0.13130325 | AX31: P | AY31: SPDR - D18
A32: 43 | B32: 0003 | C32: 2 | D32: OP1 | E32: 0003-2-OP1-43 | F32: 681800K15000 | G32: 68180-0K150-00 | H32: 513H | I32: 20 | J32: SUGITY CREATIVES | K32: WEATHERSTRIP ASSY RR DOOR GLASS OUT RH | L32: SPDR - D17 | M32: 3722 | N32: 2382 | O32: 103 | P32: 106 | Q32: 99 | R32: 110 | S32: 0 | T32: 0 | U32: 114 | V32: 105 | W32: 107 | X32: 115 | Y32: 110 | Z32: 0 | AA32: 0 | AB32: 113 | AC32: 111 | AD32: 93 | AE32: 116 | AF32: 114 | AG32: 0 | AH32: 0 | AI32: 112 | AJ32: 112 | AK32: 99 | AL32: 114 | AM32: 111 | AN32: 0 | AO32: 0 | AP32: 101 | AQ32: 108 | AR32: 109 | AS32: 0 | AT32: =MAX(O32:AS32) -> 116 | AU32: 6 | AV32: 0.065651625 | AW32: 0.39390975 | AX32: P | AY32: SPDR - D17
A33: 43 | B33: 0003 | C33: 2 | D33: OP1 | E33: 0003-2-OP1-43 | F33: 682100K10000 | G33: 68210-0K100-00 | H33: 516H | I33: 20 | J33: SUGITY CREATIVES | K33: WEATHERSTRIP ASSY FR DOOR GLASS OUT LH | L33: SPDR - D18 | M33: 927 | N33: 769 | O33: 30 | P33: 30 | Q33: 39 | R33: 38 | S33: 0 | T33: 0 | U33: 31 | V33: 43 | W33: 31 | X33: 33 | Y33: 38 | Z33: 0 | AA33: 0 | AB33: 32 | AC33: 37 | AD33: 45 | AE33: 32 | AF33: 34 | AG33: 0 | AH33: 0 | AI33: 33 | AJ33: 36 | AK33: 39 | AL33: 34 | AM33: 38 | AN33: 0 | AO33: 0 | AP33: 36 | AQ33: 31 | AR33: 29 | AS33: 0 | AT33: =MAX(O33:AS33) -> 45 | AU33: 2 | AV33: 0.065651625 | AW33: 0.13130325 | AX33: P | AY33: SPDR - D18
A34: 43 | B34: 0003 | C34: 2 | D34: OP1 | E34: 0003-2-OP1-43 | F34: 682100K12000 | G34: 68210-0K120-00 | H34: 517H | I34: 20 | J34: SUGITY CREATIVES | K34: WEATHERSTRIP ASSY FR DOOR GLASS OUT LH | L34: SPDR - D17 | M34: 3722 | N34: 2382 | O34: 103 | P34: 106 | Q34: 99 | R34: 110 | S34: 0 | T34: 0 | U34: 114 | V34: 105 | W34: 107 | X34: 115 | Y34: 110 | Z34: 0 | AA34: 0 | AB34: 113 | AC34: 111 | AD34: 93 | AE34: 116 | AF34: 114 | AG34: 0 | AH34: 0 | AI34: 112 | AJ34: 112 | AK34: 99 | AL34: 114 | AM34: 111 | AN34: 0 | AO34: 0 | AP34: 101 | AQ34: 108 | AR34: 109 | AS34: 0 | AT34: =MAX(O34:AS34) -> 116 | AU34: 6 | AV34: 0.065651625 | AW34: 0.39390975 | AX34: P | AY34: SPDR - D17
A35: 43 | B35: 0003 | C35: 2 | D35: OP1 | E35: 0003-2-OP1-43 | F35: 682300K10000 | G35: 68230-0K100-00 | H35: 518H | I35: 20 | J35: SUGITY CREATIVES | K35: WEATHERSTRIP ASSY RR DOOR GLASS OUT LH | L35: SPDR - D18 | M35: 927 | N35: 769 | O35: 30 | P35: 30 | Q35: 39 | R35: 38 | S35: 0 | T35: 0 | U35: 31 | V35: 43 | W35: 31 | X35: 33 | Y35: 38 | Z35: 0 | AA35: 0 | AB35: 32 | AC35: 37 | AD35: 45 | AE35: 32 | AF35: 34 | AG35: 0 | AH35: 0 | AI35: 33 | AJ35: 36 | AK35: 39 | AL35: 34 | AM35: 38 | AN35: 0 | AO35: 0 | AP35: 36 | AQ35: 31 | AR35: 29 | AS35: 0 | AT35: =MAX(O35:AS35) -> 45 | AU35: 2 | AV35: 0.065651625 | AW35: 0.13130325 | AX35: P | AY35: SPDR - D18
A36: 43 | B36: 0003 | C36: 2 | D36: OP1 | E36: 0003-2-OP1-43 | F36: 682300K15000 | G36: 68230-0K150-00 | H36: 519H | I36: 20 | J36: SUGITY CREATIVES | K36: WEATHERSTRIP ASSY RR DOOR GLASS OUT LH | L36: SPDR - D17 | M36: 3722 | N36: 2382 | O36: 103 | P36: 106 | Q36: 99 | R36: 110 | S36: 0 | T36: 0 | U36: 114 | V36: 105 | W36: 107 | X36: 115 | Y36: 110 | Z36: 0 | AA36: 0 | AB36: 113 | AC36: 111 | AD36: 93 | AE36: 116 | AF36: 114 | AG36: 0 | AH36: 0 | AI36: 112 | AJ36: 112 | AK36: 99 | AL36: 114 | AM36: 111 | AN36: 0 | AO36: 0 | AP36: 101 | AQ36: 108 | AR36: 109 | AS36: 0 | AT36: =MAX(O36:AS36) -> 116 | AU36: 6 | AV36: 0.065651625 | AW36: 0.39390975 | AX36: P | AY36: SPDR - D17
A37: 43 | B37: 0003 | C37: 2 | D37: OP1 | E37: 0003-2-OP1-43 | F37: 757100K03000 | G37: 75710-0K030-00 | H37: 699C | I37: 20 | J37: SUGITY CREATIVES | K37: MOULDING ASSY FR DOOR BELT RH | L37: SPDR - D20 | M37: 480 | N37: 289 | O37: 12 | P37: 12 | Q37: 13 | R37: 13 | S37: 0 | T37: 0 | U37: 13 | V37: 14 | W37: 13 | X37: 14 | Y37: 13 | Z37: 0 | AA37: 0 | AB37: 13 | AC37: 14 | AD37: 13 | AE37: 13 | AF37: 13 | AG37: 0 | AH37: 0 | AI37: 12 | AJ37: 14 | AK37: 13 | AL37: 14 | AM37: 14 | AN37: 0 | AO37: 0 | AP37: 13 | AQ37: 13 | AR37: 13 | AS37: 0 | AT37: =MAX(O37:AS37) -> 14 | AU37: 1 | AV37: 0.0875355 | AW37: 0.0875355 | AX37: P | AY37: SPDR - D20
A38: 43 | B38: 0003 | C38: 2 | D38: OP1 | E38: 0003-2-OP1-43 | F38: 757200K03000 | G38: 75720-0K030-00 | H38: 701C | I38: 20 | J38: SUGITY CREATIVES | K38: MOULDING ASSY FR DOOR BELT LH | L38: SPDR - D20 | M38: 480 | N38: 289 | O38: 12 | P38: 12 | Q38: 13 | R38: 13 | S38: 0 | T38: 0 | U38: 13 | V38: 14 | W38: 13 | X38: 14 | Y38: 13 | Z38: 0 | AA38: 0 | AB38: 13 | AC38: 14 | AD38: 13 | AE38: 13 | AF38: 13 | AG38: 0 | AH38: 0 | AI38: 12 | AJ38: 14 | AK38: 13 | AL38: 14 | AM38: 14 | AN38: 0 | AO38: 0 | AP38: 13 | AQ38: 13 | AR38: 13 | AS38: 0 | AT38: =MAX(O38:AS38) -> 14 | AU38: 1 | AV38: 0.0875355 | AW38: 0.0875355 | AX38: P | AY38: SPDR - D20
A39: 43 | B39: 0003 | C39: 2 | D39: OP1 | E39: 0003-2-OP1-43 | F39: 757300K03000 | G39: 75730-0K030-00 | H39: 703C | I39: 20 | J39: SUGITY CREATIVES | K39: MOULDING ASSY RR DOOR BELT RH | L39: SPDR - D20 | M39: 480 | N39: 289 | O39: 12 | P39: 12 | Q39: 13 | R39: 13 | S39: 0 | T39: 0 | U39: 13 | V39: 14 | W39: 13 | X39: 14 | Y39: 13 | Z39: 0 | AA39: 0 | AB39: 13 | AC39: 14 | AD39: 13 | AE39: 13 | AF39: 13 | AG39: 0 | AH39: 0 | AI39: 12 | AJ39: 14 | AK39: 13 | AL39: 14 | AM39: 14 | AN39: 0 | AO39: 0 | AP39: 13 | AQ39: 13 | AR39: 13 | AS39: 0 | AT39: =MAX(O39:AS39) -> 14 | AU39: 1 | AV39: 0.0875355 | AW39: 0.0875355 | AX39: P | AY39: SPDR - D20
A40: 43 | B40: 0003 | C40: 2 | D40: OP1 | E40: 0003-2-OP1-43 | F40: 757400K03000 | G40: 75740-0K030-00 | H40: 705C | I40: 20 | J40: SUGITY CREATIVES | K40: MOULDING ASSY RR DOOR BELT LH | L40: SPDR - D20 | M40: 480 | N40: 289 | O40: 12 | P40: 12 | Q40: 13 | R40: 13 | S40: 0 | T40: 0 | U40: 13 | V40: 14 | W40: 13 | X40: 14 | Y40: 13 | Z40: 0 | AA40: 0 | AB40: 13 | AC40: 14 | AD40: 13 | AE40: 13 | AF40: 13 | AG40: 0 | AH40: 0 | AI40: 12 | AJ40: 14 | AK40: 13 | AL40: 14 | AM40: 14 | AN40: 0 | AO40: 0 | AP40: 13 | AQ40: 13 | AR40: 13 | AS40: 0 | AT40: =MAX(O40:AS40) -> 14 | AU40: 1 | AV40: 0.0875355 | AW40: 0.0875355 | AX40: P | AY40: SPDR - D20
... A74: 43 | B74: 0003 | C74: 3 | D74: OP1 | E74: 0003-3-OP1-43 | F74: 742320KA4000 | G74: 74232-0KA40-00 | H74: 592H | I74: 6 | J74: SUGITY CREATIVES | K74: PANEL FR DOOR ARMREST BASE UPR LH | L74: SPDL - D48 | M74: 2382 | N74: 1648 | O74: 75 | P74: 71 | Q74: 73 | R74: 80 | S74: 0 | T74: 0 | U74: 80 | V74: 76 | W74: 76 | X74: 80 | Y74: 80 | Z74: 0 | AA74: 0 | AB74: 79 | AC74: 77 | AD74: 68 | AE74: 83 | AF74: 80 | AG74: 0 | AH74: 0 | AI74: 78 | AJ74: 80 | AK74: 71 | AL74: 71 | AM74: 72 | AN74: 0 | AO74: 0 | AP74: 64 | AQ74: 67 | AR74: 67 | AS74: 0 | AT74: =MAX(O74:AS74) -> 83 | AU74: 14 | AV74: 0.02311835 | AW74: 0.3236569 | AX74: P | AY74: SPDL - D48
A75: 43 | B75: 0003 | C75: 3 | D75: OP1 | E75: 0003-3-OP1-43 | F75: 74232VT01000 | G75: 74232-VT010-00 | H75: 667E | I75: 8 | J75: SUGITY CREATIVES | K75: PANEL FR DOOR ARMREST BASE UPR LH | L75: SPDL - D50 | M75: 97 | N75: 79 | O75: 4 | P75: 2 | Q75: 5 | R75: 2 | S75: 0 | T75: 0 | U75: 4 | V75: 4 | W75: 3 | X75: 3 | Y75: 3 | Z75: 0 | AA75: 0 | AB75: 4 | AC75: 5 | AD75: 5 | AE75: 4 | AF75: 3 | AG75: 0 | AH75: 0 | AI75: 3 | AJ75: 4 | AK75: 4 | AL75: 4 | AM75: 2 | AN75: 0 | AO75: 0 | AP75: 4 | AQ75: 3 | AR75: 4 | AS75: 0 | AT75: =MAX(O75:AS75) -> 5 | AU75: 1 | AV75: 0.02 | AW75: 0.02 | AX75: P | AY75: SPDL - D50
A76: 43 | B76: 0003 | C76: 3 | D76: OP1 | E76: 0003-3-OP1-43 | F76: 74232VT02000 | G76: 74232-VT020-00 | H76: 668E | I76: 8 | J76: SUGITY CREATIVES | K76: PANEL FR DOOR ARMREST BASE UPR LH | L76: SPDL - D50 | M76: 2569 | N76: 2867 | O76: 121 | P76: 123 | Q76: 124 | R76: 137 | S76: 0 | T76: 0 | U76: 132 | V76: 133 | W76: 126 | X76: 135 | Y76: 137 | Z76: 0 | AA76: 0 | AB76: 130 | AC76: 136 | AD76: 124 | AE76: 133 | AF76: 137 | AG76: 0 | AH76: 0 | AI76: 133 | AJ76: 134 | AK76: 124 | AL76: 135 | AM76: 137 | AN76: 0 | AO76: 0 | AP76: 123 | AQ76: 126 | AR76: 127 | AS76: 0 | AT76: =MAX(O76:AS76) -> 137 | AU76: 17 | AV76: 0.02311835 | AW76: 0.39301195 | AX76: P | AY76: SPDL - D50
A77: 43 | B77: 0003 | C77: 3 | D77: OP1 | E77: 0003-3-OP1-43 | F77: 74232VT03000 | G77: 74232-VT030-00 | H77: 669E | I77: 8 | J77: SUGITY CREATIVES | K77: PANEL FR DOOR ARMREST BASE UPR LH | L77: SPDL - D50 | M77: 3195 | N77: 3503 | O77: 146 | P77: 152 | Q77: 154 | R77: 164 | S77: 0 | T77: 0 | U77: 160 | V77: 166 | W77: 154 | X77: 165 | Y77: 163 | Z77: 0 | AA77: 0 | AB77: 162 | AC77: 162 | AD77: 154 | AE77: 166 | AF77: 163 | AG77: 0 | AH77: 0 | AI77: 161 | AJ77: 166 | AK77: 156 | AL77: 165 | AM77: 165 | AN77: 0 | AO77: 0 | AP77: 150 | AQ77: 155 | AR77: 154 | AS77: 0 | AT77: =MAX(O77:AS77) -> 166 | AU77: 21 | AV77: 0.02311835 | AW77: 0.48548535 | AX77: P | AY77: SPDL - D50
A78: 43 | B78: 0003 | C78: 3 | D78: OP1 | E78: 0003-3-OP1-43 | F78: 742710K27000 | G78: 74271-0K270-00 | H78: 670C | I78: 6 | J78: SUGITY CREATIVES | K78: PANEL RR DOOR ARMREST BASE UPR RH | L78: SPDL - D49 | M78: 480 | N78: 289 | O78: 12 | P78: 12 | Q78: 13 | R78: 13 | S78: 0 | T78: 0 | U78: 13 | V78: 14 | W78: 13 | X78: 14 | Y78: 13 | Z78: 0 | AA78: 0 | AB78: 13 | AC78: 14 | AD78: 13 | AE78: 13 | AF78: 13 | AG78: 0 | AH78: 0 | AI78: 12 | AJ78: 14 | AK78: 13 | AL78: 14 | AM78: 14 | AN78: 0 | AO78: 0 | AP78: 13 | AQ78: 13 | AR78: 13 | AS78: 0 | AT78: =MAX(O78:AS78) -> 14 | AU78: 3 | AV78: 0.02311835 | AW78: 0.06935505 | AX78: P | AY78: SPDL - D49
A79: 43 | B79: 0003 | C79: 3 | D79: OP1 | E79: 0003-3-OP1-43 | F79: 742710K34000 | G79: 74271-0K340-00 | H79: 605H | I79: 6 | J79: SUGITY CREATIVES | K79: PANEL RR DOOR ARMREST BASE UPR RH | L79: SPDL - D48 | M79: 2382 | N79: 1648 | O79: 75 | P79: 71 | Q79: 73 | R79: 80 | S79: 0 | T79: 0 | U79: 80 | V79: 76 | W79: 76 | X79: 80 | Y79: 80 | Z79: 0 | AA79: 0 | AB79: 79 | AC79: 77 | AD79: 68 | AE79: 83 | AF79: 80 | AG79: 0 | AH79: 0 | AI79: 78 | AJ79: 80 | AK79: 71 | AL79: 71 | AM79: 72 | AN79: 0 | AO79: 0 | AP79: 64 | AQ79: 67 | AR79: 67 | AS79: 0 | AT79: =MAX(O79:AS79) -> 83 | AU79: 14 | AV79: 0.02311835 | AW79: 0.3236569 | AX79: P | AY79: SPDL - D48
...

Sheet Phase September
K1: 2 | L1: 3 | M1: 4 | N1: 5 | O1: 6 | P1: 7 | Q1: 8 | R1: 9 | S1: 10 | T1: 11 | U1: 12 | V1: 13 | W1: 14 | X1: 15 | Y1: 16 | Z1: 17 | AA1: 18 | AB1: 19 | AC1: 20 | AD1: 21 | AE1: 22 | AF1: 23 | AG1: 24 | AH1: 25
J2: N | K2: =VLOOKUP($J2,$AJ$448:BH464,K$1,0) -> 8 | L2: =VLOOKUP($J2,$AJ$448:BJ464,L$1,0) -> 8 | M2: =VLOOKUP($J2,$AJ$448:BK464,M$1,0) -> 8 | N2: =VLOOKUP($J2,$AJ$448:BL464,N$1,0) -> 8 | O2: =VLOOKUP($J2,$AJ$448:BM464,O$1,0) -> 9 | P2: =VLOOKUP($J2,$AJ$448:BH464,P$1,0) -> 9 | Q2: =VLOOKUP($J2,$AJ$448:BO464,Q$1,0) -> 8 | R2: =VLOOKUP($J2,$AJ$448:BP464,R$1,0) -> 8 | S2: =VLOOKUP($J2,$AJ$448:BQ464,S$1,0) -> 9 | T2: =VLOOKUP($J2,$AJ$448:BR464,T$1,0) -> 9 | U2: =VLOOKUP($J2,$AJ$448:BM464,U$1,0) -> 7 | V2: =VLOOKUP($J2,$AJ$448:BT464,V$1,0) -> 9 | W2: =VLOOKUP($J2,$AJ$448:BU464,W$1,0) -> 8 | X2: =VLOOKUP($J2,$AJ$448:BV464,X$1,0) -> 8 | Y2: =VLOOKUP($J2,$AJ$448:BW464,Y$1,0) -> 8 | Z2: =VLOOKUP($J2,$AJ$448:BR464,Z$1,0) -> 9 | AA2: =VLOOKUP($J2,$AJ$448:BY464,AA$1,0) -> 8 | AB2: =VLOOKUP($J2,$AJ$448:BZ464,AB$1,0) -> 9 | AC2: =VLOOKUP($J2,$AJ$448:CA464,AC$1,0) -> 8 | AD2: =VLOOKUP($J2,$AJ$448:CB464,AD$1,0) -> 8 | AE2: =VLOOKUP($J2,$AJ$448:BW464,AE$1,0) -> 9 | AF2: =VLOOKUP($J2,$AJ$448:CD464,AF$1,0) -> 9 | AG2: =VLOOKUP($J2,$AJ$448:CE464,AG$1,0) -> 7 | AH2: =VLOOKUP($J2,$AJ$448:CF464,AH$1,0) -> 9 | AI2: RATA 2
J3: =J2 -> N | K3: =VLOOKUP($J3,$BJ$448:CH464,K$1,0) -> 4.9436152 | L3: =VLOOKUP($J3,$BJ$448:CI464,L$1,0) -> 5.289108 | M3: =VLOOKUP($J3,$BJ$448:CJ464,M$1,0) -> 4.4575903 | N3: =VLOOKUP($J3,$BJ$448:CH464,N$1,0) -> 5.3198377 | O3: =VLOOKUP($J3,$BJ$448:CH464,O$1,0) -> 5.2684696 | P3: =VLOOKUP($J3,$BJ$448:CM464,P$1,0) -> 5.6514549 | Q3: =VLOOKUP($J3,$BJ$448:CN464,Q$1,0) -> 4.7413205 | R3: =VLOOKUP($J3,$BJ$448:CI464,R$1,0) -> 4.6103703 | S3: =VLOOKUP($J3,$BJ$448:CJ464,S$1,0) -> 5.1558274 | T3: =VLOOKUP($J3,$BJ$448:CQ464,T$1,0) -> 6.0861108 | U3: =VLOOKUP($J3,$BJ$448:CR464,U$1,0) -> 4.2638582 | V3: =VLOOKUP($J3,$BJ$448:CM464,V$1,0) -> 5.3556851 | W3: =VLOOKUP($J3,$BJ$448:CN464,W$1,0) -> 4.9436152 | X3: =VLOOKUP($J3,$BJ$448:CU464,X$1,0) -> 5.289108 | Y3: =VLOOKUP($J3,$BJ$448:CV464,Y$1,0) -> 4.4575903 | Z3: =VLOOKUP($J3,$BJ$448:CQ464,Z$1,0) -> 5.4168966 | AA3: =VLOOKUP($J3,$BJ$448:CR464,AA$1,0) -> 4.9620953 | AB3: =VLOOKUP($J3,$BJ$448:CY464,AB$1,0) -> 5.6514549 | AC3: =VLOOKUP($J3,$BJ$448:CZ464,AC$1,0) -> 4.7413205 | AD3: =VLOOKUP($J3,$BJ$448:CU464,AD$1,0) -> 4.6103703 | AE3: =VLOOKUP($J3,$BJ$448:CV464,AE$1,0) -> 5.1558274 | AF3: =VLOOKUP($J3,$BJ$448:DC464,AF$1,0) -> 6.0861108 | AG3: =VLOOKUP($J3,$BJ$448:DD464,AG$1,0) -> 4.2638582 | AH3: =VLOOKUP($J3,$BJ$448:CY464,AH$1,0) -> 5.3556851
J4: =J2 -> N | K4: =VLOOKUP($J4,$CI$448:DG464,K$1,0) -> 79 | L4: =VLOOKUP($J4,$CI$448:DG464,L$1,0) -> 102 | M4: =VLOOKUP($J4,$CI$448:DG464,M$1,0) -> 58 | N4: =VLOOKUP($J4,$CI$448:DG464,N$1,0) -> 96 | O4: =VLOOKUP($J4,$CI$448:DG464,O$1,0) -> 99 | P4: =VLOOKUP($J4,$CI$448:DG464,P$1,0) -> 102 | Q4: =VLOOKUP($J4,$CI$448:DG464,Q$1,0) -> 72 | R4: =VLOOKUP($J4,$CI$448:DH464,R$1,0) -> 92 | S4: =VLOOKUP($J4,$CI$448:DI464,S$1,0) -> 79 | T4: =VLOOKUP($J4,$CI$448:DJ464,T$1,0) -> 108 | U4: =VLOOKUP($J4,$CI$448:DK464,U$1,0) -> 71 | V4: =VLOOKUP($J4,$CI$448:DK464,V$1,0) -> 102 | W4: =VLOOKUP($J4,$CI$448:DK464,W$1,0) -> 79 | X4: =VLOOKUP($J4,$CI$448:DK464,X$1,0) -> 102 | Y4: =VLOOKUP($J4,$CI$448:DK464,Y$1,0) -> 58 | Z4: =VLOOKUP($J4,$CI$448:DK464,Z$1,0) -> 98 | AA4: =VLOOKUP($J4,$CI$448:DK464,AA$1,0) -> 92 | AB4: =VLOOKUP($J4,$CI$448:DK464,AB$1,0) -> 102 | AC4: =VLOOKUP($J4,$CI$448:DK464,AC$1,0) -> 72 | AD4: =VLOOKUP($J4,$CI$448:DK464,AD$1,0) -> 92 | AE4: =VLOOKUP($J4,$CI$448:DK464,AE$1,0) -> 79 | AF4: =VLOOKUP($J4,$CI$448:DK464,AF$1,0) -> 108 | AG4: =VLOOKUP($J4,$CI$448:DK464,AG$1,0) -> 71 | AH4: =VLOOKUP($J4,$CI$448:DK464,AH$1,0) -> 102 | AI4: =AVERAGE(K4:AH4) -> 88.125
J5: L | K5: =VLOOKUP($J5,$AJ$448:BH467,K$1,0) -> 7 | L5: =VLOOKUP($J5,$AJ$448:BH467,L$1,0) -> 8 | M5: =VLOOKUP($J5,$AJ$448:BH467,M$1,0) -> 9 | N5: =VLOOKUP($J5,$AJ$448:BH467,N$1,0) -> 8 | O5: =VLOOKUP($J5,$AJ$448:BH467,O$1,0) -> 8 | P5: =VLOOKUP($J5,$AJ$448:BH467,P$1,0) -> 8 | Q5: =VLOOKUP($J5,$AJ$448:BH467,Q$1,0) -> 8 | R5: =VLOOKUP($J5,$AJ$448:BJ467,R$1,0) -> 8 | S5: =VLOOKUP($J5,$AJ$448:BK467,S$1,0) -> 9 | T5: =VLOOKUP($J5,$AJ$448:BL467,T$1,0) -> 8 | U5: =VLOOKUP($J5,$AJ$448:BM467,U$1,0) -> 9 | V5: =VLOOKUP($J5,$AJ$448:BN467,V$1,0) -> 9 | W5: =VLOOKUP($J5,$AJ$448:BO467,W$1,0) -> 7 | X5: =VLOOKUP($J5,$AJ$448:BP467,X$1,0) -> 8 | Y5: =VLOOKUP($J5,$AJ$448:BQ467,Y$1,0) -> 9 | ... AH5: =VLOOKUP($J5,$AJ$448:BZ467,AH$1,0) -> 9 | AI5: RATA 2
J6: =J5 -> L | K6: =VLOOKUP($J6,$BJ$448:CH467,K$1,0) -> 5.4767834 | L6: =VLOOKUP($J6,$BJ$448:CH467,L$1,0) -> 6.4850237 | M6: =VLOOKUP($J6,$BJ$448:CH467,M$1,0) -> 7.0190683 | N6: =VLOOKUP($J6,$BJ$448:CH467,N$1,0) -> 5.7166402 | O6: =VLOOKUP($J6,$BJ$448:CH467,O$1,0) -> 6.4539555 | P6: =VLOOKUP($J6,$BJ$448:CI467,P$1,0) -> 6.330456 | Q6: =VLOOKUP($J6,$BJ$448:CH467,Q$1,0) -> 6.2363037 | R6: =VLOOKUP($J6,$BJ$448:CI467,R$1,0) -> 5.9234233 | S6: =VLOOKUP($J6,$BJ$448:CJ467,S$1,0) -> 6.7191093 | T6: =VLOOKUP($J6,$BJ$448:CK467,T$1,0) -> 6.2782406 | U6: =VLOOKUP($J6,$BJ$448:CL467,U$1,0) -> 7.2134759 | V6: =VLOOKUP($J6,$BJ$448:CO467,V$1,0) -> 5.7688556 | W6: =VLOOKUP($J6,$BJ$448:CN467,W$1,0) -> 5.4767834 | X6: =VLOOKUP($J6,$BJ$448:CO467,X$1,0) -> 6.4850237 | Y6: =VLOOKUP($J6,$BJ$448:CP467,Y$1,0) -> 7.0190683 | Z6: =VLOOKUP($J6,$BJ$448:CQ467,Z$1,0) -> 5.7166402 | AA6: =VLOOKUP($J6,$BJ$448:CR467,AA$1,0) -> 6.4539555 | AB6: =VLOOKUP($J6,$BJ$448:CU467,AB$1,0) -> 6.330456 | AC6: =VLOOKUP($J6,$BJ$448:CT467,AC$1,0) -> 6.2363037 | AD6: =VLOOKUP($J6,$BJ$448:CU467,AD$1,0) -> 5.9234233 | AE6: =VLOOKUP($J6,$BJ$448:CV467,AE$1,0) -> 6.7191093 | AF6: =VLOOKUP($J6,$BJ$448:CW467,AF$1,0) -> 6.2782406 | AG6: =VLOOKUP($J6,$BJ$448:CX467,AG$1,0) -> 7.2134759 | AH6: =VLOOKUP($J6,$BJ$448:DA467,AH$1,0) -> 6.35063
J7: =J5 -> L | K7: =VLOOKUP($J7,$CI$448:DG467,K$1,0) -> 97 | L7: =VLOOKUP($J7,$CI$448:DG467,L$1,0) -> 90 | M7: =VLOOKUP($J7,$CI$448:DG467,M$1,0) -> 109 | N7: =VLOOKUP($J7,$CI$448:DG467,N$1,0) -> 76 | O7: =VLOOKUP($J7,$CI$448:DG467,O$1,0) -> 112 | P7: =VLOOKUP($J7,$CI$448:DG467,P$1,0) -> 97 | Q7: =VLOOKUP($J7,$CI$448:DG467,Q$1,0) -> 90 | R7: =VLOOKUP($J7,$CI$448:DH467,R$1,0) -> 79 | S7: =VLOOKUP($J7,$CI$448:DI467,S$1,0) -> 127 | T7: =VLOOKUP($J7,$CI$448:DJ467,T$1,0) -> 87 | U7: =VLOOKUP($J7,$CI$448:DK467,U$1,0) -> 105 | V7: =VLOOKUP($J7,$CI$448:DK467,V$1,0) -> 86 | W7: =VLOOKUP($J7,$CI$448:DK467,W$1,0) -> 97 | X7: =VLOOKUP($J7,$CI$448:DK467,X$1,0) -> 90 | Y7: =VLOOKUP($J7,$CI$448:DK467,Y$1,0) -> 109 | Z7: =VLOOKUP($J7,$CI$448:DK467,Z$1,0) -> 76 | AA7: =VLOOKUP($J7,$CI$448:DK467,AA$1,0) -> 112 | AB7: =VLOOKUP($J7,$CI$448:DK467,AB$1,0) -> 97 | AC7: =VLOOKUP($J7,$CI$448:DK467,AC$1,0) -> 90 | AD7: =VLOOKUP($J7,$CI$448:DK467,AD$1,0) -> 79 | AE7: =VLOOKUP($J7,$CI$448:DK467,AE$1,0) -> 127 | AF7: =VLOOKUP($J7,$CI$448:DK467,AF$1,0) -> 87 | AG7: =VLOOKUP($J7,$CI$448:DK467,AG$1,0) -> 105 | AH7: =VLOOKUP($J7,$CI$448:DK467,AH$1,0) -> 95 | AI7: =AVERAGE(K7:AH7) -> 96.625
J8: M | K8: =VLOOKUP($J8,$AJ$448:BH470,K$1,0) -> 8 | L8: =VLOOKUP($J8,$AJ$448:BH470,L$1,0) -> 8 | M8: =VLOOKUP($J8,$AJ$448:BH470,M$1,0) -> 8 | N8: =VLOOKUP($J8,$AJ$448:BH470,N$1,0) -> 8 | O8: =VLOOKUP($J8,$AJ$448:BH470,O$1,0) -> 7 | P8: =VLOOKUP($J8,$AJ$448:BH470,P$1,0) -> 8 | Q8: =VLOOKUP($J8,$AJ$448:BH470,Q$1,0) -> 8 | R8: =VLOOKUP($J8,$AJ$448:BJ470,R$1,0) -> 8 | S8: =VLOOKUP($J8,$AJ$448:BK470,S$1,0) -> 8 | T8: =VLOOKUP($J8,$AJ$448:BL470,T$1,0) -> 8 | U8: =VLOOKUP($J8,$AJ$448:BM470,U$1,0) -> 8 | V8: =VLOOKUP($J8,$AJ$448:BN470,V$1,0) -> 8 | W8: =VLOOKUP($J8,$AJ$448:BO470,W$1,0) -> 8 | X8: =VLOOKUP($J8,$AJ$448:BP470,X$1,0) -> 7 | Y8: =VLOOKUP($J8,$AJ$448:BQ470,Y$1,0) -> 8 | ... AH8: =VLOOKUP($J8,$AJ$448:BZ470,AH$1,0) -> 8 | AI8: RATA 2
J9: =J8 -> M | K9: =VLOOKUP($J9,$BJ$448:CH470,K$1,0) -> 4.605504 | L9: =VLOOKUP($J9,$BJ$448:CH470,L$1,0) -> 4.4918087 | M9: =VLOOKUP($J9,$BJ$448:CH470,M$1,0) -> 4.755053 | N9: =VLOOKUP($J9,$BJ$448:CH470,N$1,0) -> 4.8001038 | O9: =VLOOKUP($J9,$BJ$448:CH470,O$1,0) -> 4.5740918 | P9: =VLOOKUP($J9,$BJ$448:CH470,P$1,0) -> 4.5237935 | Q9: =VLOOKUP($J9,$BJ$448:CH470,Q$1,0) -> 4.753594 | R9: =VLOOKUP($J9,$BJ$448:CI470,R$1,0) -> 4.6888166 | S9: =VLOOKUP($J9,$BJ$448:CJ470,S$1,0) -> 4.4582528 | T9: =VLOOKUP($J9,$BJ$448:CK470,T$1,0) -> 4.5597184 | U9: =VLOOKUP($J9,$BJ$448:CL470,U$1,0) -> 4.9194214 | V9: =VLOOKUP($J9,$BJ$448:CM470,V$1,0) -> 4.4788443 | W9: =VLOOKUP($J9,$BJ$448:CN470,W$1,0) -> 4.6517407 | X9: =VLOOKUP($J9,$BJ$448:CO470,X$1,0) -> 4.4918087 | ... AH9: =VLOOKUP($J9,$BJ$448:CY470,AH$1,0) -> 4.4788443
J10: =J8 -> M | K10: =VLOOKUP($J10,$CI$448:DG470,K$1,0) -> 107 | L10: =VLOOKUP($J10,$CI$448:DG470,L$1,0) -> 68 | M10: =VLOOKUP($J10,$CI$448:DG470,M$1,0) -> 77 | N10: =VLOOKUP($J10,$CI$448:DG470,N$1,0) -> 121 | O10: =VLOOKUP($J10,$CI$448:DG470,O$1,0) -> 77 | P10: =VLOOKUP($J10,$CI$448:DH470,P$1,0) -> 86 | Q10: =VLOOKUP($J10,$CI$448:DG470,Q$1,0) -> 103 | R10: =VLOOKUP($J10,$CI$448:DH470,R$1,0) -> 99 | S10: =VLOOKUP($J10,$CI$448:DI470,S$1,0) -> 67 | T10: =VLOOKUP($J10,$CI$448:DJ470,T$1,0) -> 89 | U10: =VLOOKUP($J10,$CI$448:DK470,U$1,0) -> 88 | V10: =VLOOKUP($J10,$CI$448:DK470,V$1,0) -> 110 | W10: =VLOOKUP($J10,$CI$448:DK470,W$1,0) -> 111 | X10: =VLOOKUP($J10,$CI$448:DK470,X$1,0) -> 68 | Y10: =VLOOKUP($J10,$CI$448:DK470,Y$1,0) -> 77 | Z10: =VLOOKUP($J10,$CI$448:DK470,Z$1,0) -> 121 | AA10: =VLOOKUP($J10,$CI$448:DK470,AA$1,0) -> 77 | AB10: =VLOOKUP($J10,$CI$448:DK470,AB$1,0) -> 80 | AC10: =VLOOKUP($J10,$CI$448:DK470,AC$1,0) -> 103 | AD10: =VLOOKUP($J10,$CI$448:DK470,AD$1,0) -> 98 | AE10: =VLOOKUP($J10,$CI$448:DK470,AE$1,0) -> 67 | AF10: =VLOOKUP($J10,$CI$448:DK470,AF$1,0) -> 93 | AG10: =VLOOKUP($J10,$CI$448:DK470,AG$1,0) -> 87 | AH10: =VLOOKUP($J10,$CI$448:DK470,AH$1,0) -> 110 | AI10: =AVERAGE(K10:AH10) -> 91
J11: F | K11: =VLOOKUP($J11,$AJ$448:BH473,K$1,0) -> 5 | L11: =VLOOKUP($J11,$AJ$448:BH473,L$1,0) -> 6 | M11: =VLOOKUP($J11,$AJ$448:BH473,M$1,0) -> 6 | N11: =VLOOKUP($J11,$AJ$448:BH473,N$1,0) -> 6 | O11: =VLOOKUP($J11,$AJ$448:BH473,O$1,0) -> 7 | P11: =VLOOKUP($J11,$AJ$448:BH473,P$1,0) -> 7 | Q11: =VLOOKUP($J11,$AJ$448:BH473,Q$1,0) -> 5 | R11: =VLOOKUP($J11,$AJ$448:BJ473,R$1,0) -> 6 | S11: =VLOOKUP($J11,$AJ$448:BK473,S$1,0) -> 6 | T11: =VLOOKUP($J11,$AJ$448:BL473,T$1,0) -> 6 | U11: =VLOOKUP($J11,$AJ$448:BM473,U$1,0) -> 7 | V11: =VLOOKUP($J11,$AJ$448:BN473,V$1,0) -> 7 | W11: =VLOOKUP($J11,$AJ$448:BO473,W$1,0) -> 6 | X11: =VLOOKUP($J11,$AJ$448:BP473,X$1,0) -> 7 | Y11: =VLOOKUP($J11,$AJ$448:BQ473,Y$1,0) -> 6 | ... AH11: =VLOOKUP($J11,$AJ$448:BZ473,AH$1,0) -> 7 | AI11: RATA 2
J12: =J11 -> F | K12: =VLOOKUP($J12,$BJ$448:CH473,K$1,0) -> 3.32464 | L12: =VLOOKUP($J12,$BJ$448:CH473,L$1,0) -> 4.0117047 | M12: =VLOOKUP($J12,$BJ$448:CH473,M$1,0) -> 3.7364854 | N12: =VLOOKUP($J12,$BJ$448:CH473,N$1,0) -> 4.3219921 | O12: =VLOOKUP($J12,$BJ$448:CH473,O$1,0) -> 4.3348344 | P12: =VLOOKUP($J12,$BJ$448:CH473,P$1,0) -> 4.2800931 | Q12: =VLOOKUP($J12,$BJ$448:CH473,Q$1,0) -> 3.3452146 | R12: =VLOOKUP($J12,$BJ$448:CI473,R$1,0) -> 4.4959151 | S12: =VLOOKUP($J12,$BJ$448:CJ473,S$1,0) -> 3.7390292 | T12: =VLOOKUP($J12,$BJ$448:CK473,T$1,0) -> 4.1790043 | U12: =VLOOKUP($J12,$BJ$448:CL473,U$1,0) -> 4.3727478 | V12: =VLOOKUP($J12,$BJ$448:CM473,V$1,0) -> 4.3185307 | W12: =VLOOKUP($J12,$BJ$448:CN473,W$1,0) -> 3.643024 | X12: =VLOOKUP($J12,$BJ$448:CO473,X$1,0) -> 4.5211191 | ... AH12: =VLOOKUP($J12,$BJ$448:CY473,AH$1,0) -> 4.3185307
J13: =J11 -> F | K13: =VLOOKUP($J13,$CI$448:DG473,K$1,0) -> 57 | L13: =VLOOKUP($J13,$CI$448:DG473,L$1,0) -> 75 | M13: =VLOOKUP($J13,$CI$448:DG473,M$1,0) -> 72 | N13: =VLOOKUP($J13,$CI$448:DG473,N$1,0) -> 105 | O13: =VLOOKUP($J13,$CI$448:DG473,O$1,0) -> 88 | P13: =VLOOKUP($J13,$CI$448:DH473,P$1,0) -> 100 | Q13: =VLOOKUP($J13,$CI$448:DG473,Q$1,0) -> 58 | R13: =VLOOKUP($J13,$CI$448:DH473,R$1,0) -> 101 | S13: =VLOOKUP($J13,$CI$448:DI473,S$1,0) -> 73 | T13: =VLOOKUP($J13,$CI$448:DJ473,T$1,0) -> 93 | U13: =VLOOKUP($J13,$CI$448:DK473,U$1,0) -> 91 | V13: =VLOOKUP($J13,$CI$448:DK473,V$1,0) -> 100 | W13: =VLOOKUP($J13,$CI$448:DK473,W$1,0) -> 62 | X13: =VLOOKUP($J13,$CI$448:DK473,X$1,0) -> 83 | Y13: =VLOOKUP($J13,$CI$448:DK473,Y$1,0) -> 72 | Z13: =VLOOKUP($J13,$CI$448:DK473,Z$1,0) -> 105 | AA13: =VLOOKUP($J13,$CI$448:DK473,AA$1,0) -> 88 | AB13: =VLOOKUP($J13,$CI$448:DK473,AB$1,0) -> 88 | AC13: =VLOOKUP($J13,$CI$448:DK473,AC$1,0) -> 74 | AD13: =VLOOKUP($J13,$CI$448:DK473,AD$1,0) -> 131 | AE13: =VLOOKUP($J13,$CI$448:DK473,AE$1,0) -> 71 | AF13: =VLOOKUP($J13,$CI$448:DK473,AF$1,0) -> 103 | AG13: =VLOOKUP($J13,$CI$448:DK473,AG$1,0) -> 91 | AH13: =VLOOKUP($J13,$CI$448:DK473,AH$1,0) -> 100 | AI13: =AVERAGE(K13:AH13) -> 86.708333
AK14: DOLLY PATTERN | BK14: VOLUME M3 | CJ14: BOX PATTERN | DL14: BULAN LALU
K15: 30 | L15: 31 | M15: 32 | N15: 33 | O15: 34 | P15: 35 | Q15: 36 | R15: 37 | S15: 38 | T15: 39 | U15: 40 | V15: 41 | W15: 42 | X15: 43 | Y15: 44 | Z15: 45 | AA15: 46 | AB15: 47 | AC15: 48 | AD15: 49 | AE15: 50 | AF15: 51 | AG15: 52 | AH15: 53 | DM15: 11 | DN15: 12 | DO15: 13 | DP15: 14 | DQ15: 15 | DR15: 16 | DS15: 17 | DT15: 18 | DU15: 19 | DV15: 20 | DW15: 21 | DX15: 22 | DY15: 23 | DZ15: 24 | EA15: 25 | EB15: 26 | EC15: 27 | ED15: 28 | EE15: 29 | EF15: 30 | EG15: 31 | EH15: 32 | EI15: 33 | EJ15: 34
A16: SUPPLIER CODE | B16: SUPPLIER NAME | C16: FIX CODE S.DOCK | D16: CONVEYANCE | E16: GABUNGAN | F16: Sum of Vol/Day ( Box ) | G16: Sum of m 3 ( Day ) | H16: Order Freq | K16: 1 | L16: 2 | M16: 3 | N16: 4 | O16: 5 | P16: 6 | Q16: 7 | R16: 8 | S16: 9 | T16: 10 | U16: 11 | V16: 12 | W16: 13 | X16: 14 | Y16: 15 | Z16: 16 | AA16: 17 | AB16: 18 | AC16: 19 | AD16: 20 | AE16: 21 | AF16: 22 | AG16: 23 | AH16: 24 | AJ16: KADAI | AK16: 1 | AL16: 2 | AM16: 3 | AN16: 4 | AO16: 5 | AP16: 6 | AQ16: 7 | AR16: 8 | AS16: 9 | AT16: 10 | AU16: 11 | AV16: 12 | AW16: 13 | AX16: 14 | AY16: 15 | AZ16: 16 | BA16: 17 | BB16: 18 | BC16: 19 | BD16: 20 | BE16: 21 | BF16: 22 | BG16: 23 | BH16: 24 | BK16: 1 | BL16: 2 | BM16: 3 | BN16: 4 | BO16: 5 | BP16: 6 | BQ16: 7 | BR16: 8 | BS16: 9 | BT16: 10 | BU16: 11 | BV16: 12 | BW16: 13 | BX16: 14 | BY16: 15 | BZ16: 16 | CA16: 17 | CB16: 18 | CC16: 19 | CD16: 20 | CE16: 21 | CF16: 22 | CG16: 23 | CH16: 24 | CJ16: 1 | CK16: 2 | CL16: 3 | CM16: 4 | CN16: 5 | CO16: 6 | CP16: 7 | CQ16: 8 | CR16: 9 | CS16: 10 | CT16: 11 | CU16: 12 | CV16: 13 | CW16: 14 | CX16: 15 | CY16: 16 | CZ16: 17 | DA16: 18 | DB16: 19 | DC16: 20 | DD16: 21 | DE16: 22 | DF16: 23 | DG16: 24 | DJ16: SUPPLIER DOUBLE SKID | DK16: HENKATEN | DM16: 1 | DN16: 2 | DO16: 3 | DP16: 4 | DQ16: 5 | DR16: 6 | DS16: 7 | DT16: 8 | DU16: 9 | DV16: 10 | DW16: 11 | DX16: 12 | DY16: 13 | DZ16: 14 | EA16: 15 | EB16: 16 | EC16: 17 | ED16: 18 | EE16: 19 | EF16: 20 | EG16: 21 | EH16: 22 | EI16: 23 | EJ16: 24 | EL16: 1 | EM16: 2 | EN16: 3 | EO16: 4 | EP16: 5 | EQ16: 6 | ER16: 7 | ES16: 8 | ET16: 9 | EU16: 10 | EV16: 11 | EW16: 12 | EX16: 13 | EY16: 14 | EZ16: 15 | FA16: 16 | FB16: 17 | FC16: 18 | FD16: 19 | FE16: 20 | FF16: 21 | FG16: 22 | FH16: 23 | FI16: 24
A17: 0003-1-43 | B17: SUGITY CREATIVES | C17: (blank) | D17: D | E17: =A17&"-"&D17 -> 0003-1-43-D | F17: 16 | G17: 2.046984 | H17: =VLOOKUP(A17,'Pivot 1'!$A$5:$H$251,8,0) -> 4 | I17: Direct | J17: =SUM(K17:AH17) -> 4 | K17: 1 | L17: 0 | M17: 0 | N17: 0 | O17: 0 | P17: 0 | Q17: 1 | R17: 0 | S17: 0 | T17: 0 | U17: 0 | V17: 0 | W17: 1 | X17: 0 | Y17: 0 | Z17: 0 | AA17: 0 | AB17: 0 | AC17: 1 | AD17: 0 | AE17: 0 | AF17: 0 | AG17: 0 | AH17: 0 | AI17: =J17=H17 -> FALSE | AK17: =IF($I17="Direct",IF(K17=1,ROUNDUP($G17/$H17,0),IF($I17="Unpacking",IF($K17=0,ROUNDUP($G17/$H17,0)),0)),0) -> 1 | AL17: =IF($I17="Direct",IF(L17=1,ROUNDUP($G17/$H17,0),IF($I17="Unpacking",IF($K17=0,ROUNDUP($G17/$H17,0)),0)),0) -> 0 | AM17: =IF($I17="Direct",IF(M17=1,ROUNDUP($G17/$H17,0),IF($I17="Unpacking",IF($K17=0,ROUNDUP($G17/$H17,0)),0)),0) -> 0 | AN17: =IF($I17="Direct",IF(N17=1,ROUNDUP($G17/$H17,0),IF($I17="Unpacking",IF($K17=0,ROUNDUP($G17/$H17,0)),0)),0) -> 0 | AO17: =IF($I17="Direct",IF(O17=1,ROUNDUP($G17/$H17,0),IF($I17="Unpacking",IF($K17=0,ROUNDUP($G17/$H17,0)),0)),0) -> 0 | AP17: =IF($I17="Direct",IF(P17=1,ROUNDUP($G17/$H17,0),IF($I17="Unpacking",IF($K17=0,ROUNDUP($G17/$H17,0)),0)),0) -> 0 | AQ17: =IF($I17="Direct",IF(Q17=1,ROUNDUP($G17/$H17,0),IF($I17="Unpacking",IF($K17=0,ROUNDUP($G17/$H17,0)),0)),0) -> 1 | AR17: =IF($I17="Direct",IF(R17=1,ROUNDUP($G17/$H17,0),IF($I17="Unpacking",IF($K17=0,ROUNDUP($G17/$H17,0)),0)),0) -> 0 | ... BH17: =IF($I17="Direct",IF(AH17=1,ROUNDUP($G17/$H17,0),IF($I17="Unpacking",IF($K17=0,ROUNDUP($G17/$H17,0)),0)),0) -> 0 | BJ17: =MAX(BK17:CH17) -> 0.511746 | BK17: =IF(K17=1,$G17/$H17,0) -> 0.511746 | BL17: =IF(L17=1,$G17/$H17,0) -> 0 | BM17: =IF(M17=1,$G17/$H17,0) -> 0 | BN17: =IF(N17=1,$G17/$H17,0) -> 0 | BO17: =IF(O17=1,$G17/$H17,0) -> 0 | BP17: =IF(P17=1,$G17/$H17,0) -> 0 | BQ17: =IF(Q17=1,$G17/$H17,0) -> 0.511746 | BR17: =IF(R17=1,$G17/$H17,0) -> 0 | ... CH17: =IF(AH17=1,$G17/$H17,0) -> 0 | CJ17: =IF(K17=1,ROUND($F17/$H17,0),0) -> 4 | CK17: =IF(L17=1,ROUND($F17/$H17,0),0) -> 0 | CL17: =IF(M17=1,ROUND($F17/$H17,0),0) -> 0 | CM17: =IF(N17=1,ROUND($F17/$H17,0),0) -> 0 | CN17: =IF(O17=1,ROUND($F17/$H17,0),0) -> 0 | CO17: =IF(P17=1,ROUND($F17/$H17,0),0) -> 0 | CP17: =IF(Q17=1,ROUND($F17/$H17,0),0) -> 4 | CQ17: =IF(R17=1,ROUND($F17/$H17,0),0) -> 0 | ... DG17: =IF(AH17=1,ROUND($F17/$H17,0),0) -> 0 | DH17: =SUM(CJ17:DG17) -> 16 | DI17: =DH17-F17 -> 0 | DK17: =DL17=H17 -> FALSE | DL17: =SUM(DM17:EJ17) -> 0 | EL17: =DM17=K17 -> FALSE | EM17: =DN17=L17 -> TRUE | EN17: =DO17=M17 -> TRUE | EO17: =DP17=N17 -> TRUE | EP17: =DQ17=O17 -> TRUE | EQ17: =DR17=P17 -> TRUE | ER17: =DS17=Q17 -> FALSE | ES17: =DT17=R17 -> TRUE | ... FI17: =EJ17=AH17 -> TRUE | FJ17: =COUNTIF(EL17:FI17,FALSE) -> 4
A18: 0003-1-FP1-43 | B18: SUGITY CREATIVES | C18: FP1 | D18: N | E18: =A18&"-"&D18 -> 0003-1-FP1-43-N | F18: 28 | G18: 0.99188475 | H18: =VLOOKUP(A18,'Pivot 1'!$A$5:$H$251,8,0) -> 2 | I18: Direct | J18: =SUM(K18:AH18) -> 2 | K18: 0 | L18: 0 | M18: 0 | N18: 0 | O18: 0 | P18: 0 | Q18: 1 | R18: 0 | S18: 0 | T18: 0 | U18: 0 | V18: 0 | W18: 0 | X18: 0 | Y18: 0 | Z18: 0 | AA18: 0 | AB18: 0 | AC18: 1 | AD18: 0 | AE18: 0 | AF18: 0 | AG18: 0 | AH18: 0 | AI18: =J18=H18 -> FALSE | AK18: =IF($I18="Direct",IF(K18=1,ROUNDUP($G18/$H18,0),IF($I18="Unpacking",IF($K18=0,ROUNDUP($G18/$H18,0)),0)),0) -> 0 | AL18: =IF($I18="Direct",IF(L18=1,ROUNDUP($G18/$H18,0),IF($I18="Unpacking",IF($K18=0,ROUNDUP($G18/$H18,0)),0)),0) -> 0 | AM18: =IF($I18="Direct",IF(M18=1,ROUNDUP($G18/$H18,0),IF($I18="Unpacking",IF($K18=0,ROUNDUP($G18/$H18,0)),0)),0) -> 0 | AN18: =IF($I18="Direct",IF(N18=1,ROUNDUP($G18/$H18,0),IF($I18="Unpacking",IF($K18=0,ROUNDUP($G18/$H18,0)),0)),0) -> 0 | AO18: =IF($I18="Direct",IF(O18=1,ROUNDUP($G18/$H18,0),IF($I18="Unpacking",IF($K18=0,ROUNDUP($G18/$H18,0)),0)),0) -> 0 | AP18: =IF($I18="Direct",IF(P18=1,ROUNDUP($G18/$H18,0),IF($I18="Unpacking",IF($K18=0,ROUNDUP($G18/$H18,0)),0)),0) -> 0 | AQ18: =IF($I18="Direct",IF(Q18=1,ROUNDUP($G18/$H18,0),IF($I18="Unpacking",IF($K18=0,ROUNDUP($G18/$H18,0)),0)),0) -> 1 | AR18: =IF($I18="Direct",IF(R18=1,ROUNDUP($G18/$H18,0),IF($I18="Unpacking",IF($K18=0,ROUNDUP($G18/$H18,0)),0)),0) -> 0 | ... BH18: =IF($I18="Direct",IF(AH18=1,ROUNDUP($G18/$H18,0),IF($I18="Unpacking",IF($K18=0,ROUNDUP($G18/$H18,0)),0)),0) -> 0 | BJ18: =MAX(BK18:CH18) -> 0.49594237 | BK18: =IF(K18=1,$G18/$H18,0) -> 0 | BL18: =IF(L18=1,$G18/$H18,0) -> 0 | BM18: =IF(M18=1,$G18/$H18,0) -> 0 | BN18: =IF(N18=1,$G18/$H18,0) -> 0 | BO18: =IF(O18=1,$G18/$H18,0) -> 0 | BP18: =IF(P18=1,$G18/$H18,0) -> 0 | BQ18: =IF(Q18=1,$G18/$H18,0) -> 0.49594237 | BR18: =IF(R18=1,$G18/$H18,0) -> 0 | ... CH18: =IF(AH18=1,$G18/$H18,0) -> 0 | CJ18: =IF(K18=1,ROUND($F18/$H18,0),0) -> 0 | CK18: =IF(L18=1,ROUND($F18/$H18,0),0) -> 0 | CL18: =IF(M18=1,ROUND($F18/$H18,0),0) -> 0 | CM18: =IF(N18=1,ROUND($F18/$H18,0),0) -> 0 | CN18: =IF(O18=1,ROUND($F18/$H18,0),0) -> 0 | CO18: =IF(P18=1,ROUND($F18/$H18,0),0) -> 0 | CP18: =IF(Q18=1,ROUND($F18/$H18,0),0) -> 14 | CQ18: =IF(R18=1,ROUND($F18/$H18,0),0) -> 0 | ... DG18: =IF(AH18=1,ROUND($F18/$H18,0),0) -> 0 | DH18: =SUM(CJ18:DG18) -> 28 | DI18: =DH18-F18 -> 0 | DK18: =DL18=H18 -> FALSE | DL18: =SUM(DM18:EJ18) -> 0 | EL18: =DM18=K18 -> TRUE | EM18: =DN18=L18 -> TRUE | EN18: =DO18=M18 -> TRUE | EO18: =DP18=N18 -> TRUE | EP18: =DQ18=O18 -> TRUE | EQ18: =DR18=P18 -> TRUE | ER18: =DS18=Q18 -> FALSE | ES18: =DT18=R18 -> TRUE | ... FI18: =EJ18=AH18 -> TRUE | FJ18: =COUNTIF(EL18:FI18,FALSE) -> 2
A19: 0003-1-OP1-43 | B19: SUGITY CREATIVES | C19: OP1 | D19: K | E19: =A19&"-"&D19 -> 0003-1-OP1-43-K | F19: 71 | G19: 2.816623 | H19: =VLOOKUP(A19,'Pivot 1'!$A$5:$H$251,8,0) -> 4 | I19: Direct | J19: =SUM(K19:AH19) -> 4 | K19: 0 | L19: 0 | M19: 0 | N19: 1 | O19: 0 | P19: 0 | Q19: 0 | R19: 0 | S19: 0 | T19: 1 | U19: 0 | V19: 0 | W19: 0 | X19: 0 | Y19: 0 | Z19: 1 | AA19: 0 | AB19: 0 | AC19: 0 | AD19: 0 | AE19: 0 | AF19: 1 | AG19: 0 | AH19: 0 | AI19: =J19=H19 -> TRUE | AK19: =IF($I19="Direct",IF(K19=1,ROUNDUP($G19/$H19,0),IF($I19="Unpacking",IF($K19=0,ROUNDUP($G19/$H19,0)),0)),0) -> 0 | AL19: =IF($I19="Direct",IF(L19=1,ROUNDUP($G19/$H19,0),IF($I19="Unpacking",IF($K19=0,ROUNDUP($G19/$H19,0)),0)),0) -> 0 | AM19: =IF($I19="Direct",IF(M19=1,ROUNDUP($G19/$H19,0),IF($I19="Unpacking",IF($K19=0,ROUNDUP($G19/$H19,0)),0)),0) -> 0 | AN19: =IF($I19="Direct",IF(N19=1,ROUNDUP($G19/$H19,0),IF($I19="Unpacking",IF($K19=0,ROUNDUP($G19/$H19,0)),0)),0) -> 1 | AO19: =IF($I19="Direct",IF(O19=1,ROUNDUP($G19/$H19,0),IF($I19="Unpacking",IF($K19=0,ROUNDUP($G19/$H19,0)),0)),0) -> 0 | AP19: =IF($I19="Direct",IF(P19=1,ROUNDUP($G19/$H19,0),IF($I19="Unpacking",IF($K19=0,ROUNDUP($G19/$H19,0)),0)),0) -> 0 | AQ19: =IF($I19="Direct",IF(Q19=1,ROUNDUP($G19/$H19,0),IF($I19="Unpacking",IF($K19=0,ROUNDUP($G19/$H19,0)),0)),0) -> 0 | AR19: =IF($I19="Direct",IF(R19=1,ROUNDUP($G19/$H19,0),IF($I19="Unpacking",IF($K19=0,ROUNDUP($G19/$H19,0)),0)),0) -> 0 | ... BH19: =IF($I19="Direct",IF(AH19=1,ROUNDUP($G19/$H19,0),IF($I19="Unpacking",IF($K19=0,ROUNDUP($G19/$H19,0)),0)),0) -> 0 | BJ19: =MAX(BK19:CH19) -> 0.70415576 | BK19: =IF(K19=1,$G19/$H19,0) -> 0 | BL19: =IF(L19=1,$G19/$H19,0) -> 0 | BM19: =IF(M19=1,$G19/$H19,0) -> 0 | BN19: =IF(N19=1,$G19/$H19,0) -> 0.70415576 | BO19: =IF(O19=1,$G19/$H19,0) -> 0 | BP19: =IF(P19=1,$G19/$H19,0) -> 0 | BQ19: =IF(Q19=1,$G19/$H19,0) -> 0 | BR19: =IF(R19=1,$G19/$H19,0) -> 0 | ... CH19: =IF(AH19=1,$G19/$H19,0) -> 0 | CJ19: =IF(K19=1,ROUND($F19/$H19,0),0) -> 0 | CK19: =IF(L19=1,ROUND($F19/$H19,0),0) -> 0 | CL19: =IF(M19=1,ROUND($F19/$H19,0),0) -> 0 | CM19: =IF(N19=1,ROUND($F19/$H19,0),0) -> 18 | CN19: =IF(O19=1,ROUND($F19/$H19,0),0) -> 0 | CO19: =IF(P19=1,ROUND($F19/$H19,0),0) -> 0 | CP19: =IF(Q19=1,ROUND($F19/$H19,0),0) -> 0 | CQ19: =IF(R19=1,ROUND($F19/$H19,0),0) -> 0 | ... DG19: =IF(AH19=1,ROUND($F19/$H19,0),0) -> 0 | DH19: =SUM(CJ19:DG19) -> 72 | DI19: =DH19-F19 -> 1 | DK19: =DL19=H19 -> FALSE | DL19: =SUM(DM19:EJ19) -> 0 | EL19: =DM19=K19 -> TRUE | EM19: =DN19=L19 -> TRUE | EN19: =DO19=M19 -> TRUE | EO19: =DP19=N19 -> FALSE | EP19: =DQ19=O19 -> TRUE | EQ19: =DR19=P19 -> TRUE | ER19: =DS19=Q19 -> TRUE | ES19: =DT19=R19 -> TRUE | ... FI19: =EJ19=AH19 -> TRUE | FJ19: =COUNTIF(EL19:FI19,FALSE) -> 4
A20: 0003-2-43 | B20: SUGITY CREATIVES | C20: (blank) | D20: G | E20: =A20&"-"&D20 -> 0003-2-43-G | F20: 10 | G20: 0.2 | H20: =VLOOKUP(A20,'Pivot 1'!$A$5:$H$251,8,0) -> 1 | I20: Direct | J20: =SUM(K20:AH20) -> 1 | K20: 0 | L20: 0 | M20: 0 | N20: 0 | O20: 0 | P20: 0 | Q20: 0 | R20: 0 | S20: 0 | T20: 0 | U20: 0 | V20: 0 | W20: 0 | X20: 0 | Y20: 0 | Z20: 1 | AA20: 0 | AB20: 0 | AC20: 0 | AD20: 0 | AE20: 0 | AF20: 0 | AG20: 0 | AH20: 0 | AI20: =J20=H20 -> FALSE | AK20: =IF($I20="Direct",IF(K20=1,ROUNDUP($G20/$H20,0),IF($I20="Unpacking",IF($K20=0,ROUNDUP($G20/$H20,0)),0)),0) -> 0 | AL20: =IF($I20="Direct",IF(L20=1,ROUNDUP($G20/$H20,0),IF($I20="Unpacking",IF($K20=0,ROUNDUP($G20/$H20,0)),0)),0) -> 0 | AM20: =IF($I20="Direct",IF(M20=1,ROUNDUP($G20/$H20,0),IF($I20="Unpacking",IF($K20=0,ROUNDUP($G20/$H20,0)),0)),0) -> 0 | AN20: =IF($I20="Direct",IF(N20=1,ROUNDUP($G20/$H20,0),IF($I20="Unpacking",IF($K20=0,ROUNDUP($G20/$H20,0)),0)),0) -> 0 | AO20: =IF($I20="Direct",IF(O20=1,ROUNDUP($G20/$H20,0),IF($I20="Unpacking",IF($K20=0,ROUNDUP($G20/$H20,0)),0)),0) -> 0 | AP20: =IF($I20="Direct",IF(P20=1,ROUNDUP($G20/$H20,0),IF($I20="Unpacking",IF($K20=0,ROUNDUP($G20/$H20,0)),0)),0) -> 0 | AQ20: =IF($I20="Direct",IF(Q20=1,ROUNDUP($G20/$H20,0),IF($I20="Unpacking",IF($K20=0,ROUNDUP($G20/$H20,0)),0)),0) -> 0 | AR20: =IF($I20="Direct",IF(R20=1,ROUNDUP($G20/$H20,0),IF($I20="Unpacking",IF($K20=0,ROUNDUP($G20/$H20,0)),0)),0) -> 0 | ... BH20: =IF($I20="Direct",IF(AH20=1,ROUNDUP($G20/$H20,0),IF($I20="Unpacking",IF($K20=0,ROUNDUP($G20/$H20,0)),0)),0) -> 0 | BJ20: =MAX(BK20:CH20) -> 0.2 | BK20: =IF(K20=1,$G20/$H20,0) -> 0 | BL20: =IF(L20=1,$G20/$H20,0) -> 0 | BM20: =IF(M20=1,$G20/$H20,0) -> 0 | BN20: =IF(N20=1,$G20/$H20,0) -> 0 | BO20: =IF(O20=1,$G20/$H20,0) -> 0 | BP20: =IF(P20=1,$G20/$H20,0) -> 0 | BQ20: =IF(Q20=1,$G20/$H20,0) -> 0 | BR20: =IF(R20=1,$G20/$H20,0) -> 0 | ... CH20: =IF(AH20=1,$G20/$H20,0) -> 0 | CJ20: =IF(K20=1,ROUND($F20/$H20,0),0) -> 0 | CK20: =IF(L20=1,ROUND($F20/$H20,0),0) -> 0 | CL20: =IF(M20=1,ROUND($F20/$H20,0),0) -> 0 | CM20: =IF(N20=1,ROUND($F20/$H20,0),0) -> 0 | CN20: =IF(O20=1,ROUND($F20/$H20,0),0) -> 0 | CO20: =IF(P20=1,ROUND($F20/$H20,0),0) -> 0 | CP20: =IF(Q20=1,ROUND($F20/$H20,0),0) -> 0 | CQ20: =IF(R20=1,ROUND($F20/$H20,0),0) -> 0 | ... DG20: =IF(AH20=1,ROUND($F20/$H20,0),0) -> 0 | DH20: =SUM(CJ20:DG20) -> 10 | DI20: =DH20-F20 -> 0 | DK20: =DL20=H20 -> FALSE | DL20: =SUM(DM20:EJ20) -> 0 | EL20: =DM20=K20 -> TRUE | EM20: =DN20=L20 -> TRUE | EN20: =DO20=M20 -> TRUE | EO20: =DP20=N20 -> TRUE | EP20: =DQ20=O20 -> TRUE | EQ20: =DR20=P20 -> TRUE | ER20: =DS20=Q20 -> TRUE | ES20: =DT20=R20 -> TRUE | ... FI20: =EJ20=AH20 -> TRUE | FJ20: =COUNTIF(EL20:FI20,FALSE) -> 1
